Workbook

Sheet Painel
A1: Painel do projeto — Driver M-Audio FireWire 1814 para macOS 10.13.6
A2: 2026-10-21
A4: Visão geral
A5: Itens rastreados | B5: =COUNTA(Itens!$A$2:$A$500) | D5: Progresso total do projeto (média pesquisa + build) | H5: =IFERROR(AVERAGE(B15,B16),0)
A6: Itens fechados | B6: =COUNTIF(Itens!$K$2:$K$500,"Consistente")+COUNTIF(Itens!$K$2:$K$500,"Corrigido 2026-10-14")+COUNTIF(Itens!$K$2:$K$500,"Corrigido 2026-10-15")+COUNTIF(Itens!$K$2:$K$500,"Corrigido 2026-10-16")+COUNTIF(Itens!$K$2:$K$500,"Corrigido 2026-10-09") | D6: Média de dois blocos: pesquisa (fases 0–D, linhas 22–28) e build (pacotes P/M/H/PN/IN da aba Build, linhas 30–34). O portão G1 passou em 2026-10-14; o build avança segundo o fluxograma.
A7: % fechados | B7: =IFERROR(B6/B5,0)
A8: Itens abertos | B8: =COUNTIF(Itens!$K$2:$K$500,"Aberto / não resolvido") | D8: ONDE ESTAMOS
A9: Não auditados | B9: =COUNTIF(Itens!$K$2:$K$500,"Não auditado") | D9: Árvore 0.1.0 (só FW1814) concluída e congelada (tag v0.1.0). O trabalho atual está em openaudio-mafw-bebob/ (pacote 0.2.2, FW1814 + Audiophile, publicado; tracker PROVENANCE-MATRIX-AUDIOPHILE.xlsx). Tudo funciona no uso diário (usuário, 2026-10-21).
A10: Flags do audit | B10: =COUNTA(Flags_auditoria!$A$2:$A$500)-COUNTIF(Flags_auditoria!$A$2:$A$500,"OK")
A11: Flags resolvidas | B11: =COUNTIF(Flags_auditoria!$H$2:$H$500,"Resolvido")
A12: Flags rotuladas (hipótese) | B12: =COUNTIF(Flags_auditoria!$H$2:$H$500,"Rotulado") | D12: PARA ONDE VAMOS
A13: Flags abertas | B13: =COUNTIF(Flags_auditoria!$H$2:$H$500,"Aberto") | D13: Sem testes formais (R123): os testes restantes estão como 'Sob demanda (uso real)' e só voltam se o uso real mostrar problema. Novas tarefas vão para o tracker do Audiophile.
A14: Confiança média (0–10) | B14: =IFERROR(AVERAGE(Itens!$L$2:$L$500),0)
A15: Progresso da pesquisa (fases 0–D) | B15: =IFERROR(AVERAGE(D22:D28),0)
A16: Progresso do build (aba Build) | B16: =IFERROR(AVERAGE(D30:D34),0)
A17: Tarefas de build concluídas (exclui canceladas) | B17: =COUNTIF(Build!$F$2:$F$300,"Concluído")&" / "&(COUNTA(Build!$A$2:$A$300)-COUNTIF(Build!$F$2:$F$300,"Cancelado*")-COUNTIF(Build!$F$2:$F$300,"Sob demanda*"))&" (+"&COUNTIF(Build!$F$2:$F$300,"Cancelado*")&" canceladas, +"&COUNTIF(Build!$F$2:$F$300,"Sob demanda*")&" sob demanda)"
A19: Roadmap — pesquisa (linhas 22–28) e build do clone D2 (linhas 29–34)
A20: Portão G1 PASSOU em 2026-10-14. Regras (2026-10-15): pilha completa; REGRA DO AVIÃO (sem teste parcial em hardware; verificar por conformidade; um teste integrado no fim); dev local + sync para o build PC; sem gravação de flash.
A21: Fase | B21: Ramo principal | C21: Estado | D21: % pronto | E21: Itens | F21: Fechados | G21: Abertos | H21: Não audit. | I21: Flags abertas | K21: Onde estamos | L21: O que falta / próximo passo
A22: 0 | B22: Fundação: pivô e plano (NEW_PLAN) | C22: Concluído | D22: 1 | E22: — | F22: — | G22: — | H22: — | I22: — | K22: NEW_PLAN.md, STATE.md, regras de proveniência e árvore docs/system-map prontos. | L22: Nada.
A23: A | B23: Desmontagem de _extracted/ (A1 kext, A2 painel, A3 MIDI, A4 helper, A5 firmware, A6 prefpane) | C23: Concluído | D23: =IFERROR(F23/E23,0) | E23: =SUM(COUNTIF(Itens!$B$2:$B$500,{"A1","A2","A3","A4","A5","A6"})) | F23: =SUM(COUNTIFS(Itens!$B$2:$B$500,{"A1","A2","A3","A4","A5","A6"},Itens!$K$2:$K$500,"Consistente"))+SUM(COUNTIFS(Itens!$B$2:$B$500,{"A1","A2","A3","A4","A5","A6"},Itens!$K$2:$K$500,"Corrigido 2026-10-14"))+SUM(COUNTIFS(Itens!$B$2:$B$500,{"A1","A2","A3","A4","A5","A6"},Itens!$K$2:$K$500,"Corrigido 2026-10-15"))+SUM(COUNTIFS(Itens!$B$2:$B$500,{"A1","A2","A3","A4","A5","A6"},Itens!$K$2:$K$500,"Corrigido 2026-10-16"))+SUM(COUNTIFS(Itens!$B$2:$B$500,{"A1","A2","A3","A4","A5","A6"},Itens!$K$2:$K$500,"Corrigido 2026-10-09")) | G23: =SUM(COUNTIFS(Itens!$B$2:$B$500,{"A1","A2","A3","A4","A5","A6"},Itens!$K$2:$K$500,"Aberto / não resolvido")) | H23: =SUM(COUNTIFS(Itens!$B$2:$B$500,{"A1","A2","A3","A4","A5","A6"},Itens!$K$2:$K$500,"Não auditado")) | I23: =SUM(COUNTIFS(Flags_auditoria!$K$2:$K$500,{"A1","A2","A3","A4","A5","A6"},Flags_auditoria!$H$2:$H$500,"Aberto")) | K23: Ghidra + otool em todos os binários; 70 itens só no kext (A1). | L23: Q-MAMAP (46 chaves MA*), Q3b (reaplicar preferências), v1.5.2 sync-radio, consumidor do bit 2 S/PDIF, identidade de IOFireWireNub vt[0x850].
A24: B | B24: Cruzamento com terceiros e hardware (B1 FFADO, B2 snd-bebob, B2a Rust, B3 hack Sierra, B4 macfw, B5 DTrace SL) | C24: Concluído | D24: =IFERROR(F24/E24,0) | E24: =SUM(COUNTIF(Itens!$B$2:$B$500,{"B1","B2","B2a","B3","B4","B5"})) | F24: =SUM(COUNTIFS(Itens!$B$2:$B$500,{"B1","B2","B2a","B3","B4","B5"},Itens!$K$2:$K$500,"Consistente"))+SUM(COUNTIFS(Itens!$B$2:$B$500,{"B1","B2","B2a","B3","B4","B5"},Itens!$K$2:$K$500,"Corrigido 2026-10-14"))+SUM(COUNTIFS(Itens!$B$2:$B$500,{"B1","B2","B2a","B3","B4","B5"},Itens!$K$2:$K$500,"Corrigido 2026-10-15"))+SUM(COUNTIFS(Itens!$B$2:$B$500,{"B1","B2","B2a","B3","B4","B5"},Itens!$K$2:$K$500,"Corrigido 2026-10-16"))+SUM(COUNTIFS(Itens!$B$2:$B$500,{"B1","B2","B2a","B3","B4","B5"},Itens!$K$2:$K$500,"Corrigido 2026-10-09")) | G24: =SUM(COUNTIFS(Itens!$B$2:$B$500,{"B1","B2","B2a","B3","B4","B5"},Itens!$K$2:$K$500,"Aberto / não resolvido")) | H24: =SUM(COUNTIFS(Itens!$B$2:$B$500,{"B1","B2","B2a","B3","B4","B5"},Itens!$K$2:$K$500,"Não auditado")) | I24: =SUM(COUNTIFS(Flags_auditoria!$K$2:$K$500,{"B1","B2","B2a","B3","B4","B5"},Flags_auditoria!$H$2:$H$500,"Aberto")) | K24: Terceiros usados só para decodificar bytes opacos; o kext vence em conflito. | L24: Latência em 88.2/96/176.4/192 kHz e captura FCP de troca de clock (rig SL); pânico do v1.9 em troca de taxa.
A25: C | B25: Síntese do sistema (C1 ciclo de vida, C2 sync, C3 comunicação, C4 transporte, C5 user-client, C6 latência) | C25: Concluído | D25: =IFERROR(F25/E25,0) | E25: =SUM(COUNTIF(Itens!$B$2:$B$500,{"C1","C2","C3","C4","C5","C6"})) | F25: =SUM(COUNTIFS(Itens!$B$2:$B$500,{"C1","C2","C3","C4","C5","C6"},Itens!$K$2:$K$500,"Consistente"))+SUM(COUNTIFS(Itens!$B$2:$B$500,{"C1","C2","C3","C4","C5","C6"},Itens!$K$2:$K$500,"Corrigido 2026-10-14"))+SUM(COUNTIFS(Itens!$B$2:$B$500,{"C1","C2","C3","C4","C5","C6"},Itens!$K$2:$K$500,"Corrigido 2026-10-15"))+SUM(COUNTIFS(Itens!$B$2:$B$500,{"C1","C2","C3","C4","C5","C6"},Itens!$K$2:$K$500,"Corrigido 2026-10-16"))+SUM(COUNTIFS(Itens!$B$2:$B$500,{"C1","C2","C3","C4","C5","C6"},Itens!$K$2:$K$500,"Corrigido 2026-10-09")) | G25: =SUM(COUNTIFS(Itens!$B$2:$B$500,{"C1","C2","C3","C4","C5","C6"},Itens!$K$2:$K$500,"Aberto / não resolvido")) | H25: =SUM(COUNTIFS(Itens!$B$2:$B$500,{"C1","C2","C3","C4","C5","C6"},Itens!$K$2:$K$500,"Não auditado")) | I25: =SUM(COUNTIFS(Flags_auditoria!$K$2:$K$500,{"C1","C2","C3","C4","C5","C6"},Flags_auditoria!$H$2:$H$500,"Aberto")) | K25: C1–C6 consolidados em 2026-10-14 (P5, R35): uma versão consistente por documento; itens não verificados seguem rotulados. | L25: Restam só medições/hardware (7 flags abertas) e os itens P1–P4/P6; nada de texto antigo a consolidar.
A26: Aud | B26: Auditoria de proveniência (129 flags) | C26: Em andamento | D26: =IFERROR(F26/E26,0) | E26: =COUNTIF(Flags_auditoria!$A$2:$A$500,"AUD-*") | F26: =COUNTIF(Flags_auditoria!$H$2:$H$500,"Resolvido")+COUNTIF(Flags_auditoria!$H$2:$H$500,"Rotulado") | G26: =COUNTIF(Flags_auditoria!$H$2:$H$500,"Aberto") | H26: — | I26: =COUNTIF(Flags_auditoria!$H$2:$H$500,"Aberto") | K26: Resolvidas/rotuladas todas as pendências; restam as abertas que exigem captura ou fonte Apple. | L26: Fechar as flags "Aberto" (aba Flags_auditoria, coluna Status): temporização, hipótese 0xCF, firmware read-shy.
A27: Pré | B27: Pesquisa pré-build (Q-MAMAP, Q3b, Q-SDK, Q-RATE-LATENCY, rig SL) | C27: Em andamento | D27: =IFERROR(F27/E27,0) | E27: =SUM(COUNTIF(Itens!$P$2:$P$500,{"A1-Q-SDK","A1-Q3b","A1-Q15f","A1-Q-CMP"})) | F27: =SUM(COUNTIFS(Itens!$P$2:$P$500,{"A1-Q-SDK","A1-Q3b","A1-Q15f","A1-Q-CMP"},Itens!$K$2:$K$500,"Consistente"))+SUM(COUNTIFS(Itens!$P$2:$P$500,{"A1-Q-SDK","A1-Q3b","A1-Q15f","A1-Q-CMP"},Itens!$K$2:$K$500,"Corrigido 2026-10-14"))+SUM(COUNTIFS(Itens!$P$2:$P$500,{"A1-Q-SDK","A1-Q3b","A1-Q15f","A1-Q-CMP"},Itens!$K$2:$K$500,"Corrigido 2026-10-15"))+SUM(COUNTIFS(Itens!$P$2:$P$500,{"A1-Q-SDK","A1-Q3b","A1-Q15f","A1-Q-CMP"},Itens!$K$2:$K$500,"Corrigido 2026-10-16"))+SUM(COUNTIFS(Itens!$P$2:$P$500,{"A1-Q-SDK","A1-Q3b","A1-Q15f","A1-Q-CMP"},Itens!$K$2:$K$500,"Corrigido 2026-10-09")) | G27: =SUM(COUNTIFS(Itens!$P$2:$P$500,{"A1-Q-SDK","A1-Q3b","A1-Q15f","A1-Q-CMP"},Itens!$K$2:$K$500,"Aberto / não resolvido")) | H27: =SUM(COUNTIFS(Itens!$P$2:$P$500,{"A1-Q-SDK","A1-Q3b","A1-Q15f","A1-Q-CMP"},Itens!$K$2:$K$500,"Não auditado")) | I27: — | K27: Q-SDK refutou o breaker #3; causa do pânico = operator delete(NULL) na destruição. | L27: Q-SDK.5 fechado. Resta: tolerância a NULL no kernel SL (hipótese), rodada 2 no 10.13.6 (precisa de patch, congelado até D).
A28: D | B28: Decisão de build (D1 patch, D2 clone retomado, D3 híbrido) | C28: Escolhido: D2 (clone) | D28: =IFERROR(F28/E28,0) | E28: =SUM(COUNTIF(Itens!$B$2:$B$500,{"D"})) | F28: =SUM(COUNTIFS(Itens!$B$2:$B$500,{"D"},Itens!$K$2:$K$500,"Consistente"))+SUM(COUNTIFS(Itens!$B$2:$B$500,{"D"},Itens!$K$2:$K$500,"Corrigido 2026-10-14"))+SUM(COUNTIFS(Itens!$B$2:$B$500,{"D"},Itens!$K$2:$K$500,"Corrigido 2026-10-15"))+SUM(COUNTIFS(Itens!$B$2:$B$500,{"D"},Itens!$K$2:$K$500,"Corrigido 2026-10-16"))+SUM(COUNTIFS(Itens!$B$2:$B$500,{"D"},Itens!$K$2:$K$500,"Corrigido 2026-10-09")) | G28: =SUM(COUNTIFS(Itens!$B$2:$B$500,{"D"},Itens!$K$2:$K$500,"Aberto / não resolvido")) | H28: =SUM(COUNTIFS(Itens!$B$2:$B$500,{"D"},Itens!$K$2:$K$500,"Não auditado")) | I28: =SUM(COUNTIFS(Flags_auditoria!$K$2:$K$500,{"D"},Flags_auditoria!$H$2:$H$500,"Aberto")) | K28: D2 (clone completo) escolhido pelo usuário em 2026-10-14; D1/D3 retirados; plano em docs/BUILD-PLAN.md. | L28: Você aprovar o BUILD-PLAN (portão G1). Código congelado até lá.
A29: Fase | B29: Pacote de build (aba Build) | C29: Estado | D29: % pronto | E29: Tarefas | F29: Concluídas | G29: Em andamento | H29: Autorizadas | I29: Aguardam plano | K29: Onde estamos | L29: O que falta / próximo passo
A30: P | B30: Pré-trabalho estático P1–P6 (DCL clássico, IOBMD, firmware no kext, tabelas, C-docs, oráculo) | C30: =IF(F30=E30,"Concluído",IF(F30+G30>0,"Em andamento",IF(H30>0,"Autorizado","Não iniciado"))) | D30: =IFERROR(F30/E30,0) | E30: =COUNTIF(Build!$B$2:$B$300,"P")-(COUNTIFS(Build!$B$2:$B$300,"P",Build!$F$2:$F$300,"Cancelado*")+COUNTIFS(Build!$B$2:$B$300,"P",Build!$F$2:$F$300,"Sob demanda*")) | F30: =COUNTIFS(Build!$B$2:$B$300,"P",Build!$F$2:$F$300,"Concluído") | G30: =COUNTIFS(Build!$B$2:$B$300,"P",Build!$F$2:$F$300,"Em andamento") | H30: =COUNTIFS(Build!$B$2:$B$300,"P",Build!$F$2:$F$300,"Autorizado (pré-trabalho)") | I30: =COUNTIFS(Build!$B$2:$B$300,"P",Build!$F$2:$F$300,"Aguarda aprovação do plano") | K30: P1–P6 concluídos em 2026-10-14 (R35–R39). | L30: Nada.
A31: M | B31: Kext clone (M-A…M-M: esqueleto, firmware, DCL, CMP, taxas, mixer, user-client, MIDI, AC3, engines, multi, latência, UX) | C31: =IF(F31=E31,"Concluído",IF(F31+G31>0,"Em andamento",IF(H31>0,"Autorizado","Não iniciado"))) | D31: =IFERROR(F31/E31,0) | E31: =COUNTIF(Build!$B$2:$B$300,"M")-(COUNTIFS(Build!$B$2:$B$300,"M",Build!$F$2:$F$300,"Cancelado*")+COUNTIFS(Build!$B$2:$B$300,"M",Build!$F$2:$F$300,"Sob demanda*")) | F31: =COUNTIFS(Build!$B$2:$B$300,"M",Build!$F$2:$F$300,"Concluído") | G31: =COUNTIFS(Build!$B$2:$B$300,"M",Build!$F$2:$F$300,"Em andamento") | H31: =COUNTIFS(Build!$B$2:$B$300,"M",Build!$F$2:$F$300,"Autorizado (pré-trabalho)") | I31: =COUNTIFS(Build!$B$2:$B$300,"M",Build!$F$2:$F$300,"Aguarda aprovação do plano") | K31: Kext 0.1.0 completo e em uso; caminhos não exercitados (sleep/wake, MIDI no fio, AC-3, pares, latência em todas as taxas) sob demanda. | L31: Nada planejado; só se o uso real pedir.
A32: H | B32: Helper novo estilo MAFireWireLoader (H.1–H.6) | C32: =IF(F32=E32,"Concluído",IF(F32+G32>0,"Em andamento",IF(H32>0,"Autorizado","Não iniciado"))) | D32: =IFERROR(F32/E32,0) | E32: =COUNTIF(Build!$B$2:$B$300,"H")-(COUNTIFS(Build!$B$2:$B$300,"H",Build!$F$2:$F$300,"Cancelado*")+COUNTIFS(Build!$B$2:$B$300,"H",Build!$F$2:$F$300,"Sob demanda*")) | F32: =COUNTIFS(Build!$B$2:$B$300,"H",Build!$F$2:$F$300,"Concluído") | G32: =COUNTIFS(Build!$B$2:$B$300,"H",Build!$F$2:$F$300,"Em andamento") | H32: =COUNTIFS(Build!$B$2:$B$300,"H",Build!$F$2:$F$300,"Autorizado (pré-trabalho)") | I32: =COUNTIFS(Build!$B$2:$B$300,"H",Build!$F$2:$F$300,"Aguarda aprovação do plano") | K32: H.1/H.4 verificados; H.3 sob demanda; H.2/H.5 cancelados. | L32: —
A33: PN | B33: Painel AppKit novo, paridade total (PN.1–PN.7) | C33: =IF(F33=E33,"Concluído",IF(F33+G33>0,"Em andamento",IF(H33>0,"Autorizado","Não iniciado"))) | D33: =IFERROR(F33/E33,0) | E33: =COUNTIF(Build!$B$2:$B$300,"PN")-(COUNTIFS(Build!$B$2:$B$300,"PN",Build!$F$2:$F$300,"Cancelado*")+COUNTIFS(Build!$B$2:$B$300,"PN",Build!$F$2:$F$300,"Sob demanda*")) | F33: =COUNTIFS(Build!$B$2:$B$300,"PN",Build!$F$2:$F$300,"Concluído") | G33: =COUNTIFS(Build!$B$2:$B$300,"PN",Build!$F$2:$F$300,"Em andamento") | H33: =COUNTIFS(Build!$B$2:$B$300,"PN",Build!$F$2:$F$300,"Autorizado (pré-trabalho)") | I33: =COUNTIFS(Build!$B$2:$B$300,"PN",Build!$F$2:$F$300,"Aguarda aprovação do plano") | K33: Painel concluído (0.1.0) e substituído pelo painel 0.2.x. | L33: —
A34: IN | B34: Validação, instalador e entrega (IN.1–IN.6) | C34: =IF(F34=E34,"Concluído",IF(F34+G34>0,"Em andamento",IF(H34>0,"Autorizado","Não iniciado"))) | D34: =IFERROR(F34/E34,0) | E34: =COUNTIF(Build!$B$2:$B$300,"IN")-(COUNTIFS(Build!$B$2:$B$300,"IN",Build!$F$2:$F$300,"Cancelado*")+COUNTIFS(Build!$B$2:$B$300,"IN",Build!$F$2:$F$300,"Sob demanda*")) | F34: =COUNTIFS(Build!$B$2:$B$300,"IN",Build!$F$2:$F$300,"Concluído") | G34: =COUNTIFS(Build!$B$2:$B$300,"IN",Build!$F$2:$F$300,"Em andamento") | H34: =COUNTIFS(Build!$B$2:$B$300,"IN",Build!$F$2:$F$300,"Autorizado (pré-trabalho)") | I34: =COUNTIFS(Build!$B$2:$B$300,"IN",Build!$F$2:$F$300,"Aguarda aprovação do plano") | K34: Pacote, dmg e desinstalador em uso (0.2.2); IN.1/IN.6 cancelados (sem assinatura); IN.2/IN.4 sob demanda. | L34: —
A36: Ramos principais (por parte do system-map)
A37: Ramo | B37: Descrição | C37: Estado | D37: % fechado | E37: Itens | F37: Fechados | G37: Abertos | H37: Pend. correção | I37: Não audit. | J37: Flags abertas | K37: O que falta | L37: Confiança média
A38: A1 | B38: Kext: classes, DCL, HSCI, mixer, user-client | C38: =IF(D38>=1,"Fechado",IF(G38+H38>0,"Com pendência",IF(I38>0,"Parcial","Em dia"))) | D38: =IFERROR(F38/E38,0) | E38: =COUNTIF(Itens!$B$2:$B$500,A38) | F38: =COUNTIFS(Itens!$B$2:$B$500,A38,Itens!$K$2:$K$500,"Consistente")+COUNTIFS(Itens!$B$2:$B$500,A38,Itens!$K$2:$K$500,"Corrigido 2026-10-14")+COUNTIFS(Itens!$B$2:$B$500,A38,Itens!$K$2:$K$500,"Corrigido 2026-10-15")+COUNTIFS(Itens!$B$2:$B$500,A38,Itens!$K$2:$K$500,"Corrigido 2026-10-16")+COUNTIFS(Itens!$B$2:$B$500,A38,Itens!$K$2:$K$500,"Corrigido 2026-10-09") | G38: =COUNTIFS(Itens!$B$2:$B$500,A38,Itens!$K$2:$K$500,"Aberto / não resolvido") | H38: =COUNTIFS(Itens!$B$2:$B$500,A38,Itens!$K$2:$K$500,"Correção pendente (audit)") | I38: =COUNTIFS(Itens!$B$2:$B$500,A38,Itens!$K$2:$K$500,"Não auditado") | J38: =COUNTIFS(Flags_auditoria!$K$2:$K$500,A38,Flags_auditoria!$H$2:$H$500,"Aberto") | K38: A1-Q-DCL.9: aceitação do DCL no 10.13.6 (só no teste integrado). A1-Q3a.5: quem inicia os canais (Q-START). A1-Q17.2: hipótese 0xCF. | L38: =IFERROR(AVERAGEIF(Itens!$B$2:$B$500,A38,Itens!$L$2:$L$500),0)
A39: A2 | B39: Painel Carbon/NIB (chaves MA*, medidores) | C39: =IF(D39>=1,"Fechado",IF(G39+H39>0,"Com pendência",IF(I39>0,"Parcial","Em dia"))) | D39: =IFERROR(F39/E39,0) | E39: =COUNTIF(Itens!$B$2:$B$500,A39) | F39: =COUNTIFS(Itens!$B$2:$B$500,A39,Itens!$K$2:$K$500,"Consistente")+COUNTIFS(Itens!$B$2:$B$500,A39,Itens!$K$2:$K$500,"Corrigido 2026-10-14")+COUNTIFS(Itens!$B$2:$B$500,A39,Itens!$K$2:$K$500,"Corrigido 2026-10-15")+COUNTIFS(Itens!$B$2:$B$500,A39,Itens!$K$2:$K$500,"Corrigido 2026-10-16")+COUNTIFS(Itens!$B$2:$B$500,A39,Itens!$K$2:$K$500,"Corrigido 2026-10-09") | G39: =COUNTIFS(Itens!$B$2:$B$500,A39,Itens!$K$2:$K$500,"Aberto / não resolvido") | H39: =COUNTIFS(Itens!$B$2:$B$500,A39,Itens!$K$2:$K$500,"Correção pendente (audit)") | I39: =COUNTIFS(Itens!$B$2:$B$500,A39,Itens!$K$2:$K$500,"Não auditado") | J39: =COUNTIFS(Flags_auditoria!$K$2:$K$500,A39,Flags_auditoria!$H$2:$H$500,"Aberto") | K39: — | L39: =IFERROR(AVERAGEIF(Itens!$B$2:$B$500,A39,Itens!$L$2:$L$500),0)
A40: A3 | B40: Plug-in CoreMIDI | C40: =IF(D40>=1,"Fechado",IF(G40+H40>0,"Com pendência",IF(I40>0,"Parcial","Em dia"))) | D40: =IFERROR(F40/E40,0) | E40: =COUNTIF(Itens!$B$2:$B$500,A40) | F40: =COUNTIFS(Itens!$B$2:$B$500,A40,Itens!$K$2:$K$500,"Consistente")+COUNTIFS(Itens!$B$2:$B$500,A40,Itens!$K$2:$K$500,"Corrigido 2026-10-14")+COUNTIFS(Itens!$B$2:$B$500,A40,Itens!$K$2:$K$500,"Corrigido 2026-10-15")+COUNTIFS(Itens!$B$2:$B$500,A40,Itens!$K$2:$K$500,"Corrigido 2026-10-16")+COUNTIFS(Itens!$B$2:$B$500,A40,Itens!$K$2:$K$500,"Corrigido 2026-10-09") | G40: =COUNTIFS(Itens!$B$2:$B$500,A40,Itens!$K$2:$K$500,"Aberto / não resolvido") | H40: =COUNTIFS(Itens!$B$2:$B$500,A40,Itens!$K$2:$K$500,"Correção pendente (audit)") | I40: =COUNTIFS(Itens!$B$2:$B$500,A40,Itens!$K$2:$K$500,"Não auditado") | J40: =COUNTIFS(Flags_auditoria!$K$2:$K$500,A40,Flags_auditoria!$H$2:$H$500,"Aberto") | K40: — | L40: =IFERROR(AVERAGEIF(Itens!$B$2:$B$500,A40,Itens!$L$2:$L$500),0)
A41: A4 | B41: Helper de firmware | C41: =IF(D41>=1,"Fechado",IF(G41+H41>0,"Com pendência",IF(I41>0,"Parcial","Em dia"))) | D41: =IFERROR(F41/E41,0) | E41: =COUNTIF(Itens!$B$2:$B$500,A41) | F41: =COUNTIFS(Itens!$B$2:$B$500,A41,Itens!$K$2:$K$500,"Consistente")+COUNTIFS(Itens!$B$2:$B$500,A41,Itens!$K$2:$K$500,"Corrigido 2026-10-14")+COUNTIFS(Itens!$B$2:$B$500,A41,Itens!$K$2:$K$500,"Corrigido 2026-10-15")+COUNTIFS(Itens!$B$2:$B$500,A41,Itens!$K$2:$K$500,"Corrigido 2026-10-16")+COUNTIFS(Itens!$B$2:$B$500,A41,Itens!$K$2:$K$500,"Corrigido 2026-10-09") | G41: =COUNTIFS(Itens!$B$2:$B$500,A41,Itens!$K$2:$K$500,"Aberto / não resolvido") | H41: =COUNTIFS(Itens!$B$2:$B$500,A41,Itens!$K$2:$K$500,"Correção pendente (audit)") | I41: =COUNTIFS(Itens!$B$2:$B$500,A41,Itens!$K$2:$K$500,"Não auditado") | J41: =COUNTIFS(Flags_auditoria!$K$2:$K$500,A41,Flags_auditoria!$H$2:$H$500,"Aberto") | K41: — | L41: =IFERROR(AVERAGEIF(Itens!$B$2:$B$500,A41,Itens!$L$2:$L$500),0)
A42: A5 | B42: Envelope de firmware .bcd | C42: =IF(D42>=1,"Fechado",IF(G42+H42>0,"Com pendência",IF(I42>0,"Parcial","Em dia"))) | D42: =IFERROR(F42/E42,0) | E42: =COUNTIF(Itens!$B$2:$B$500,A42) | F42: =COUNTIFS(Itens!$B$2:$B$500,A42,Itens!$K$2:$K$500,"Consistente")+COUNTIFS(Itens!$B$2:$B$500,A42,Itens!$K$2:$K$500,"Corrigido 2026-10-14")+COUNTIFS(Itens!$B$2:$B$500,A42,Itens!$K$2:$K$500,"Corrigido 2026-10-15")+COUNTIFS(Itens!$B$2:$B$500,A42,Itens!$K$2:$K$500,"Corrigido 2026-10-16")+COUNTIFS(Itens!$B$2:$B$500,A42,Itens!$K$2:$K$500,"Corrigido 2026-10-09") | G42: =COUNTIFS(Itens!$B$2:$B$500,A42,Itens!$K$2:$K$500,"Aberto / não resolvido") | H42: =COUNTIFS(Itens!$B$2:$B$500,A42,Itens!$K$2:$K$500,"Correção pendente (audit)") | I42: =COUNTIFS(Itens!$B$2:$B$500,A42,Itens!$K$2:$K$500,"Não auditado") | J42: =COUNTIFS(Flags_auditoria!$K$2:$K$500,A42,Flags_auditoria!$H$2:$H$500,"Aberto") | K42: — | L42: =IFERROR(AVERAGEIF(Itens!$B$2:$B$500,A42,Itens!$L$2:$L$500),0)
A43: A6 | B43: Prefpane | C43: =IF(D43>=1,"Fechado",IF(G43+H43>0,"Com pendência",IF(I43>0,"Parcial","Em dia"))) | D43: =IFERROR(F43/E43,0) | E43: =COUNTIF(Itens!$B$2:$B$500,A43) | F43: =COUNTIFS(Itens!$B$2:$B$500,A43,Itens!$K$2:$K$500,"Consistente")+COUNTIFS(Itens!$B$2:$B$500,A43,Itens!$K$2:$K$500,"Corrigido 2026-10-14")+COUNTIFS(Itens!$B$2:$B$500,A43,Itens!$K$2:$K$500,"Corrigido 2026-10-15")+COUNTIFS(Itens!$B$2:$B$500,A43,Itens!$K$2:$K$500,"Corrigido 2026-10-16")+COUNTIFS(Itens!$B$2:$B$500,A43,Itens!$K$2:$K$500,"Corrigido 2026-10-09") | G43: =COUNTIFS(Itens!$B$2:$B$500,A43,Itens!$K$2:$K$500,"Aberto / não resolvido") | H43: =COUNTIFS(Itens!$B$2:$B$500,A43,Itens!$K$2:$K$500,"Correção pendente (audit)") | I43: =COUNTIFS(Itens!$B$2:$B$500,A43,Itens!$K$2:$K$500,"Não auditado") | J43: =COUNTIFS(Flags_auditoria!$K$2:$K$500,A43,Flags_auditoria!$H$2:$H$500,"Aberto") | K43: — | L43: =IFERROR(AVERAGEIF(Itens!$B$2:$B$500,A43,Itens!$L$2:$L$500),0)
...

Sheet Resumo
A1: Matriz de proveniência — system-map FW1814 (2026-10-14)
A2: Tudo nesta aba é fórmula sobre as abas Itens e Flags_auditoria.
A4: Parte | B4: Itens | C4: Confiança média | D4: Byte-level = Sim | E4: Hardware live = Sim | F4: Especulativo = Sim | G4: Correção pendente | H4: Aberto | I4: Confiança ≤ 3 | J4: Confiança ≥ 7
A5: A1 | B5: =COUNTIF(Itens!$B$2:$B$132,A5) | C5: =IFERROR(AVERAGEIF(Itens!$B$2:$B$132,A5,Itens!$L$2:$L$132),0) | D5: =COUNTIFS(Itens!$B$2:$B$132,A5,Itens!$E$2:$E$132,"Sim") | E5: =COUNTIFS(Itens!$B$2:$B$132,A5,Itens!$F$2:$F$132,"Sim") | F5: =COUNTIFS(Itens!$B$2:$B$132,A5,Itens!$H$2:$H$132,"Sim") | G5: =COUNTIFS(Itens!$B$2:$B$132,A5,Itens!$K$2:$K$132,"Correção pendente (audit)") | H5: =COUNTIFS(Itens!$B$2:$B$132,A5,Itens!$K$2:$K$132,"Aberto / não resolvido") | I5: =COUNTIFS(Itens!$B$2:$B$132,A5,Itens!$L$2:$L$132,"<=3") | J5: =COUNTIFS(Itens!$B$2:$B$132,A5,Itens!$L$2:$L$132,">=7")
A6: A2 | B6: =COUNTIF(Itens!$B$2:$B$132,A6) | C6: =IFERROR(AVERAGEIF(Itens!$B$2:$B$132,A6,Itens!$L$2:$L$132),0) | D6: =COUNTIFS(Itens!$B$2:$B$132,A6,Itens!$E$2:$E$132,"Sim") | E6: =COUNTIFS(Itens!$B$2:$B$132,A6,Itens!$F$2:$F$132,"Sim") | F6: =COUNTIFS(Itens!$B$2:$B$132,A6,Itens!$H$2:$H$132,"Sim") | G6: =COUNTIFS(Itens!$B$2:$B$132,A6,Itens!$K$2:$K$132,"Correção pendente (audit)") | H6: =COUNTIFS(Itens!$B$2:$B$132,A6,Itens!$K$2:$K$132,"Aberto / não resolvido") | I6: =COUNTIFS(Itens!$B$2:$B$132,A6,Itens!$L$2:$L$132,"<=3") | J6: =COUNTIFS(Itens!$B$2:$B$132,A6,Itens!$L$2:$L$132,">=7")
A7: A3 | B7: =COUNTIF(Itens!$B$2:$B$132,A7) | C7: =IFERROR(AVERAGEIF(Itens!$B$2:$B$132,A7,Itens!$L$2:$L$132),0) | D7: =COUNTIFS(Itens!$B$2:$B$132,A7,Itens!$E$2:$E$132,"Sim") | E7: =COUNTIFS(Itens!$B$2:$B$132,A7,Itens!$F$2:$F$132,"Sim") | F7: =COUNTIFS(Itens!$B$2:$B$132,A7,Itens!$H$2:$H$132,"Sim") | G7: =COUNTIFS(Itens!$B$2:$B$132,A7,Itens!$K$2:$K$132,"Correção pendente (audit)") | H7: =COUNTIFS(Itens!$B$2:$B$132,A7,Itens!$K$2:$K$132,"Aberto / não resolvido") | I7: =COUNTIFS(Itens!$B$2:$B$132,A7,Itens!$L$2:$L$132,"<=3") | J7: =COUNTIFS(Itens!$B$2:$B$132,A7,Itens!$L$2:$L$132,">=7")
A8: A4 | B8: =COUNTIF(Itens!$B$2:$B$132,A8) | C8: =IFERROR(AVERAGEIF(Itens!$B$2:$B$132,A8,Itens!$L$2:$L$132),0) | D8: =COUNTIFS(Itens!$B$2:$B$132,A8,Itens!$E$2:$E$132,"Sim") | E8: =COUNTIFS(Itens!$B$2:$B$132,A8,Itens!$F$2:$F$132,"Sim") | F8: =COUNTIFS(Itens!$B$2:$B$132,A8,Itens!$H$2:$H$132,"Sim") | G8: =COUNTIFS(Itens!$B$2:$B$132,A8,Itens!$K$2:$K$132,"Correção pendente (audit)") | H8: =COUNTIFS(Itens!$B$2:$B$132,A8,Itens!$K$2:$K$132,"Aberto / não resolvido") | I8: =COUNTIFS(Itens!$B$2:$B$132,A8,Itens!$L$2:$L$132,"<=3") | J8: =COUNTIFS(Itens!$B$2:$B$132,A8,Itens!$L$2:$L$132,">=7")
A9: A5 | B9: =COUNTIF(Itens!$B$2:$B$132,A9) | C9: =IFERROR(AVERAGEIF(Itens!$B$2:$B$132,A9,Itens!$L$2:$L$132),0) | D9: =COUNTIFS(Itens!$B$2:$B$132,A9,Itens!$E$2:$E$132,"Sim") | E9: =COUNTIFS(Itens!$B$2:$B$132,A9,Itens!$F$2:$F$132,"Sim") | F9: =COUNTIFS(Itens!$B$2:$B$132,A9,Itens!$H$2:$H$132,"Sim") | G9: =COUNTIFS(Itens!$B$2:$B$132,A9,Itens!$K$2:$K$132,"Correção pendente (audit)") | H9: =COUNTIFS(Itens!$B$2:$B$132,A9,Itens!$K$2:$K$132,"Aberto / não resolvido") | I9: =COUNTIFS(Itens!$B$2:$B$132,A9,Itens!$L$2:$L$132,"<=3") | J9: =COUNTIFS(Itens!$B$2:$B$132,A9,Itens!$L$2:$L$132,">=7")
A10: A6 | B10: =COUNTIF(Itens!$B$2:$B$132,A10) | C10: =IFERROR(AVERAGEIF(Itens!$B$2:$B$132,A10,Itens!$L$2:$L$132),0) | D10: =COUNTIFS(Itens!$B$2:$B$132,A10,Itens!$E$2:$E$132,"Sim") | E10: =COUNTIFS(Itens!$B$2:$B$132,A10,Itens!$F$2:$F$132,"Sim") | F10: =COUNTIFS(Itens!$B$2:$B$132,A10,Itens!$H$2:$H$132,"Sim") | G10: =COUNTIFS(Itens!$B$2:$B$132,A10,Itens!$K$2:$K$132,"Correção pendente (audit)") | H10: =COUNTIFS(Itens!$B$2:$B$132,A10,Itens!$K$2:$K$132,"Aberto / não resolvido") | I10: =COUNTIFS(Itens!$B$2:$B$132,A10,Itens!$L$2:$L$132,"<=3") | J10: =COUNTIFS(Itens!$B$2:$B$132,A10,Itens!$L$2:$L$132,">=7")
A11: B1 | B11: =COUNTIF(Itens!$B$2:$B$132,A11) | C11: =IFERROR(AVERAGEIF(Itens!$B$2:$B$132,A11,Itens!$L$2:$L$132),0) | D11: =COUNTIFS(Itens!$B$2:$B$132,A11,Itens!$E$2:$E$132,"Sim") | E11: =COUNTIFS(Itens!$B$2:$B$132,A11,Itens!$F$2:$F$132,"Sim") | F11: =COUNTIFS(Itens!$B$2:$B$132,A11,Itens!$H$2:$H$132,"Sim") | G11: =COUNTIFS(Itens!$B$2:$B$132,A11,Itens!$K$2:$K$132,"Correção pendente (audit)") | H11: =COUNTIFS(Itens!$B$2:$B$132,A11,Itens!$K$2:$K$132,"Aberto / não resolvido") | I11: =COUNTIFS(Itens!$B$2:$B$132,A11,Itens!$L$2:$L$132,"<=3") | J11: =COUNTIFS(Itens!$B$2:$B$132,A11,Itens!$L$2:$L$132,">=7")
A12: B2 | B12: =COUNTIF(Itens!$B$2:$B$132,A12) | C12: =IFERROR(AVERAGEIF(Itens!$B$2:$B$132,A12,Itens!$L$2:$L$132),0) | D12: =COUNTIFS(Itens!$B$2:$B$132,A12,Itens!$E$2:$E$132,"Sim") | E12: =COUNTIFS(Itens!$B$2:$B$132,A12,Itens!$F$2:$F$132,"Sim") | F12: =COUNTIFS(Itens!$B$2:$B$132,A12,Itens!$H$2:$H$132,"Sim") | G12: =COUNTIFS(Itens!$B$2:$B$132,A12,Itens!$K$2:$K$132,"Correção pendente (audit)") | H12: =COUNTIFS(Itens!$B$2:$B$132,A12,Itens!$K$2:$K$132,"Aberto / não resolvido") | I12: =COUNTIFS(Itens!$B$2:$B$132,A12,Itens!$L$2:$L$132,"<=3") | J12: =COUNTIFS(Itens!$B$2:$B$132,A12,Itens!$L$2:$L$132,">=7")
A13: B2a | B13: =COUNTIF(Itens!$B$2:$B$132,A13) | C13: =IFERROR(AVERAGEIF(Itens!$B$2:$B$132,A13,Itens!$L$2:$L$132),0) | D13: =COUNTIFS(Itens!$B$2:$B$132,A13,Itens!$E$2:$E$132,"Sim") | E13: =COUNTIFS(Itens!$B$2:$B$132,A13,Itens!$F$2:$F$132,"Sim") | F13: =COUNTIFS(Itens!$B$2:$B$132,A13,Itens!$H$2:$H$132,"Sim") | G13: =COUNTIFS(Itens!$B$2:$B$132,A13,Itens!$K$2:$K$132,"Correção pendente (audit)") | H13: =COUNTIFS(Itens!$B$2:$B$132,A13,Itens!$K$2:$K$132,"Aberto / não resolvido") | I13: =COUNTIFS(Itens!$B$2:$B$132,A13,Itens!$L$2:$L$132,"<=3") | J13: =COUNTIFS(Itens!$B$2:$B$132,A13,Itens!$L$2:$L$132,">=7")
A14: B3 | B14: =COUNTIF(Itens!$B$2:$B$132,A14) | C14: =IFERROR(AVERAGEIF(Itens!$B$2:$B$132,A14,Itens!$L$2:$L$132),0) | D14: =COUNTIFS(Itens!$B$2:$B$132,A14,Itens!$E$2:$E$132,"Sim") | E14: =COUNTIFS(Itens!$B$2:$B$132,A14,Itens!$F$2:$F$132,"Sim") | F14: =COUNTIFS(Itens!$B$2:$B$132,A14,Itens!$H$2:$H$132,"Sim") | G14: =COUNTIFS(Itens!$B$2:$B$132,A14,Itens!$K$2:$K$132,"Correção pendente (audit)") | H14: =COUNTIFS(Itens!$B$2:$B$132,A14,Itens!$K$2:$K$132,"Aberto / não resolvido") | I14: =COUNTIFS(Itens!$B$2:$B$132,A14,Itens!$L$2:$L$132,"<=3") | J14: =COUNTIFS(Itens!$B$2:$B$132,A14,Itens!$L$2:$L$132,">=7")
A15: B4 | B15: =COUNTIF(Itens!$B$2:$B$132,A15) | C15: =IFERROR(AVERAGEIF(Itens!$B$2:$B$132,A15,Itens!$L$2:$L$132),0) | D15: =COUNTIFS(Itens!$B$2:$B$132,A15,Itens!$E$2:$E$132,"Sim") | E15: =COUNTIFS(Itens!$B$2:$B$132,A15,Itens!$F$2:$F$132,"Sim") | F15: =COUNTIFS(Itens!$B$2:$B$132,A15,Itens!$H$2:$H$132,"Sim") | G15: =COUNTIFS(Itens!$B$2:$B$132,A15,Itens!$K$2:$K$132,"Correção pendente (audit)") | H15: =COUNTIFS(Itens!$B$2:$B$132,A15,Itens!$K$2:$K$132,"Aberto / não resolvido") | I15: =COUNTIFS(Itens!$B$2:$B$132,A15,Itens!$L$2:$L$132,"<=3") | J15: =COUNTIFS(Itens!$B$2:$B$132,A15,Itens!$L$2:$L$132,">=7")
A16: B5 | B16: =COUNTIF(Itens!$B$2:$B$132,A16) | C16: =IFERROR(AVERAGEIF(Itens!$B$2:$B$132,A16,Itens!$L$2:$L$132),0) | D16: =COUNTIFS(Itens!$B$2:$B$132,A16,Itens!$E$2:$E$132,"Sim") | E16: =COUNTIFS(Itens!$B$2:$B$132,A16,Itens!$F$2:$F$132,"Sim") | F16: =COUNTIFS(Itens!$B$2:$B$132,A16,Itens!$H$2:$H$132,"Sim") | G16: =COUNTIFS(Itens!$B$2:$B$132,A16,Itens!$K$2:$K$132,"Correção pendente (audit)") | H16: =COUNTIFS(Itens!$B$2:$B$132,A16,Itens!$K$2:$K$132,"Aberto / não resolvido") | I16: =COUNTIFS(Itens!$B$2:$B$132,A16,Itens!$L$2:$L$132,"<=3") | J16: =COUNTIFS(Itens!$B$2:$B$132,A16,Itens!$L$2:$L$132,">=7")
... A24: D | B24: =COUNTIF(Itens!$B$2:$B$132,A24) | C24: =IFERROR(AVERAGEIF(Itens!$B$2:$B$132,A24,Itens!$L$2:$L$132),0) | D24: =COUNTIFS(Itens!$B$2:$B$132,A24,Itens!$E$2:$E$132,"Sim") | E24: =COUNTIFS(Itens!$B$2:$B$132,A24,Itens!$F$2:$F$132,"Sim") | F24: =COUNTIFS(Itens!$B$2:$B$132,A24,Itens!$H$2:$H$132,"Sim") | G24: =COUNTIFS(Itens!$B$2:$B$132,A24,Itens!$K$2:$K$132,"Correção pendente (audit)") | H24: =COUNTIFS(Itens!$B$2:$B$132,A24,Itens!$K$2:$K$132,"Aberto / não resolvido") | I24: =COUNTIFS(Itens!$B$2:$B$132,A24,Itens!$L$2:$L$132,"<=3") | J24: =COUNTIFS(Itens!$B$2:$B$132,A24,Itens!$L$2:$L$132,">=7")
A25: Total | B25: =SUM(B5:B24) | C25: =AVERAGE(Itens!$L$2:$L$132) | D25: =SUM(D5:D24) | E25: =SUM(E5:E24) | F25: =SUM(F5:F24) | G25: =SUM(G5:G24) | H25: =SUM(H5:H24) | I25: =SUM(I5:I24) | J25: =SUM(J5:J24)
A27: Flags do audit por categoria e severidade
A28: Categoria | B28: Significado | C28: Total | D28: Alta | E28: Média | F28: Baixa
A29: 1 | B29: Inferência como fato | C29: =COUNTIF(Flags_auditoria!$E$2:$E$127,"*"&A29&"*") | D29: =COUNTIFS(Flags_auditoria!$E$2:$E$127,"*"&A29&"*",Flags_auditoria!$F$2:$F$127,"alta") | E29: =COUNTIFS(Flags_auditoria!$E$2:$E$127,"*"&A29&"*",Flags_auditoria!$F$2:$F$127,"média") | F29: =COUNTIFS(Flags_auditoria!$E$2:$E$127,"*"&A29&"*",Flags_auditoria!$F$2:$F$127,"baixa")
A30: 2 | B30: Só fonte de terceiros | C30: =COUNTIF(Flags_auditoria!$E$2:$E$127,"*"&A30&"*") | D30: =COUNTIFS(Flags_auditoria!$E$2:$E$127,"*"&A30&"*",Flags_auditoria!$F$2:$F$127,"alta") | E30: =COUNTIFS(Flags_auditoria!$E$2:$E$127,"*"&A30&"*",Flags_auditoria!$F$2:$F$127,"média") | F30: =COUNTIFS(Flags_auditoria!$E$2:$E$127,"*"&A30&"*",Flags_auditoria!$F$2:$F$127,"baixa")
A31: 3 | B31: Só decompile em valor sensível | C31: =COUNTIF(Flags_auditoria!$E$2:$E$127,"*"&A31&"*") | D31: =COUNTIFS(Flags_auditoria!$E$2:$E$127,"*"&A31&"*",Flags_auditoria!$F$2:$F$127,"alta") | E31: =COUNTIFS(Flags_auditoria!$E$2:$E$127,"*"&A31&"*",Flags_auditoria!$F$2:$F$127,"média") | F31: =COUNTIFS(Flags_auditoria!$E$2:$E$127,"*"&A31&"*",Flags_auditoria!$F$2:$F$127,"baixa")
A32: 4 | B32: Citação não confere / binário contradiz | C32: =COUNTIF(Flags_auditoria!$E$2:$E$127,"*"&A32&"*") | D32: =COUNTIFS(Flags_auditoria!$E$2:$E$127,"*"&A32&"*",Flags_auditoria!$F$2:$F$127,"alta") | E32: =COUNTIFS(Flags_auditoria!$E$2:$E$127,"*"&A32&"*",Flags_auditoria!$F$2:$F$127,"média") | F32: =COUNTIFS(Flags_auditoria!$E$2:$E$127,"*"&A32&"*",Flags_auditoria!$F$2:$F$127,"baixa")
A33: 5 | B33: Número sem fonte | C33: =COUNTIF(Flags_auditoria!$E$2:$E$127,"*"&A33&"*") | D33: =COUNTIFS(Flags_auditoria!$E$2:$E$127,"*"&A33&"*",Flags_auditoria!$F$2:$F$127,"alta") | E33: =COUNTIFS(Flags_auditoria!$E$2:$E$127,"*"&A33&"*",Flags_auditoria!$F$2:$F$127,"média") | F33: =COUNTIFS(Flags_auditoria!$E$2:$E$127,"*"&A33&"*",Flags_auditoria!$F$2:$F$127,"baixa")
A34: Linhas de flag | C34: =COUNTA(Flags_auditoria!$A$2:$A$127) | D34: =COUNTIF(Flags_auditoria!$F$2:$F$127,"alta") | E34: =COUNTIF(Flags_auditoria!$F$2:$F$127,"média") | F34: =COUNTIF(Flags_auditoria!$F$2:$F$127,"baixa")
A35: Uma linha de flag pode ter duas categorias (ex.: '4/2'); por isso a soma por categoria pode passar do total de linhas. O audit conta 129 afirmações porque algumas linhas agrupam várias.
A37: Distribuição da confiança (todos os itens)
A38: 0–3 (fraco / especulativo) | C38: =COUNTIFS(Itens!$L$2:$L$132,">=0",Itens!$L$2:$L$132,"<=3")
A39: acima de 3 até 6 (parcial) | C39: =COUNTIFS(Itens!$L$2:$L$132,">3",Itens!$L$2:$L$132,"<=6")
A40: acima de 6 até 8 (sólido) | C40: =COUNTIFS(Itens!$L$2:$L$132,">6",Itens!$L$2:$L$132,"<=8")
A41: acima de 8 até 10 (forte) | C41: =COUNTIFS(Itens!$L$2:$L$132,">8",Itens!$L$2:$L$132,"<=10")

Sheet Itens
A1: ID | B1: Parte | C1: Item | D1: Descrição breve | E1: Byte-level confirmado | F1: Hardware live | G1: Ferramenta (otool/Ghidra) | H1: Especulativo | I1: Fontes / cruzamentos (separe com ;) | J1: Nº de fontes | K1: Status documental | L1: Confiança (0–10) | M1: Referência (arquivo; seção/linha) | N1: Flags do audit (arquivo:linha) | O1: Notas / pendências | P1: Sub-ramo
A2: A1-OV.1 | B2: A1 | C2: Estrutura geral do kext | D2: 2862 funções, 222 classes; família de engines (FWEngine1/2, Pair, TimeSlave); FWMetaNub polimórfico; framework de propriedades tipadas + ChannelGroup. | E2: Parcial | F2: Não | G2: otool + Ghidra | H2: Não | I2: export Ghidra (functions.tsv, classes.md); símbolos nm | J2: =IF(TRIM(I2)="",0,LEN(I2)-LEN(SUBSTITUTE(I2,";",""))+1) | K2: Corrigido 2026-10-14 | L2: =ROUND(IF(H2="Sim",MIN(Legenda!$C$12,MIN(10,IF(E2="Sim",Legenda!$C$4,IF(E2="Parcial",Legenda!$C$5,0))+IF(F2="Sim",Legenda!$C$6,IF(F2="Parcial",Legenda!$C$7,0))+IF(G2="otool + Ghidra",Legenda!$C$8,IF(OR(G2="otool",G2="Ghidra",G2="Outro binário"),Legenda!$C$9,0))+MIN(Legenda!$C$11,MAX(0,J2-1)*Legenda!$C$10))),IF(H2="Parcial",MIN(Legenda!$C$13,MIN(10,IF(E2="Sim",Legenda!$C$4,IF(E2="Parcial",Legenda!$C$5,0))+IF(F2="Sim",Legenda!$C$6,IF(F2="Parcial",Legenda!$C$7,0))+IF(G2="otool + Ghidra",Legenda!$C$8,IF(OR(G2="otool",G2="Ghidra",G2="Outro binário"),Legenda!$C$9,0))+MIN(Legenda!$C$11,MAX(0,J2-1)*Legenda!$C$10))),MIN(10,IF(E2="Sim",Legenda!$C$4,IF(E2="Parcial",Legenda!$C$5,0))+IF(F2="Sim",Legenda!$C$6,IF(F2="Parcial",Legenda!$C$7,0))+IF(G2="otool + Ghidra",Legenda!$C$8,IF(OR(G2="otool",G2="Ghidra",G2="Outro binário"),Legenda!$C$9,0))+MIN(Legenda!$C$11,MAX(0,J2-1)*Legenda!$C$10)))),1) | M2: A1-ghidra/A1-ghidra-overview.md; ghidra-exports/classes.md | N2: A1-ghidra/README:17,19,38 | O2: Afirmação 'segundo UserClient FWKIPCUserClient' superada: é a classe-base do FWUserClient (A1-Q-UC.2). Linhas do índice A1 desatualizadas. | P2: =LEFT(A2,FIND(".",A2&".")-1)
A3: A1-Q1.1 | B3: A1 | C3: Anel DCL RX | D3: 64 segmentos × 4 pacotes + 64 jumps, ligados em anel (labels[(i+1)&0x3f]); procData = {this, segIdx}. | E3: Sim | F3: Não | G3: otool + Ghidra | H3: Não | I3: asm 0x25962/0x25a99; Ghidra (Q1); Q-DCL | J3: =IF(TRIM(I3)="",0,LEN(I3)-LEN(SUBSTITUTE(I3,";",""))+1) | K3: Corrigido 2026-10-14 | L3: =ROUND(IF(H3="Sim",MIN(Legenda!$C$12,MIN(10,IF(E3="Sim",Legenda!$C$4,IF(E3="Parcial",Legenda!$C$5,0))+IF(F3="Sim",Legenda!$C$6,IF(F3="Parcial",Legenda!$C$7,0))+IF(G3="otool + Ghidra",Legenda!$C$8,IF(OR(G3="otool",G3="Ghidra",G3="Outro binário"),Legenda!$C$9,0))+MIN(Legenda!$C$11,MAX(0,J3-1)*Legenda!$C$10))),IF(H3="Parcial",MIN(Legenda!$C$13,MIN(10,IF(E3="Sim",Legenda!$C$4,IF(E3="Parcial",Legenda!$C$5,0))+IF(F3="Sim",Legenda!$C$6,IF(F3="Parcial",Legenda!$C$7,0))+IF(G3="otool + Ghidra",Legenda!$C$8,IF(OR(G3="otool",G3="Ghidra",G3="Outro binário"),Legenda!$C$9,0))+MIN(Legenda!$C$11,MAX(0,J3-1)*Legenda!$C$10))),MIN(10,IF(E3="Sim",Legenda!$C$4,IF(E3="Parcial",Legenda!$C$5,0))+IF(F3="Sim",Legenda!$C$6,IF(F3="Parcial",Legenda!$C$7,0))+IF(G3="otool + Ghidra",Legenda!$C$8,IF(OR(G3="otool",G3="Ghidra",G3="Outro binário"),Legenda!$C$9,0))+MIN(Legenda!$C$11,MAX(0,J3-1)*Legenda!$C$10)))),1) | M3: A1-ghidra/Q1-rx-dcl-callbacks.md (Correction no topo); Q-DCL-geometry-table.md §RX | N3: — | O3: Callbacks nunca observados em execução no hardware. | P3: =LEFT(A3,FIND(".",A3&".")-1)
A4: A1-Q1.2 | B4: A1 | C4: Mecanismo de interrupção OHCI | D4: Qual nó DCL faz o OHCI gerar interrupção: DCLPtrTimeStamp (C2/C4) ou bit 's' do CallProc (Q1). | E4: Sim | F4: Não | G4: otool | H4: Não | I4: AppleFWOHCI 5.5.9 asm 0x8f69/0x901d/0xd53f/0xcce7; IOFWDCL.h (IOFireWireFamily source); Q-OHCI-interrupt | J4: =IF(TRIM(I4)="",0,LEN(I4)-LEN(SUBSTITUTE(I4,";",""))+1) | K4: Corrigido 2026-10-14 | L4: =ROUND(IF(H4="Sim",MIN(Legenda!$C$12,MIN(10,IF(E4="Sim",Legenda!$C$4,IF(E4="Parcial",Legenda!$C$5,0))+IF(F4="Sim",Legenda!$C$6,IF(F4="Parcial",Legenda!$C$7,0))+IF(G4="otool + Ghidra",Legenda!$C$8,IF(OR(G4="otool",G4="Ghidra",G4="Outro binário"),Legenda!$C$9,0))+MIN(Legenda!$C$11,MAX(0,J4-1)*Legenda!$C$10))),IF(H4="Parcial",MIN(Legenda!$C$13,MIN(10,IF(E4="Sim",Legenda!$C$4,IF(E4="Parcial",Legenda!$C$5,0))+IF(F4="Sim",Legenda!$C$6,IF(F4="Parcial",Legenda!$C$7,0))+IF(G4="otool + Ghidra",Legenda!$C$8,IF(OR(G4="otool",G4="Ghidra",G4="Outro binário"),Legenda!$C$9,0))+MIN(Legenda!$C$11,MAX(0,J4-1)*Legenda!$C$10))),MIN(10,IF(E4="Sim",Legenda!$C$4,IF(E4="Parcial",Legenda!$C$5,0))+IF(F4="Sim",Legenda!$C$6,IF(F4="Parcial",Legenda!$C$7,0))+IF(G4="otool + Ghidra",Legenda!$C$8,IF(OR(G4="otool",G4="Ghidra",G4="Outro binário"),Legenda!$C$9,0))+MIN(Legenda!$C$11,MAX(0,J4-1)*Legenda!$C$10)))),1) | M4: A1-ghidra/Q-OHCI-interrupt.md; PROVENANCE-RESOLUTIONS.md §R7 | N4: Q1:177,187; C2:242; C4:133-135 | O4: Resolvido 2026-10-14: interrupção vem do callback (CallProc dobrado no DCL de transferência anterior), não do nó de timestamp. Aberto: igualdade com o SL 10.6.8 (não verificada); teste de cadência ao vivo bloqueado (sem experimentos no build PC). | P4: =LEFT(A4,FIND(".",A4&".")-1)
A5: A1-Q1a.1 | B5: A1 | C5: Opcodes DCL (label / SetTagSyncBits) | D5: AddLabel emite 0x9 e AddSetTagSyncBits emite 0xb; os docs trocam os dois. | E5: Sim | F5: Não | G5: otool | H5: Não | I5: asm 0x6bdd/0x6d34 | J5: =IF(TRIM(I5)="",0,LEN(I5)-LEN(SUBSTITUTE(I5,";",""))+1) | K5: Corrigido 2026-10-14 | L5: =ROUND(IF(H5="Sim",MIN(Legenda!$C$12,MIN(10,IF(E5="Sim",Legenda!$C$4,IF(E5="Parcial",Legenda!$C$5,0))+IF(F5="Sim",Legenda!$C$6,IF(F5="Parcial",Legenda!$C$7,0))+IF(G5="otool + Ghidra",Legenda!$C$8,IF(OR(G5="otool",G5="Ghidra",G5="Outro binário"),Legenda!$C$9,0))+MIN(Legenda!$C$11,MAX(0,J5-1)*Legenda!$C$10))),IF(H5="Parcial",MIN(Legenda!$C$13,MIN(10,IF(E5="Sim",Legenda!$C$4,IF(E5="Parcial",Legenda!$C$5,0))+IF(F5="Sim",Legenda!$C$6,IF(F5="Parcial",Legenda!$C$7,0))+IF(G5="otool + Ghidra",Legenda!$C$8,IF(OR(G5="otool",G5="Ghidra",G5="Outro binário"),Legenda!$C$9,0))+MIN(Legenda!$C$11,MAX(0,J5-1)*Legenda!$C$10))),MIN(10,IF(E5="Sim",Legenda!$C$4,IF(E5="Parcial",Legenda!$C$5,0))+IF(F5="Sim",Legenda!$C$6,IF(F5="Parcial",Legenda!$C$7,0))+IF(G5="otool + Ghidra",Legenda!$C$8,IF(OR(G5="otool",G5="Ghidra",G5="Outro binário"),Legenda!$C$9,0))+MIN(Legenda!$C$11,MAX(0,J5-1)*Legenda!$C$10)))),1) | M5: Q1a:85; Q1b:156,158; C4:102-103,143 | N5: Q1a:85; Q1b:156,158; C4:102-103,143 | O5: Conferir com IOFireWireFamilyCommon.h do SDK 10.13 no build PC. [2026-10-14] Bloco Correction inserido nos .md; evidência em docs/system-map/PROVENANCE-RESOLUTIONS.md. | P5: =LEFT(A5,FIND(".",A5&".")-1)
A6: A1-Q1b.1 | B6: A1 | C6: Entrega ao createLocalIsochPort | D6: Chamada clássica de 7 argumentos com ranges NULL; porta local + porta remota (FWRemoteIsochPort) + FWIsochChannel. | E6: Sim | F6: Não | G6: otool + Ghidra | H6: Não | I6: asm 0x255c2; Ghidra (cmp.c); Q-CMP | J6: =IF(TRIM(I6)="",0,LEN(I6)-LEN(SUBSTITUTE(I6,";",""))+1) | K6: Corrigido 2026-10-14 | L6: =ROUND(IF(H6="Sim",MIN(Legenda!$C$12,MIN(10,IF(E6="Sim",Legenda!$C$4,IF(E6="Parcial",Legenda!$C$5,0))+IF(F6="Sim",Legenda!$C$6,IF(F6="Parcial",Legenda!$C$7,0))+IF(G6="otool + Ghidra",Legenda!$C$8,IF(OR(G6="otool",G6="Ghidra",G6="Outro binário"),Legenda!$C$9,0))+MIN(Legenda!$C$11,MAX(0,J6-1)*Legenda!$C$10))),IF(H6="Parcial",MIN(Legenda!$C$13,MIN(10,IF(E6="Sim",Legenda!$C$4,IF(E6="Parcial",Legenda!$C$5,0))+IF(F6="Sim",Legenda!$C$6,IF(F6="Parcial",Legenda!$C$7,0))+IF(G6="otool + Ghidra",Legenda!$C$8,IF(OR(G6="otool",G6="Ghidra",G6="Outro binário"),Legenda!$C$9,0))+MIN(Legenda!$C$11,MAX(0,J6-1)*Legenda!$C$10))),MIN(10,IF(E6="Sim",Legenda!$C$4,IF(E6="Parcial",Legenda!$C$5,0))+IF(F6="Sim",Legenda!$C$6,IF(F6="Parcial",Legenda!$C$7,0))+IF(G6="otool + Ghidra",Legenda!$C$8,IF(OR(G6="otool",G6="Ghidra",G6="Outro binário"),Legenda!$C$9,0))+MIN(Legenda!$C$11,MAX(0,J6-1)*Legenda!$C$10)))),1) | M6: A1-ghidra/Q1b-createlocaliosochport-handoff.md; Q-CMP-connect.md §1 | N6: Q1b:156,158 (opcodes) | O6: [+0x60] é packetSize, não velocidade (corrigido). 'NuDCL inutilizável no kernel 10.13' vem de experimento pré-Ghidra sem captura arquivada. | P6: =LEFT(A6,FIND(".",A6&".")-1)
A7: A1-Q1c.1 | B7: A1 | C7: Caminho de overrun | D7: InputDCLStaticOverrunCallback/InputDCLCallbackOverrun são stubs vazios; CheckDCLOverrun é código morto. | E7: Sim | F7: Não | G7: otool + Ghidra | H7: Não | I7: asm 0x2533a/0x25340; Ghidra | J7: =IF(TRIM(I7)="",0,LEN(I7)-LEN(SUBSTITUTE(I7,";",""))+1) | K7: Consistente | L7: =ROUND(IF(H7="Sim",MIN(Legenda!$C$12,MIN(10,IF(E7="Sim",Legenda!$C$4,IF(E7="Parcial",Legenda!$C$5,0))+IF(F7="Sim",Legenda!$C$6,IF(F7="Parcial",Legenda!$C$7,0))+IF(G7="otool + Ghidra",Legenda!$C$8,IF(OR(G7="otool",G7="Ghidra",G7="Outro binário"),Legenda!$C$9,0))+MIN(Legenda!$C$11,MAX(0,J7-1)*Legenda!$C$10))),IF(H7="Parcial",MIN(Legenda!$C$13,MIN(10,IF(E7="Sim",Legenda!$C$4,IF(E7="Parcial",Legenda!$C$5,0))+IF(F7="Sim",Legenda!$C$6,IF(F7="Parcial",Legenda!$C$7,0))+IF(G7="otool + Ghidra",Legenda!$C$8,IF(OR(G7="otool",G7="Ghidra",G7="Outro binário"),Legenda!$C$9,0))+MIN(Legenda!$C$11,MAX(0,J7-1)*Legenda!$C$10))),MIN(10,IF(E7="Sim",Legenda!$C$4,IF(E7="Parcial",Legenda!$C$5,0))+IF(F7="Sim",Legenda!$C$6,IF(F7="Parcial",Legenda!$C$7,0))+IF(G7="otool + Ghidra",Legenda!$C$8,IF(OR(G7="otool",G7="Ghidra",G7="Outro binário"),Legenda!$C$9,0))+MIN(Legenda!$C$11,MAX(0,J7-1)*Legenda!$C$10)))),1) | M7: A1-ghidra/Q1c-overrun-path.md | N7: — | O7: Verificado no audit (OK #19). | P7: =LEFT(A7,FIND(".",A7&".")-1)
A8: A1-Q-DCL.1 | B8: A1 | C8: Anel DCL TX | D8: 4 bancos × (4 primers de 1 pacote + 1 segmento de P−4 pacotes com callback) + 4 jumps = 20 segmentos; P = ⌊65.536.000/(4·taxa)⌋+2. | E8: Sim | F8: Não | G8: otool + Ghidra | H8: Não | I8: asm 0x25ae4, 0x27102..0x27133; Ghidra | J8: =IF(TRIM(I8)="",0,LEN(I8)-LEN(SUBSTITUTE(I8,";",""))+1) | K8: Corrigido 2026-10-14 | L8: =ROUND(IF(H8="Sim",MIN(Legenda!$C$12,MIN(10,IF(E8="Sim",Legenda!$C$4,IF(E8="Parcial",Legenda!$C$5,0))+IF(F8="Sim",Legenda!$C$6,IF(F8="Parcial",Legenda!$C$7,0))+IF(G8="otool + Ghidra",Legenda!$C$8,IF(OR(G8="otool",G8="Ghidra",G8="Outro binário"),Legenda!$C$9,0))+MIN(Legenda!$C$11,MAX(0,J8-1)*Legenda!$C$10))),IF(H8="Parcial",MIN(Legenda!$C$13,MIN(10,IF(E8="Sim",Legenda!$C$4,IF(E8="Parcial",Legenda!$C$5,0))+IF(F8="Sim",Legenda!$C$6,IF(F8="Parcial",Legenda!$C$7,0))+IF(G8="otool + Ghidra",Legenda!$C$8,IF(OR(G8="otool",G8="Ghidra",G8="Outro binário"),Legenda!$C$9,0))+MIN(Legenda!$C$11,MAX(0,J8-1)*Legenda!$C$10))),MIN(10,IF(E8="Sim",Legenda!$C$4,IF(E8="Parcial",Legenda!$C$5,0))+IF(F8="Sim",Legenda!$C$6,IF(F8="Parcial",Legenda!$C$7,0))+IF(G8="otool + Ghidra",Legenda!$C$8,IF(OR(G8="otool",G8="Ghidra",G8="Outro binário"),Legenda!$C$9,0))+MIN(Legenda!$C$11,MAX(0,J8-1)*Legenda!$C$10)))),1) | M8: A1-ghidra/Q-DCL-geometry-table.md §Ring topology, §TX pkt-count | N8: C1:140 | O8: Verificado (OK #21). C1 ainda diz 64 segmentos TX. | P8: =LEFT(A8,FIND(".",A8&".")-1)
A9: A1-Q-DCL.2 | B9: A1 | C9: Arenas e páginas do pool | D9: Arena TX 0x14000, RX 0x10000; páginas do pool por taxa; possível estouro da arena TX a 32 kHz. | E9: Sim | F9: Não | G9: otool | H9: Parcial | I9: asm 0x25b22, 0xa45c; Q17 | J9: =IF(TRIM(I9)="",0,LEN(I9)-LEN(SUBSTITUTE(I9,";",""))+1) | K9: Corrigido 2026-10-14 | L9: =ROUND(IF(H9="Sim",MIN(Legenda!$C$12,MIN(10,IF(E9="Sim",Legenda!$C$4,IF(E9="Parcial",Legenda!$C$5,0))+IF(F9="Sim",Legenda!$C$6,IF(F9="Parcial",Legenda!$C$7,0))+IF(G9="otool + Ghidra",Legenda!$C$8,IF(OR(G9="otool",G9="Ghidra",G9="Outro binário"),Legenda!$C$9,0))+MIN(Legenda!$C$11,MAX(0,J9-1)*Legenda!$C$10))),IF(H9="Parcial",MIN(Legenda!$C$13,MIN(10,IF(E9="Sim",Legenda!$C$4,IF(E9="Parcial",Legenda!$C$5,0))+IF(F9="Sim",Legenda!$C$6,IF(F9="Parcial",Legenda!$C$7,0))+IF(G9="otool + Ghidra",Legenda!$C$8,IF(OR(G9="otool",G9="Ghidra",G9="Outro binário"),Legenda!$C$9,0))+MIN(Legenda!$C$11,MAX(0,J9-1)*Legenda!$C$10))),MIN(10,IF(E9="Sim",Legenda!$C$4,IF(E9="Parcial",Legenda!$C$5,0))+IF(F9="Sim",Legenda!$C$6,IF(F9="Parcial",Legenda!$C$7,0))+IF(G9="otool + Ghidra",Legenda!$C$8,IF(OR(G9="otool",G9="Ghidra",G9="Outro binário"),Legenda!$C$9,0))+MIN(Legenda!$C$11,MAX(0,J9-1)*Legenda!$C$10)))),1) | M9: A1-ghidra/Q-DCL-geometry-table.md §Pool, §Non-blocking follow-ups | N9: C4:455,464 | O9: Fórmula e máscara física confirmadas no asm (0xa3e6..0xa49e); significado de [+0x18] e crescimento real continuam não verificados. Ver PROVENANCE-RESOLUTIONS.md §R8. | P9: =LEFT(A9,FIND(".",A9&".")-1)
A10: A1-Q2.1 | B10: A1 | C10: Campos do SetupCIP | D10: +0x4a0 = taxa (Hz); +0x4ac = SYTInterval; +0x4a8 = SYTIncrement; +0x4a4 = FDFValue (registradores esi/edx/ecx/r8d). | E10: Sim | F10: Não | G10: otool + Ghidra | H10: Não | I10: asm 0x27102..0x27157; Ghidra | J10: =IF(TRIM(I10)="",0,LEN(I10)-LEN(SUBSTITUTE(I10,";",""))+1) | K10: Corrigido 2026-10-14 | L10: =ROUND(IF(H10="Sim",MIN(Legenda!$C$12,MIN(10,IF(E10="Sim",Legenda!$C$4,IF(E10="Parcial",Legenda!$C$5,0))+IF(F10="Sim",Legenda!$C$6,IF(F10="Parcial",Legenda!$C$7,0))+IF(G10="otool + Ghidra",Legenda!$C$8,IF(OR(G10="otool",G10="Ghidra",G10="Outro binário"),Legenda!$C$9,0))+MIN(Legenda!$C$11,MAX(0,J10-1)*Legenda!$C$10))),IF(H10="Parcial",MIN(Legenda!$C$13,MIN(10,IF(E10="Sim",Legenda!$C$4,IF(E10="Parcial",Legenda!$C$5,0))+IF(F10="Sim",Legenda!$C$6,IF(F10="Parcial",Legenda!$C$7,0))+IF(G10="otool + Ghidra",Legenda!$C$8,IF(OR(G10="otool",G10="Ghidra",G10="Outro binário"),Legenda!$C$9,0))+MIN(Legenda!$C$11,MAX(0,J10-1)*Legenda!$C$10))),MIN(10,IF(E10="Sim",Legenda!$C$4,IF(E10="Parcial",Legenda!$C$5,0))+IF(F10="Sim",Legenda!$C$6,IF(F10="Parcial",Legenda!$C$7,0))+IF(G10="otool + Ghidra",Legenda!$C$8,IF(OR(G10="otool",G10="Ghidra",G10="Outro binário"),Legenda!$C$9,0))+MIN(Legenda!$C$11,MAX(0,J10-1)*Legenda!$C$10)))),1) | M10: A1-ghidra/Q2-setupcip-rate-table.md (tabela de campos); Q15e §3 | N10: — | O10: Ghidra numera os parâmetros com deslocamento de 1; vale o asm. | P10: =LEFT(A10,FIND(".",A10&".")-1)
A11: A1-Q2.2 | B11: A1 | C11: Cabeçalho CIP 1 | D11: (nodeID&0x3f)<<24 | DBS<<16, com DBS = [+0x64]+[+0x68] (quadlets áudio+MIDI), sem máscara. | E11: Sim | F11: Não | G11: otool | H11: Não | I11: asm 0x27173..0x2718e | J11: =IF(TRIM(I11)="",0,LEN(I11)-LEN(SUBSTITUTE(I11,";",""))+1) | K11: Corrigido 2026-10-14 | L11: =ROUND(IF(H11="Sim",MIN(Legenda!$C$12,MIN(10,IF(E11="Sim",Legenda!$C$4,IF(E11="Parcial",Legenda!$C$5,0))+IF(F11="Sim",Legenda!$C$6,IF(F11="Parcial",Legenda!$C$7,0))+IF(G11="otool + Ghidra",Legenda!$C$8,IF(OR(G11="otool",G11="Ghidra",G11="Outro binário"),Legenda!$C$9,0))+MIN(Legenda!$C$11,MAX(0,J11-1)*Legenda!$C$10))),IF(H11="Parcial",MIN(Legenda!$C$13,MIN(10,IF(E11="Sim",Legenda!$C$4,IF(E11="Parcial",Legenda!$C$5,0))+IF(F11="Sim",Legenda!$C$6,IF(F11="Parcial",Legenda!$C$7,0))+IF(G11="otool + Ghidra",Legenda!$C$8,IF(OR(G11="otool",G11="Ghidra",G11="Outro binário"),Legenda!$C$9,0))+MIN(Legenda!$C$11,MAX(0,J11-1)*Legenda!$C$10))),MIN(10,IF(E11="Sim",Legenda!$C$4,IF(E11="Parcial",Legenda!$C$5,0))+IF(F11="Sim",Legenda!$C$6,IF(F11="Parcial",Legenda!$C$7,0))+IF(G11="otool + Ghidra",Legenda!$C$8,IF(OR(G11="otool",G11="Ghidra",G11="Outro binário"),Legenda!$C$9,0))+MIN(Legenda!$C$11,MAX(0,J11-1)*Legenda!$C$10)))),1) | M11: Q2 (linha +0x498); C2:232,331 | N11: C2:232,331 | O11: Q2/C2 ainda dizem (hubID<<24)|((dbc_start<<16)&0x3F0000). [2026-10-14] Bloco Correction inserido nos .md; evidência em docs/system-map/PROVENANCE-RESOLUTIONS.md. | P11: =LEFT(A11,FIND(".",A11&".")-1)
A12: A1-Q2.3 | B12: A1 | C12: Cabeçalho CIP 2 | D12: Template 0x90000000 (EOH/FMT do quadlet CIP 2), não bits de tag/canal do cabeçalho isoch. | E12: Sim | F12: Não | G12: otool | H12: Não | I12: asm 0x27195; IEC 61883-1 | J12: =IF(TRIM(I12)="",0,LEN(I12)-LEN(SUBSTITUTE(I12,";",""))+1) | K12: Corrigido 2026-10-14 | L12: =ROUND(IF(H12="Sim",MIN(Legenda!$C$12,MIN(10,IF(E12="Sim",Legenda!$C$4,IF(E12="Parcial",Legenda!$C$5,0))+IF(F12="Sim",Legenda!$C$6,IF(F12="Parcial",Legenda!$C$7,0))+IF(G12="otool + Ghidra",Legenda!$C$8,IF(OR(G12="otool",G12="Ghidra",G12="Outro binário"),Legenda!$C$9,0))+MIN(Legenda!$C$11,MAX(0,J12-1)*Legenda!$C$10))),IF(H12="Parcial",MIN(Legenda!$C$13,MIN(10,IF(E12="Sim",Legenda!$C$4,IF(E12="Parcial",Legenda!$C$5,0))+IF(F12="Sim",Legenda!$C$6,IF(F12="Parcial",Legenda!$C$7,0))+IF(G12="otool + Ghidra",Legenda!$C$8,IF(OR(G12="otool",G12="Ghidra",G12="Outro binário"),Legenda!$C$9,0))+MIN(Legenda!$C$11,MAX(0,J12-1)*Legenda!$C$10))),MIN(10,IF(E12="Sim",Legenda!$C$4,IF(E12="Parcial",Legenda!$C$5,0))+IF(F12="Sim",Legenda!$C$6,IF(F12="Parcial",Legenda!$C$7,0))+IF(G12="otool + Ghidra",Legenda!$C$8,IF(OR(G12="otool",G12="Ghidra",G12="Outro binário"),Legenda!$C$9,0))+MIN(Legenda!$C$11,MAX(0,J12-1)*Legenda!$C$10)))),1) | M12: Q2; C2:232 | N12: C2:232 | O12: Valor correto; rótulo semântico errado em C2. [2026-10-14] Bloco Correction inserido nos .md; evidência em docs/system-map/PROVENANCE-RESOLUTIONS.md. | P12: =LEFT(A12,FIND(".",A12&".")-1)
A13: A1-Q2.4 | B13: A1 | C13: Acumuladores SYT por FDF | D13: Tabela de salto 0x272d8: FDF 0 {1,2,1,1}; 1/3/5 {199,640,339,441}; 2/4/6 {1,4,1,1}; divisor = (c4−c0)·SYTInterval. | E13: Sim | F13: Não | G13: otool + Ghidra | H13: Não | I13: bytes da fatia 0x272d8; asm 0x2727e..0x272c6; Ghidra | J13: =IF(TRIM(I13)="",0,LEN(I13)-LEN(SUBSTITUTE(I13,";",""))+1) | K13: Corrigido 2026-10-14 | L13: =ROUND(IF(H13="Sim",MIN(Legenda!$C$12,MIN(10,IF(E13="Sim",Legenda!$C$4,IF(E13="Parcial",Legenda!$C$5,0))+IF(F13="Sim",Legenda!$C$6,IF(F13="Parcial",Legenda!$C$7,0))+IF(G13="otool + Ghidra",Legenda!$C$8,IF(OR(G13="otool",G13="Ghidra",G13="Outro binário"),Legenda!$C$9,0))+MIN(Legenda!$C$11,MAX(0,J13-1)*Legenda!$C$10))),IF(H13="Parcial",MIN(Legenda!$C$13,MIN(10,IF(E13="Sim",Legenda!$C$4,IF(E13="Parcial",Legenda!$C$5,0))+IF(F13="Sim",Legenda!$C$6,IF(F13="Parcial",Legenda!$C$7,0))+IF(G13="otool + Ghidra",Legenda!$C$8,IF(OR(G13="otool",G13="Ghidra",G13="Outro binário"),Legenda!$C$9,0))+MIN(Legenda!$C$11,MAX(0,J13-1)*Legenda!$C$10))),MIN(10,IF(E13="Sim",Legenda!$C$4,IF(E13="Parcial",Legenda!$C$5,0))+IF(F13="Sim",Legenda!$C$6,IF(F13="Parcial",Legenda!$C$7,0))+IF(G13="otool + Ghidra",Legenda!$C$8,IF(OR(G13="otool",G13="Ghidra",G13="Outro binário"),Legenda!$C$9,0))+MIN(Legenda!$C$11,MAX(0,J13-1)*Legenda!$C$10)))),1) | M13: Q15e §3 Correction; Q2 (fórmula pós-switch) | N13: — | O13: Verificado (OK #13). | P13: =LEFT(A13,FIND(".",A13&".")-1)
... A196: IN3.1 | B196: IN | C196: 1º teste integrado em hardware (10.13.6 + FW1814) | D196: Áudio de saída limpo, CoreAudio lista o aparelho, painel funciona no aparelho real; correções F1-F10; abertos O1-O4. | E196: Não | F196: Sim | G196: Nenhum | H196: Não | I196: dmesg; ioreg; maprop; system_profiler; panic report 2026-10-16 | J196: =IF(TRIM(I196)="",0,LEN(I196)-LEN(SUBSTITUTE(I196,";",""))+1) | K196: Corrigido 2026-10-16 | L196: =ROUND(IF(H196="Sim",MIN(Legenda!$C$12,MIN(10,IF(E196="Sim",Legenda!$C$4,IF(E196="Parcial",Legenda!$C$5,0))+IF(F196="Sim",Legenda!$C$6,IF(F196="Parcial",Legenda!$C$7,0))+IF(G196="otool + Ghidra",Legenda!$C$8,IF(OR(G196="otool",G196="Ghidra",G196="Outro binário"),Legenda!$C$9,0))+MIN(Legenda!$C$11,MAX(0,J196-1)*Legenda!$C$10))),IF(H196="Parcial",MIN(Legenda!$C$13,MIN(10,IF(E196="Sim",Legenda!$C$4,IF(E196="Parcial",Legenda!$C$5,0))+IF(F196="Sim",Legenda!$C$6,IF(F196="Parcial",Legenda!$C$7,0))+IF(G196="otool + Ghidra",Legenda!$C$8,IF(OR(G196="otool",G196="Ghidra",G196="Outro binário"),Legenda!$C$9,0))+MIN(Legenda!$C$11,MAX(0,J196-1)*Legenda!$C$10))),MIN(10,IF(E196="Sim",Legenda!$C$4,IF(E196="Parcial",Legenda!$C$5,0))+IF(F196="Sim",Legenda!$C$6,IF(F196="Parcial",Legenda!$C$7,0))+IF(G196="otool + Ghidra",Legenda!$C$8,IF(OR(G196="otool",G196="Ghidra",G196="Outro binário"),Legenda!$C$9,0))+MIN(Legenda!$C$11,MAX(0,J196-1)*Legenda!$C$10)))),1) | M196: build-pc-runs/2026-10-16-first-integrated-run.md; R55 | N196: — | O196: O1 troca S/PDIF->ADAT em streaming; verificar F4/F7/F10. | P196: =LEFT(A196,FIND(".",A196&".")-1)

Sheet Build
A1: ID | B1: Pacote | C1: Tarefa | D1: Critério de aceite (teste) | E1: Depende de | F1: Status | G1: Quem | H1: Fonte no plano | I1: Notas
A2: P1 | B2: P | C2: Ler IODCLProgram::generateBufferMap (10.13.6) e definir as restrições que a cadeia DCL do clone precisa cumprir (risco R-1) | D2: Nota em Q-D1-round-two-static-review com cites de asm; lista de restrições para o M-B | E2: — | F2: Concluído | G2: Claude | H2: BUILD-PLAN §2 P1 | I2: [2026-10-14, R36] Seis restrições à cadeia DCL (buffers e slots de timestamp numa só alocação, não-NULL, DMA 32 bits...). Aceitação em tempo de execução só no M-B.
A3: P2 | B3: P | C3: Semântica de IOBufferMemoryDescriptor::inTaskWithPhysicalMask no 10.13.6 vs. parâmetros do TPacketPool (Q17) (risco R-2) | D3: Lista de máscaras/tamanhos permitidos; o clone só usa esses | E3: — | F3: Concluído | G3: Claude | H3: BUILD-PLAN §2 P2 | I3: [2026-10-14, R36] Máscara = bus->getFireWirePhysicalBufferMask() & ~0xFFF; options 0; KMA_LOMEM (não contígua); pools de 0,1–0,7 MB. Sucesso da alocação só no M-B.
A4: P3 | B4: P | C4: Documentar o caminho de firmware no kext: FirmwareUpdate*, Download*, FirmwareHalt, layout de 80 B do MAFirmwareInfo | D4: Nota A1 nova; layout de bytes com cites; comandos BeBoB conferidos com FFADO/snd-bebob | E4: — | F4: Concluído | G4: Claude | H4: BUILD-PLAN §2 P3 | I4: [2026-10-14, R37] Protocolo BeBoB no kext decodificado (registradores C8020000/C8021000/C8021040/C8029000; Reset/DownloadStart/Block/End/Go; blocos de 512 B; despacho por bcd[0x34]); MAFirmwareInfo = info_register_t do FFADO (valor vivo decodificado). Não verificado: CRC extra no DownloadEnd; 10.13.6.
A5: P4 | B5: P | C5: Fechar parâmetros por taxa do Q-CMP-CONNECT (banda, canal, velocidade, packetSize) e os padrões do Q3b (parcial) | D5: Tabelas nas notas A1; nenhum valor usado pelo código ainda rotulado como "guess" | E5: — | F5: Concluído | G5: Claude | H5: BUILD-PLAN §2 P4 | I5: [2026-10-14, R38] Tabela por taxa/modo verificada (capturas 72/74, MABytesPerCycle=976); sequência de init e palavras padrão do mixer. Abertos e rotulados: ordem dos half-words do pan, imagem inicial do 0x98, 2 quadros AV/C. 10.13.6 não executado.
A6: P5 | B6: P | C6: Consolidar os corpos de C1–C6 (texto antigo ainda sob blocos Correction) | D6: Cada C-doc lê como uma versão consistente; flags abertas de C2–C6 reconferidas | E6: — | F6: Concluído | G6: Claude | H6: BUILD-PLAN §2 P5 | I6: [2026-10-14, R35] C1–C6 reescritos como uma versão consistente cada (logs de mudança no fim; originais no git a9cb63c). Itens ainda não verificados seguem rotulados no texto; as 7 flags abertas dependem de hardware.
A7: P6 | B7: P | C7: Especificar o oráculo de verificação: capturas SL/DTrace que dão a referência bit-a-bit (CIP, rótulos AM824, quadros FCP, escritas de propriedade, página de medidores) | D7: Especificação do harness em tests/ e lista de capturas por marco | E7: — | F7: Concluído | G7: Claude | H7: BUILD-PLAN §2 P6 | I7: [2026-10-14, R39] Oráculo especificado em docs/system-map/P6-verification-oracle.md: O1 vetores estáticos, O2 ioreg, O3 replay setProperties, O4 logs macfw/FFADO, O5 capturas novas (precisam de OK), O6 aceite em hardware; layout tests/ e matriz marco→oráculo. Lacunas: bytes assíncronos/isócronos não observáveis no SL.
A8: M-A | B8: M | C8: Esqueleto do kext: Info.plist (Q-INFO), FWMetaNub (6 estados), FWAVCAudioDevice::probe de duas rodadas, free()/dtors NULL-safe, go-away do FW1814, os_log | D8: Carrega de /tmp com a interface desligada e descarrega limpo; com a interface ligada (power-cycle, sem hot-plug) NÃO há pânico em 5 min; rodada 1 rejeitada em silêncio; após MAFirmwareStart a classe do produto instancia; AppleFWAudio não ligado | E8: aprovação do plano; checagem SIP-on | F8: Concluído | G8: Claude + Você presente | H8: BUILD-PLAN §3 | I8: [2026-10-15] Aceite verificado no build PC (10.13.6): carrega/descarrega limpo com interface desligada; com interface ligada sem panic (~6,5 min), round 1 rejeitado, MAFirmwareStart -> FW1814Device; AppleFWAudio ausente (a sub-unidade AV/C nem aparece: a personalidade GoAway não foi exercitada). Instalado em /Library/Extensions e sobrevive a reboot.
A9: M-FW | B9: M | C9: Caminho de firmware no kext + propriedades MAFirmwareInfo/Start/Halt/UpgradeImage | D9: Transição bootloader→runtime só por propriedades; atualização testada por último, com você presente | E9: M-A; H.1 (P3 concluído) | F9: Concluído | G9: Claude + Você presente | H9: BUILD-PLAN §3 | I9: [2026-10-15] Escopo reduzido por decisão do usuário (2026-10-15): SEM gravação de flash. Mantidos MAFirmwareInfo, MAFirmwareStart (runtime e bootloader/Go) e o temporizador de re-registro 2500 ms; removidos Halt/UpgradeImage/Download*. Ciclo Halt->bootloader->Go verificado em hardware antes do corte (janela do bootloader ~3 s; o dispositivo também reinicia sozinho).
A10: M-B | B10: M | C10: TPacketPool, construtores DCL (TX 20 seg / RX 64×4), callbacks via CallProc, TX AM824 contínuo | D10: createLocalIsochPort devolve não-NULL; geometria dos pacotes TX igual à captura 74 (424 B, DBS 13) | E10: P1; P2; M-A | F10: Concluído | G10: Claude | H10: BUILD-PLAN §3 | I10: [2026-10-15] Parte 1 escrita (TPacketPool, FWDCLBuilder, programas TX 20 seg / RX 64x4, createLocalIsochPort, atribuição do pool à cadeia); compila e passa kextutil -t -n. Falta: callbacks TX/RX com preparação de pacotes (OutputDCLCallback @0x26269), cabeçalhos CIP/SYT/DBC. Achado: no TX, SetTagSyncBits(1,0) vai no PRIMEIRO primer de cada banco (asm 0x25b50), não no último segmento. [2026-10-15] Fechamento 2026-10-15: decodificação completa em A1-ghidra/Q-MB-dcl-callbacks.md (R41). Escrito: FWSharedSync, FWCip, TPacketPool (+índice FWTPacketIndex), FWDCLBuilder (+ModifyJumpLabel), FWDCLProgram.h; FALTA portar FWDCLProgram.cpp (a árvore do kext NÃO compila até lá) e remover o gancho de bring-up do FW1814Device. Nunca carregado em hardware (regra do avião). Correções a docs antigos: ver Q-MB §7. [2026-10-15] Parte 2 escrita: FWDCLProgram.cpp portado (callbacks TX/RX, AdjustOutputDCL, SetPacketSize com offset-por-1, Start/Stop); hook de bring-up removido. Build PC: make limpo + kextutil -t -n OK, nada carregado. Aceite (porta não-NULL, geometria 424 B) só no teste integrado. [2026-10-16 1º teste integrado] Programas DCL TX/RX montados e rodando no hardware; áudio de saída limpo. [2026-10-21] Funciona no hardware (0.1.0 e 0.2.x, uso diário do usuário até 2026-10-21).
A11: M-C | B11: M | C11: CMP (canal IRM, travas oPCR/iPCR), formato de stream AV/C e a ordem de partida da referência | D11: Dispositivo trava; isoch nos dois sentidos; estável 5 min a 48 kHz/512 | E11: P4; M-B | F11: Concluído | G11: Claude + Você presente | H11: BUILD-PLAN §3 | I11: [2026-10-15] G1 aprovado pelo usuário; construção segue o fluxograma docs/flowchart driver.drawio. [2026-10-15] Esqueleto: FWIsochChannel, FWCMP, FWAvc, FWStreamControl, FWBusReset (.h/.cpp com cabeçalho do plano). ANTES de escrever: Q-START (quem chama Connect/channel->start/ResetPort; vt[0x120] do ConnectAudioMIDIChannels é Connect, não Start). [2026-10-15] Q-START fechado (R43): Connect e Start separados; RX Start antes de TX Start. [2026-10-15] Código escrito (R44/Q-MC): FWAvc, FWCMP, FWIsochChannel, FWStreamControl, Connect/Disconnect/ResetPort, AllocateConnectionManager. Build PC limpo + kextutil -t -n OK; nada carregado. Falta: ligar BusReset ao evento do nub, instanciar pelo engine (M-D/M-J). Aceite só no teste integrado. [2026-10-16 1º teste integrado] CMP/AV-C e início dos canais funcionam (áudio em out 1/2). Troca S/PDIF->ADAT com áudio tocando trava o stream (O1). [2026-10-17] [2026-10-17, R56/Q-AVC-unit-and-O1] FWAvcUnit reconstruído como subclasse de IOFireWireAVCUnit (init/attach/start como asm 0x23c72; fCommand/avcLock/cmdLock como 0x1594; fila async 0x17fc/0x16c8) - antes nenhuma resposta FCP chegava e todo comando AV/C estourava 1,27 s. Agora síncrono 22 ms ACCEPTED, bring-up 23 s -> 13 s (5-14 s), roteamento SW return 1/2 -> out 3/4 funciona (usuário). Falta: estabilidade 5 min, bus reset/sleep-wake da unit. [2026-10-21] Funciona no hardware (0.1.0 e 0.2.x, uso diário do usuário até 2026-10-21).
