Workbook

Sheet Painel
A1: Painel — fase Audiophile (openaudio-mafw-bebob, macOS 10.13.6)
A2: 2026-10-21
A4: Visão geral
A5: Itens rastreados | B5: =COUNTA(Itens!$A$2:$A$500) | D5: ONDE ESTAMOS
A6: Itens fechados | B6: =COUNTIF(Itens!$K$2:$K$500,"Consistente")+COUNTIF(Itens!$K$2:$K$500,"Corrigido*") | D6: Painel: modo barra de menus (AP-5.5) e medidor grande (AP-5.6) escritos, testes do painel passam; instalador 0.2.0 construído e conferido estaticamente (R118). Duas unidades juntas no iMac feitas (R117).
A7: % itens fechados | B7: =IFERROR(B6/B5,0)
A8: Itens abertos | B8: =COUNTIF(Itens!$K$2:$K$500,"Aberto / não resolvido")
A9: Correções pendentes | B9: =COUNTIF(Itens!$K$2:$K$500,"Correção pendente (audit)")
A10: Flags abertas | B10: =COUNTIF(Flags_auditoria!$H$2:$H$500,"Aberto") | D10: PARA ONDE VAMOS
A11: Confiança média (0–10) | B11: =IFERROR(AVERAGE(Itens!$L$2:$L$500),0) | D11: Próximo: você instala o 0.2.0 no MacBook Air (AP-8.2) e testa o menu de status e o medidor grande; depois README/NOTICE para dois modelos (AP-8.3, rascunho no repositório privado) e o release (AP-8.4, você).
A12: Tarefas concluídas | B12: =COUNTIF(Build!$F$2:$F$500,"Concluído")&" / "&(COUNTA(Build!$A$2:$A$500)-COUNTIF(Build!$F$2:$F$500,"Cancelado*"))
A13: Aguardando você | B13: =COUNTIF(Build!$F$2:$F$500,"Aguarda o usuário")
A14: Progresso do build | B14: =IFERROR(COUNTIF(Build!$F$2:$F$500,"Concluído")/(COUNTA(Build!$A$2:$A$500)-COUNTIF(Build!$F$2:$F$500,"Cancelado*")),0)
A17: Roadmap por fase (aba Build)
A18: Fase | B18: Conteúdo | C18: Estado | D18: % pronto | E18: Tarefas | F18: Concluídas | G18: Aguardam você | H18: Próximo passo | I18: Sessões (plano §8)
A19: Decisão | B19: Decisões Q1–Q5 do plano §9 | C19: =IF(COUNTIFS(Build!$B$2:$B$500,A19,Build!$F$2:$F$500,"Concluído")=(COUNTIF(Build!$B$2:$B$500,A19)-COUNTIFS(Build!$B$2:$B$500,A19,Build!$F$2:$F$500,"Cancelado*")),"Concluído",IF(COUNTIFS(Build!$B$2:$B$500,A19,Build!$F$2:$F$500,"Em andamento")+COUNTIFS(Build!$B$2:$B$500,A19,Build!$F$2:$F$500,"Concluído")>0,"Em andamento",IF(COUNTIFS(Build!$B$2:$B$500,A19,Build!$F$2:$F$500,"Aguarda o usuário")>0,"Aguarda você","Não iniciado"))) | D19: =IFERROR(COUNTIFS(Build!$B$2:$B$500,A19,Build!$F$2:$F$500,"Concluído")/(COUNTIF(Build!$B$2:$B$500,A19)-COUNTIFS(Build!$B$2:$B$500,A19,Build!$F$2:$F$500,"Cancelado*")),0) | E19: =(COUNTIF(Build!$B$2:$B$500,A19)-COUNTIFS(Build!$B$2:$B$500,A19,Build!$F$2:$F$500,"Cancelado*")) | F19: =COUNTIFS(Build!$B$2:$B$500,A19,Build!$F$2:$F$500,"Concluído") | G19: =COUNTIFS(Build!$B$2:$B$500,A19,Build!$F$2:$F$500,"Aguarda o usuário") | H19: Responder antes da fase 1 | I19: —
A20: 0 | B20: Pesquisa estática + capturas no rig SL | C20: =IF(COUNTIFS(Build!$B$2:$B$500,A20,Build!$F$2:$F$500,"Concluído")=(COUNTIF(Build!$B$2:$B$500,A20)-COUNTIFS(Build!$B$2:$B$500,A20,Build!$F$2:$F$500,"Cancelado*")),"Concluído",IF(COUNTIFS(Build!$B$2:$B$500,A20,Build!$F$2:$F$500,"Em andamento")+COUNTIFS(Build!$B$2:$B$500,A20,Build!$F$2:$F$500,"Concluído")>0,"Em andamento",IF(COUNTIFS(Build!$B$2:$B$500,A20,Build!$F$2:$F$500,"Aguarda o usuário")>0,"Aguarda você","Não iniciado"))) | D20: =IFERROR(COUNTIFS(Build!$B$2:$B$500,A20,Build!$F$2:$F$500,"Concluído")/(COUNTIF(Build!$B$2:$B$500,A20)-COUNTIFS(Build!$B$2:$B$500,A20,Build!$F$2:$F$500,"Cancelado*")),0) | E20: =(COUNTIF(Build!$B$2:$B$500,A20)-COUNTIFS(Build!$B$2:$B$500,A20,Build!$F$2:$F$500,"Cancelado*")) | F20: =COUNTIFS(Build!$B$2:$B$500,A20,Build!$F$2:$F$500,"Concluído") | G20: =COUNTIFS(Build!$B$2:$B$500,A20,Build!$F$2:$F$500,"Aguarda o usuário") | H20: Fechar AP-0.2, depois AP-0.3 | I20: 2-3 + 1
A21: 1 | B21: Criar a árvore openaudio-mafw-bebob/ (cópia do 1814) | C21: =IF(COUNTIFS(Build!$B$2:$B$500,A21,Build!$F$2:$F$500,"Concluído")=(COUNTIF(Build!$B$2:$B$500,A21)-COUNTIFS(Build!$B$2:$B$500,A21,Build!$F$2:$F$500,"Cancelado*")),"Concluído",IF(COUNTIFS(Build!$B$2:$B$500,A21,Build!$F$2:$F$500,"Em andamento")+COUNTIFS(Build!$B$2:$B$500,A21,Build!$F$2:$F$500,"Concluído")>0,"Em andamento",IF(COUNTIFS(Build!$B$2:$B$500,A21,Build!$F$2:$F$500,"Aguarda o usuário")>0,"Aguarda você","Não iniciado"))) | D21: =IFERROR(COUNTIFS(Build!$B$2:$B$500,A21,Build!$F$2:$F$500,"Concluído")/(COUNTIF(Build!$B$2:$B$500,A21)-COUNTIFS(Build!$B$2:$B$500,A21,Build!$F$2:$F$500,"Cancelado*")),0) | E21: =(COUNTIF(Build!$B$2:$B$500,A21)-COUNTIFS(Build!$B$2:$B$500,A21,Build!$F$2:$F$500,"Cancelado*")) | F21: =COUNTIFS(Build!$B$2:$B$500,A21,Build!$F$2:$F$500,"Concluído") | G21: =COUNTIFS(Build!$B$2:$B$500,A21,Build!$F$2:$F$500,"Aguarda o usuário") | H21: Depende de Q1/Q2 | I21: 1
A22: 2 | B22: Núcleo agnóstico de modelo + base Rev2 | C22: =IF(COUNTIFS(Build!$B$2:$B$500,A22,Build!$F$2:$F$500,"Concluído")=(COUNTIF(Build!$B$2:$B$500,A22)-COUNTIFS(Build!$B$2:$B$500,A22,Build!$F$2:$F$500,"Cancelado*")),"Concluído",IF(COUNTIFS(Build!$B$2:$B$500,A22,Build!$F$2:$F$500,"Em andamento")+COUNTIFS(Build!$B$2:$B$500,A22,Build!$F$2:$F$500,"Concluído")>0,"Em andamento",IF(COUNTIFS(Build!$B$2:$B$500,A22,Build!$F$2:$F$500,"Aguarda o usuário")>0,"Aguarda você","Não iniciado"))) | D22: =IFERROR(COUNTIFS(Build!$B$2:$B$500,A22,Build!$F$2:$F$500,"Concluído")/(COUNTIF(Build!$B$2:$B$500,A22)-COUNTIFS(Build!$B$2:$B$500,A22,Build!$F$2:$F$500,"Cancelado*")),0) | E22: =(COUNTIF(Build!$B$2:$B$500,A22)-COUNTIFS(Build!$B$2:$B$500,A22,Build!$F$2:$F$500,"Cancelado*")) | F22: =COUNTIFS(Build!$B$2:$B$500,A22,Build!$F$2:$F$500,"Concluído") | G22: =COUNTIFS(Build!$B$2:$B$500,A22,Build!$F$2:$F$500,"Aguarda o usuário") | H22: — | I22: 2-3
A23: 3 | B23: Kext do Audiophile | C23: =IF(COUNTIFS(Build!$B$2:$B$500,A23,Build!$F$2:$F$500,"Concluído")=(COUNTIF(Build!$B$2:$B$500,A23)-COUNTIFS(Build!$B$2:$B$500,A23,Build!$F$2:$F$500,"Cancelado*")),"Concluído",IF(COUNTIFS(Build!$B$2:$B$500,A23,Build!$F$2:$F$500,"Em andamento")+COUNTIFS(Build!$B$2:$B$500,A23,Build!$F$2:$F$500,"Concluído")>0,"Em andamento",IF(COUNTIFS(Build!$B$2:$B$500,A23,Build!$F$2:$F$500,"Aguarda o usuário")>0,"Aguarda você","Não iniciado"))) | D23: =IFERROR(COUNTIFS(Build!$B$2:$B$500,A23,Build!$F$2:$F$500,"Concluído")/(COUNTIF(Build!$B$2:$B$500,A23)-COUNTIFS(Build!$B$2:$B$500,A23,Build!$F$2:$F$500,"Cancelado*")),0) | E23: =(COUNTIF(Build!$B$2:$B$500,A23)-COUNTIFS(Build!$B$2:$B$500,A23,Build!$F$2:$F$500,"Cancelado*")) | F23: =COUNTIFS(Build!$B$2:$B$500,A23,Build!$F$2:$F$500,"Concluído") | G23: =COUNTIFS(Build!$B$2:$B$500,A23,Build!$F$2:$F$500,"Aguarda o usuário") | H23: — | I23: 3-5
A24: 4 | B24: Helper (.bcd por offsets, tabela de produtos) | C24: =IF(COUNTIFS(Build!$B$2:$B$500,A24,Build!$F$2:$F$500,"Concluído")=(COUNTIF(Build!$B$2:$B$500,A24)-COUNTIFS(Build!$B$2:$B$500,A24,Build!$F$2:$F$500,"Cancelado*")),"Concluído",IF(COUNTIFS(Build!$B$2:$B$500,A24,Build!$F$2:$F$500,"Em andamento")+COUNTIFS(Build!$B$2:$B$500,A24,Build!$F$2:$F$500,"Concluído")>0,"Em andamento",IF(COUNTIFS(Build!$B$2:$B$500,A24,Build!$F$2:$F$500,"Aguarda o usuário")>0,"Aguarda você","Não iniciado"))) | D24: =IFERROR(COUNTIFS(Build!$B$2:$B$500,A24,Build!$F$2:$F$500,"Concluído")/(COUNTIF(Build!$B$2:$B$500,A24)-COUNTIFS(Build!$B$2:$B$500,A24,Build!$F$2:$F$500,"Cancelado*")),0) | E24: =(COUNTIF(Build!$B$2:$B$500,A24)-COUNTIFS(Build!$B$2:$B$500,A24,Build!$F$2:$F$500,"Cancelado*")) | F24: =COUNTIFS(Build!$B$2:$B$500,A24,Build!$F$2:$F$500,"Concluído") | G24: =COUNTIFS(Build!$B$2:$B$500,A24,Build!$F$2:$F$500,"Aguarda o usuário") | H24: — | I24: 1
A25: 5 | B25: Painel por descritores + telas do Audiophile | C25: =IF(COUNTIFS(Build!$B$2:$B$500,A25,Build!$F$2:$F$500,"Concluído")=(COUNTIF(Build!$B$2:$B$500,A25)-COUNTIFS(Build!$B$2:$B$500,A25,Build!$F$2:$F$500,"Cancelado*")),"Concluído",IF(COUNTIFS(Build!$B$2:$B$500,A25,Build!$F$2:$F$500,"Em andamento")+COUNTIFS(Build!$B$2:$B$500,A25,Build!$F$2:$F$500,"Concluído")>0,"Em andamento",IF(COUNTIFS(Build!$B$2:$B$500,A25,Build!$F$2:$F$500,"Aguarda o usuário")>0,"Aguarda você","Não iniciado"))) | D25: =IFERROR(COUNTIFS(Build!$B$2:$B$500,A25,Build!$F$2:$F$500,"Concluído")/(COUNTIF(Build!$B$2:$B$500,A25)-COUNTIFS(Build!$B$2:$B$500,A25,Build!$F$2:$F$500,"Cancelado*")),0) | E25: =(COUNTIF(Build!$B$2:$B$500,A25)-COUNTIFS(Build!$B$2:$B$500,A25,Build!$F$2:$F$500,"Cancelado*")) | F25: =COUNTIFS(Build!$B$2:$B$500,A25,Build!$F$2:$F$500,"Concluído") | G25: =COUNTIFS(Build!$B$2:$B$500,A25,Build!$F$2:$F$500,"Aguarda o usuário") | H25: — | I25: 3-4
A26: 6 | B26: MIDI | C26: =IF(COUNTIFS(Build!$B$2:$B$500,A26,Build!$F$2:$F$500,"Concluído")=(COUNTIF(Build!$B$2:$B$500,A26)-COUNTIFS(Build!$B$2:$B$500,A26,Build!$F$2:$F$500,"Cancelado*")),"Concluído",IF(COUNTIFS(Build!$B$2:$B$500,A26,Build!$F$2:$F$500,"Em andamento")+COUNTIFS(Build!$B$2:$B$500,A26,Build!$F$2:$F$500,"Concluído")>0,"Em andamento",IF(COUNTIFS(Build!$B$2:$B$500,A26,Build!$F$2:$F$500,"Aguarda o usuário")>0,"Aguarda você","Não iniciado"))) | D26: =IFERROR(COUNTIFS(Build!$B$2:$B$500,A26,Build!$F$2:$F$500,"Concluído")/(COUNTIF(Build!$B$2:$B$500,A26)-COUNTIFS(Build!$B$2:$B$500,A26,Build!$F$2:$F$500,"Cancelado*")),0) | E26: =(COUNTIF(Build!$B$2:$B$500,A26)-COUNTIFS(Build!$B$2:$B$500,A26,Build!$F$2:$F$500,"Cancelado*")) | F26: =COUNTIFS(Build!$B$2:$B$500,A26,Build!$F$2:$F$500,"Concluído") | G26: =COUNTIFS(Build!$B$2:$B$500,A26,Build!$F$2:$F$500,"Aguarda o usuário") | H26: — | I26: 0.5
A27: 7 | B27: Escada de hardware (um teste integrado) | C27: =IF(COUNTIFS(Build!$B$2:$B$500,A27,Build!$F$2:$F$500,"Concluído")=(COUNTIF(Build!$B$2:$B$500,A27)-COUNTIFS(Build!$B$2:$B$500,A27,Build!$F$2:$F$500,"Cancelado*")),"Concluído",IF(COUNTIFS(Build!$B$2:$B$500,A27,Build!$F$2:$F$500,"Em andamento")+COUNTIFS(Build!$B$2:$B$500,A27,Build!$F$2:$F$500,"Concluído")>0,"Em andamento",IF(COUNTIFS(Build!$B$2:$B$500,A27,Build!$F$2:$F$500,"Aguarda o usuário")>0,"Aguarda você","Não iniciado"))) | D27: =IFERROR(COUNTIFS(Build!$B$2:$B$500,A27,Build!$F$2:$F$500,"Concluído")/(COUNTIF(Build!$B$2:$B$500,A27)-COUNTIFS(Build!$B$2:$B$500,A27,Build!$F$2:$F$500,"Cancelado*")),0) | E27: =(COUNTIF(Build!$B$2:$B$500,A27)-COUNTIFS(Build!$B$2:$B$500,A27,Build!$F$2:$F$500,"Cancelado*")) | F27: =COUNTIFS(Build!$B$2:$B$500,A27,Build!$F$2:$F$500,"Concluído") | G27: =COUNTIFS(Build!$B$2:$B$500,A27,Build!$F$2:$F$500,"Aguarda o usuário") | H27: Regra do avião | I27: 3-4
A28: 8 | B28: Regressão do 1814, instalador, docs | C28: =IF(COUNTIFS(Build!$B$2:$B$500,A28,Build!$F$2:$F$500,"Concluído")=(COUNTIF(Build!$B$2:$B$500,A28)-COUNTIFS(Build!$B$2:$B$500,A28,Build!$F$2:$F$500,"Cancelado*")),"Concluído",IF(COUNTIFS(Build!$B$2:$B$500,A28,Build!$F$2:$F$500,"Em andamento")+COUNTIFS(Build!$B$2:$B$500,A28,Build!$F$2:$F$500,"Concluído")>0,"Em andamento",IF(COUNTIFS(Build!$B$2:$B$500,A28,Build!$F$2:$F$500,"Aguarda o usuário")>0,"Aguarda você","Não iniciado"))) | D28: =IFERROR(COUNTIFS(Build!$B$2:$B$500,A28,Build!$F$2:$F$500,"Concluído")/(COUNTIF(Build!$B$2:$B$500,A28)-COUNTIFS(Build!$B$2:$B$500,A28,Build!$F$2:$F$500,"Cancelado*")),0) | E28: =(COUNTIF(Build!$B$2:$B$500,A28)-COUNTIFS(Build!$B$2:$B$500,A28,Build!$F$2:$F$500,"Cancelado*")) | F28: =COUNTIFS(Build!$B$2:$B$500,A28,Build!$F$2:$F$500,"Concluído") | G28: =COUNTIFS(Build!$B$2:$B$500,A28,Build!$F$2:$F$500,"Aguarda o usuário") | H28: — | I28: 2-3

Sheet Resumo
A1: Matriz de proveniência — fase Audiophile (openaudio-mafw-bebob)
A2: Tudo nesta aba é fórmula sobre as abas Itens e Flags_auditoria.
A4: Parte | B4: Itens | C4: Confiança média | D4: Byte-level = Sim | E4: Hardware live = Sim | F4: Especulativo = Sim | G4: Correção pendente | H4: Aberto | I4: Confiança ≤ 3 | J4: Confiança ≥ 7
A5: AP-0.1 | B5: =COUNTIF(Itens!$B$2:$B$500,A5) | C5: =IFERROR(AVERAGEIF(Itens!$B$2:$B$500,A5,Itens!$L$2:$L$500),0) | D5: =COUNTIFS(Itens!$B$2:$B$500,A5,Itens!$E$2:$E$500,"Sim") | E5: =COUNTIFS(Itens!$B$2:$B$500,A5,Itens!$F$2:$F$500,"Sim") | F5: =COUNTIFS(Itens!$B$2:$B$500,A5,Itens!$H$2:$H$500,"Sim") | G5: =COUNTIFS(Itens!$B$2:$B$500,A5,Itens!$K$2:$K$500,"Correção pendente (audit)") | H5: =COUNTIFS(Itens!$B$2:$B$500,A5,Itens!$K$2:$K$500,"Aberto / não resolvido") | I5: =COUNTIFS(Itens!$B$2:$B$500,A5,Itens!$L$2:$L$500,"<=3") | J5: =COUNTIFS(Itens!$B$2:$B$500,A5,Itens!$L$2:$L$500,">=7")
A6: AP-0.2 | B6: =COUNTIF(Itens!$B$2:$B$500,A6) | C6: =IFERROR(AVERAGEIF(Itens!$B$2:$B$500,A6,Itens!$L$2:$L$500),0) | D6: =COUNTIFS(Itens!$B$2:$B$500,A6,Itens!$E$2:$E$500,"Sim") | E6: =COUNTIFS(Itens!$B$2:$B$500,A6,Itens!$F$2:$F$500,"Sim") | F6: =COUNTIFS(Itens!$B$2:$B$500,A6,Itens!$H$2:$H$500,"Sim") | G6: =COUNTIFS(Itens!$B$2:$B$500,A6,Itens!$K$2:$K$500,"Correção pendente (audit)") | H6: =COUNTIFS(Itens!$B$2:$B$500,A6,Itens!$K$2:$K$500,"Aberto / não resolvido") | I6: =COUNTIFS(Itens!$B$2:$B$500,A6,Itens!$L$2:$L$500,"<=3") | J6: =COUNTIFS(Itens!$B$2:$B$500,A6,Itens!$L$2:$L$500,">=7")
A7: AP-0.3 | B7: =COUNTIF(Itens!$B$2:$B$500,A7) | C7: =IFERROR(AVERAGEIF(Itens!$B$2:$B$500,A7,Itens!$L$2:$L$500),0) | D7: =COUNTIFS(Itens!$B$2:$B$500,A7,Itens!$E$2:$E$500,"Sim") | E7: =COUNTIFS(Itens!$B$2:$B$500,A7,Itens!$F$2:$F$500,"Sim") | F7: =COUNTIFS(Itens!$B$2:$B$500,A7,Itens!$H$2:$H$500,"Sim") | G7: =COUNTIFS(Itens!$B$2:$B$500,A7,Itens!$K$2:$K$500,"Correção pendente (audit)") | H7: =COUNTIFS(Itens!$B$2:$B$500,A7,Itens!$K$2:$K$500,"Aberto / não resolvido") | I7: =COUNTIFS(Itens!$B$2:$B$500,A7,Itens!$L$2:$L$500,"<=3") | J7: =COUNTIFS(Itens!$B$2:$B$500,A7,Itens!$L$2:$L$500,">=7")
A8: AP-0.4 | B8: =COUNTIF(Itens!$B$2:$B$500,A8) | C8: =IFERROR(AVERAGEIF(Itens!$B$2:$B$500,A8,Itens!$L$2:$L$500),0) | D8: =COUNTIFS(Itens!$B$2:$B$500,A8,Itens!$E$2:$E$500,"Sim") | E8: =COUNTIFS(Itens!$B$2:$B$500,A8,Itens!$F$2:$F$500,"Sim") | F8: =COUNTIFS(Itens!$B$2:$B$500,A8,Itens!$H$2:$H$500,"Sim") | G8: =COUNTIFS(Itens!$B$2:$B$500,A8,Itens!$K$2:$K$500,"Correção pendente (audit)") | H8: =COUNTIFS(Itens!$B$2:$B$500,A8,Itens!$K$2:$K$500,"Aberto / não resolvido") | I8: =COUNTIFS(Itens!$B$2:$B$500,A8,Itens!$L$2:$L$500,"<=3") | J8: =COUNTIFS(Itens!$B$2:$B$500,A8,Itens!$L$2:$L$500,">=7")
A9: AP-0.5 | B9: =COUNTIF(Itens!$B$2:$B$500,A9) | C9: =IFERROR(AVERAGEIF(Itens!$B$2:$B$500,A9,Itens!$L$2:$L$500),0) | D9: =COUNTIFS(Itens!$B$2:$B$500,A9,Itens!$E$2:$E$500,"Sim") | E9: =COUNTIFS(Itens!$B$2:$B$500,A9,Itens!$F$2:$F$500,"Sim") | F9: =COUNTIFS(Itens!$B$2:$B$500,A9,Itens!$H$2:$H$500,"Sim") | G9: =COUNTIFS(Itens!$B$2:$B$500,A9,Itens!$K$2:$K$500,"Correção pendente (audit)") | H9: =COUNTIFS(Itens!$B$2:$B$500,A9,Itens!$K$2:$K$500,"Aberto / não resolvido") | I9: =COUNTIFS(Itens!$B$2:$B$500,A9,Itens!$L$2:$L$500,"<=3") | J9: =COUNTIFS(Itens!$B$2:$B$500,A9,Itens!$L$2:$L$500,">=7")
A10: AP-0.6 | B10: =COUNTIF(Itens!$B$2:$B$500,A10) | C10: =IFERROR(AVERAGEIF(Itens!$B$2:$B$500,A10,Itens!$L$2:$L$500),0) | D10: =COUNTIFS(Itens!$B$2:$B$500,A10,Itens!$E$2:$E$500,"Sim") | E10: =COUNTIFS(Itens!$B$2:$B$500,A10,Itens!$F$2:$F$500,"Sim") | F10: =COUNTIFS(Itens!$B$2:$B$500,A10,Itens!$H$2:$H$500,"Sim") | G10: =COUNTIFS(Itens!$B$2:$B$500,A10,Itens!$K$2:$K$500,"Correção pendente (audit)") | H10: =COUNTIFS(Itens!$B$2:$B$500,A10,Itens!$K$2:$K$500,"Aberto / não resolvido") | I10: =COUNTIFS(Itens!$B$2:$B$500,A10,Itens!$L$2:$L$500,"<=3") | J10: =COUNTIFS(Itens!$B$2:$B$500,A10,Itens!$L$2:$L$500,">=7")
A11: AP-0.7 | B11: =COUNTIF(Itens!$B$2:$B$500,A11) | C11: =IFERROR(AVERAGEIF(Itens!$B$2:$B$500,A11,Itens!$L$2:$L$500),0) | D11: =COUNTIFS(Itens!$B$2:$B$500,A11,Itens!$E$2:$E$500,"Sim") | E11: =COUNTIFS(Itens!$B$2:$B$500,A11,Itens!$F$2:$F$500,"Sim") | F11: =COUNTIFS(Itens!$B$2:$B$500,A11,Itens!$H$2:$H$500,"Sim") | G11: =COUNTIFS(Itens!$B$2:$B$500,A11,Itens!$K$2:$K$500,"Correção pendente (audit)") | H11: =COUNTIFS(Itens!$B$2:$B$500,A11,Itens!$K$2:$K$500,"Aberto / não resolvido") | I11: =COUNTIFS(Itens!$B$2:$B$500,A11,Itens!$L$2:$L$500,"<=3") | J11: =COUNTIFS(Itens!$B$2:$B$500,A11,Itens!$L$2:$L$500,">=7")
A12: AP-0.9 | B12: =COUNTIF(Itens!$B$2:$B$500,A12) | C12: =IFERROR(AVERAGEIF(Itens!$B$2:$B$500,A12,Itens!$L$2:$L$500),0) | D12: =COUNTIFS(Itens!$B$2:$B$500,A12,Itens!$E$2:$E$500,"Sim") | E12: =COUNTIFS(Itens!$B$2:$B$500,A12,Itens!$F$2:$F$500,"Sim") | F12: =COUNTIFS(Itens!$B$2:$B$500,A12,Itens!$H$2:$H$500,"Sim") | G12: =COUNTIFS(Itens!$B$2:$B$500,A12,Itens!$K$2:$K$500,"Correção pendente (audit)") | H12: =COUNTIFS(Itens!$B$2:$B$500,A12,Itens!$K$2:$K$500,"Aberto / não resolvido") | I12: =COUNTIFS(Itens!$B$2:$B$500,A12,Itens!$L$2:$L$500,"<=3") | J12: =COUNTIFS(Itens!$B$2:$B$500,A12,Itens!$L$2:$L$500,">=7")
A13: Total | B13: =SUM(B5:B12) | C13: =AVERAGE(Itens!$L$2:$L$500) | D13: =SUM(D5:D12) | E13: =SUM(E5:E12) | F13: =SUM(F5:F12) | G13: =SUM(G5:G12) | H13: =SUM(H5:H12) | I13: =SUM(I5:I12) | J13: =SUM(J5:J12)
A15: Flags do audit por severidade
A16: Severidade | B16: Total | C16: Abertas | D16: Resolvidas
A17: alta | B17: =COUNTIF(Flags_auditoria!$F$2:$F$500,A17) | C17: =COUNTIFS(Flags_auditoria!$F$2:$F$500,A17,Flags_auditoria!$H$2:$H$500,"Aberto") | D17: =COUNTIFS(Flags_auditoria!$F$2:$F$500,A17,Flags_auditoria!$H$2:$H$500,"Resolvido")
A18: média | B18: =COUNTIF(Flags_auditoria!$F$2:$F$500,A18) | C18: =COUNTIFS(Flags_auditoria!$F$2:$F$500,A18,Flags_auditoria!$H$2:$H$500,"Aberto") | D18: =COUNTIFS(Flags_auditoria!$F$2:$F$500,A18,Flags_auditoria!$H$2:$H$500,"Resolvido")
A19: baixa | B19: =COUNTIF(Flags_auditoria!$F$2:$F$500,A19) | C19: =COUNTIFS(Flags_auditoria!$F$2:$F$500,A19,Flags_auditoria!$H$2:$H$500,"Aberto") | D19: =COUNTIFS(Flags_auditoria!$F$2:$F$500,A19,Flags_auditoria!$H$2:$H$500,"Resolvido")

Sheet Itens
A1: ID | B1: Parte | C1: Item | D1: Descrição breve | E1: Byte-level confirmado | F1: Hardware live | G1: Ferramenta (otool/Ghidra) | H1: Especulativo | I1: Fontes / cruzamentos (separe com ;) | J1: Nº de fontes | K1: Status documental | L1: Confiança (0–10) | M1: Referência (arquivo; seção/linha) | N1: Flags do audit (arquivo:linha) | O1: Notas / pendências | P1: Sub-ramo
A2: AP-0.1.1 | B2: AP-0.1 | C2: Tabela kDeviceSpecs | D2: 8 entradas × {nome de produto, nome do bootloader, classe} em 0x46450, passo 0x18: FW 410/FW Bootloader/FW410Device; FW Audiophile/FW Audiophile Bootloader/FWAudiophileDevice; FW 1814/FW 1814 Bootloader; ProjectMix/ProjectMix; FW Solo/FWSolo Bootloader; Ozonic/Ozonic Bootloader; NRV-10/NRV-10 Bootloader; ProFire Lightbridge/ProFire Lightbridge Bootloader. | E2: Sim | F2: Não | G2: otool + Ghidra | H2: Não | I2: bytes da fatia 0x46450–0x46510 lidos via python 2026-10-19; mafw.asm 0x1ce1c (lea kDeviceSpecs); GetActualProductName @0x1ce06 (Ghidra); Info.plist (personalidades com os mesmos nomes) | J2: =IF(TRIM(I2)="",0,LEN(I2)-LEN(SUBSTITUTE(I2,";",""))+1) | K2: Consistente | L2: =ROUND(IF(H2="Sim",MIN(Legenda!$C$12,MIN(10,IF(E2="Sim",Legenda!$C$4,IF(E2="Parcial",Legenda!$C$5,0))+IF(F2="Sim",Legenda!$C$6,IF(F2="Parcial",Legenda!$C$7,0))+IF(G2="otool + Ghidra",Legenda!$C$8,IF(OR(G2="otool",G2="Ghidra",G2="Outro binário"),Legenda!$C$9,0))+MIN(Legenda!$C$11,MAX(0,J2-1)*Legenda!$C$10))),IF(H2="Parcial",MIN(Legenda!$C$13,MIN(10,IF(E2="Sim",Legenda!$C$4,IF(E2="Parcial",Legenda!$C$5,0))+IF(F2="Sim",Legenda!$C$6,IF(F2="Parcial",Legenda!$C$7,0))+IF(G2="otool + Ghidra",Legenda!$C$8,IF(OR(G2="otool",G2="Ghidra",G2="Outro binário"),Legenda!$C$9,0))+MIN(Legenda!$C$11,MAX(0,J2-1)*Legenda!$C$10))),MIN(10,IF(E2="Sim",Legenda!$C$4,IF(E2="Parcial",Legenda!$C$5,0))+IF(F2="Sim",Legenda!$C$6,IF(F2="Parcial",Legenda!$C$7,0))+IF(G2="otool + Ghidra",Legenda!$C$8,IF(OR(G2="otool",G2="Ghidra",G2="Outro binário"),Legenda!$C$9,0))+MIN(Legenda!$C$11,MAX(0,J2-1)*Legenda!$C$10)))),1) | M2: A1-ghidra/Q-AP0-nub-and-rev2.md §1.1 | N2: — | O2: O clone tem a mesma tabela com 1 entrada (FWMetaNub.cpp:42); AP-2.1 a estende para 8. [2026-10-19] R77. | P2: =LEFT(A2,FIND(".",A2&".")-1)
A3: AP-0.1.2 | B3: AP-0.1 | C3: FWMetaNub::probe | D3: Aceita o nó se 'FireWire Vendor Name' = 'M-Audio' ou 'M-AUDIO' e o 'FireWire Product Name' estiver na tabela (nome runtime OU de bootloader); score 0x7FFFFF. Não usa Model_ID. | E3: Parcial | F3: Não | G3: Ghidra | H3: Não | I3: FWMetaNub::probe @0x1ce62 (Ghidra); clone FWMetaNub.cpp:112 (mesma regra) | J3: =IF(TRIM(I3)="",0,LEN(I3)-LEN(SUBSTITUTE(I3,";",""))+1) | K3: Consistente | L3: =ROUND(IF(H3="Sim",MIN(Legenda!$C$12,MIN(10,IF(E3="Sim",Legenda!$C$4,IF(E3="Parcial",Legenda!$C$5,0))+IF(F3="Sim",Legenda!$C$6,IF(F3="Parcial",Legenda!$C$7,0))+IF(G3="otool + Ghidra",Legenda!$C$8,IF(OR(G3="otool",G3="Ghidra",G3="Outro binário"),Legenda!$C$9,0))+MIN(Legenda!$C$11,MAX(0,J3-1)*Legenda!$C$10))),IF(H3="Parcial",MIN(Legenda!$C$13,MIN(10,IF(E3="Sim",Legenda!$C$4,IF(E3="Parcial",Legenda!$C$5,0))+IF(F3="Sim",Legenda!$C$6,IF(F3="Parcial",Legenda!$C$7,0))+IF(G3="otool + Ghidra",Legenda!$C$8,IF(OR(G3="otool",G3="Ghidra",G3="Outro binário"),Legenda!$C$9,0))+MIN(Legenda!$C$11,MAX(0,J3-1)*Legenda!$C$10))),MIN(10,IF(E3="Sim",Legenda!$C$4,IF(E3="Parcial",Legenda!$C$5,0))+IF(F3="Sim",Legenda!$C$6,IF(F3="Parcial",Legenda!$C$7,0))+IF(G3="otool + Ghidra",Legenda!$C$8,IF(OR(G3="otool",G3="Ghidra",G3="Outro binário"),Legenda!$C$9,0))+MIN(Legenda!$C$11,MAX(0,J3-1)*Legenda!$C$10)))),1) | M3: decomp/FWMetaNub__probe.c | N3: AUD-AP-06 | O3: Resolve o item 2 do §8 do audiophile-manual-reference (a parte 'qual Model_ID'). | P3: =LEFT(A3,FIND(".",A3&".")-1)
A4: AP-0.1.3 | B4: AP-0.1 | C4: MAActualProductName | D4: start() publica MAActualProductName = nome runtime (campo 0) mesmo quando o nó é o bootloader ('FW Audiophile Bootloader' → 'FW Audiophile'). O laço de GetActualProductName não para no primeiro acerto (último acerto vence). | E4: Parcial | F4: Não | G4: Ghidra | H4: Não | I4: FWMetaNub::start @0x1cf68; GetActualProductName @0x1ce06 | J4: =IF(TRIM(I4)="",0,LEN(I4)-LEN(SUBSTITUTE(I4,";",""))+1) | K4: Consistente | L4: =ROUND(IF(H4="Sim",MIN(Legenda!$C$12,MIN(10,IF(E4="Sim",Legenda!$C$4,IF(E4="Parcial",Legenda!$C$5,0))+IF(F4="Sim",Legenda!$C$6,IF(F4="Parcial",Legenda!$C$7,0))+IF(G4="otool + Ghidra",Legenda!$C$8,IF(OR(G4="otool",G4="Ghidra",G4="Outro binário"),Legenda!$C$9,0))+MIN(Legenda!$C$11,MAX(0,J4-1)*Legenda!$C$10))),IF(H4="Parcial",MIN(Legenda!$C$13,MIN(10,IF(E4="Sim",Legenda!$C$4,IF(E4="Parcial",Legenda!$C$5,0))+IF(F4="Sim",Legenda!$C$6,IF(F4="Parcial",Legenda!$C$7,0))+IF(G4="otool + Ghidra",Legenda!$C$8,IF(OR(G4="otool",G4="Ghidra",G4="Outro binário"),Legenda!$C$9,0))+MIN(Legenda!$C$11,MAX(0,J4-1)*Legenda!$C$10))),MIN(10,IF(E4="Sim",Legenda!$C$4,IF(E4="Parcial",Legenda!$C$5,0))+IF(F4="Sim",Legenda!$C$6,IF(F4="Parcial",Legenda!$C$7,0))+IF(G4="otool + Ghidra",Legenda!$C$8,IF(OR(G4="otool",G4="Ghidra",G4="Outro binário"),Legenda!$C$9,0))+MIN(Legenda!$C$11,MAX(0,J4-1)*Legenda!$C$10)))),1) | M4: decomp/FWMetaNub__start.c | N4: — | O4: O helper usa este nome para escolher o .bcd (A4-H10). | P4: =LEFT(A4,FIND(".",A4&".")-1)
A5: AP-0.1.4 | B5: AP-0.1 | C5: Casamento da classe de dispositivo | D5: A personalidade de cada classe (IOProviderClass = com_m_audio_FWMetaNub) casa pela propriedade 'FireWire Product Name' copiada para o nub; só o NRV-10 exige também Model_ID 65665. Audiophile: 'FW Audiophile'. | E5: Sim | F5: Sim | G5: Outro binário | H5: Não | I5: Info.plist do kext (plutil 2026-10-19); captura 89 (FWAudiophileDevice sob FWMetaNub no SL v1.9); FWMetaNub::start copia Product/Vendor Name, Vendor_ID, Model_ID, GUID | J5: =IF(TRIM(I5)="",0,LEN(I5)-LEN(SUBSTITUTE(I5,";",""))+1) | K5: Corrigido 2026-10-19 | L5: =ROUND(IF(H5="Sim",MIN(Legenda!$C$12,MIN(10,IF(E5="Sim",Legenda!$C$4,IF(E5="Parcial",Legenda!$C$5,0))+IF(F5="Sim",Legenda!$C$6,IF(F5="Parcial",Legenda!$C$7,0))+IF(G5="otool + Ghidra",Legenda!$C$8,IF(OR(G5="otool",G5="Ghidra",G5="Outro binário"),Legenda!$C$9,0))+MIN(Legenda!$C$11,MAX(0,J5-1)*Legenda!$C$10))),IF(H5="Parcial",MIN(Legenda!$C$13,MIN(10,IF(E5="Sim",Legenda!$C$4,IF(E5="Parcial",Legenda!$C$5,0))+IF(F5="Sim",Legenda!$C$6,IF(F5="Parcial",Legenda!$C$7,0))+IF(G5="otool + Ghidra",Legenda!$C$8,IF(OR(G5="otool",G5="Ghidra",G5="Outro binário"),Legenda!$C$9,0))+MIN(Legenda!$C$11,MAX(0,J5-1)*Legenda!$C$10))),MIN(10,IF(E5="Sim",Legenda!$C$4,IF(E5="Parcial",Legenda!$C$5,0))+IF(F5="Sim",Legenda!$C$6,IF(F5="Parcial",Legenda!$C$7,0))+IF(G5="otool + Ghidra",Legenda!$C$8,IF(OR(G5="otool",G5="Ghidra",G5="Outro binário"),Legenda!$C$9,0))+MIN(Legenda!$C$11,MAX(0,J5-1)*Legenda!$C$10)))),1) | M5: _extracted/kext/…/Info.plist; captures/89-sl-audiophile-ioreg-device-subtree.txt | N5: AUD-AP-06 | O5: audiophile-manual-reference §1 diz 'by class alone' — corrigir. [2026-10-19] Correction block no audiophile-manual-reference (R77). | P5: =LEFT(A5,FIND(".",A5&".")-1)
A6: AP-0.1.5 | B6: AP-0.1 | C6: FWAVCAudioDevice::probe | D6: Exige provedor FWMetaNub, mesmo Product Name, Model_ID igual se ambos existirem, nub [+0xf0]==0 (não está no bootloader) e [+0xf3]!=0 (FirmwareStart já registrou). | E6: Parcial | F6: Não | G6: Ghidra | H6: Não | I6: FWAVCAudioDevice::probe (Ghidra 2026-10-19); Q7 tabela de campos; clone FWAudioDeviceChain.cpp:38 | J6: =IF(TRIM(I6)="",0,LEN(I6)-LEN(SUBSTITUTE(I6,";",""))+1) | K6: Consistente | L6: =ROUND(IF(H6="Sim",MIN(Legenda!$C$12,MIN(10,IF(E6="Sim",Legenda!$C$4,IF(E6="Parcial",Legenda!$C$5,0))+IF(F6="Sim",Legenda!$C$6,IF(F6="Parcial",Legenda!$C$7,0))+IF(G6="otool + Ghidra",Legenda!$C$8,IF(OR(G6="otool",G6="Ghidra",G6="Outro binário"),Legenda!$C$9,0))+MIN(Legenda!$C$11,MAX(0,J6-1)*Legenda!$C$10))),IF(H6="Parcial",MIN(Legenda!$C$13,MIN(10,IF(E6="Sim",Legenda!$C$4,IF(E6="Parcial",Legenda!$C$5,0))+IF(F6="Sim",Legenda!$C$6,IF(F6="Parcial",Legenda!$C$7,0))+IF(G6="otool + Ghidra",Legenda!$C$8,IF(OR(G6="otool",G6="Ghidra",G6="Outro binário"),Legenda!$C$9,0))+MIN(Legenda!$C$11,MAX(0,J6-1)*Legenda!$C$10))),MIN(10,IF(E6="Sim",Legenda!$C$4,IF(E6="Parcial",Legenda!$C$5,0))+IF(F6="Sim",Legenda!$C$6,IF(F6="Parcial",Legenda!$C$7,0))+IF(G6="otool + Ghidra",Legenda!$C$8,IF(OR(G6="otool",G6="Ghidra",G6="Outro binário"),Legenda!$C$9,0))+MIN(Legenda!$C$11,MAX(0,J6-1)*Legenda!$C$10)))),1) | M6: decomp/FWAVCAudioDevice__probe.c; A1-ghidra/Q7-fwmetanub-lifecycle.md | N6: — | O6: Já espelhado no clone; vale para todos os modelos. | P6: =LEFT(A6,FIND(".",A6&".")-1)
A7: AP-0.1.6 | B7: AP-0.1 | C7: Model_ID do Audiophile | D7: Runtime 0x00010060 (65632). Bootloader: mesmo Model_ID, distinguido só pelo texto da unidade 'FW Audiophile Bootloader' (fonte de terceiros; o bootloader nunca foi observado). | E7: Sim | F7: Parcial | G7: Outro binário | H7: Parcial | I7: FWAP.bcd apêndice ModelID; captura 89b (Model_ID 65632 no SL); snd-bebob bebob.c:150-157; ffado normal_avdevice.cpp:39 | J7: =IF(TRIM(I7)="",0,LEN(I7)-LEN(SUBSTITUTE(I7,";",""))+1) | K7: Aberto / não resolvido | L7: =ROUND(IF(H7="Sim",MIN(Legenda!$C$12,MIN(10,IF(E7="Sim",Legenda!$C$4,IF(E7="Parcial",Legenda!$C$5,0))+IF(F7="Sim",Legenda!$C$6,IF(F7="Parcial",Legenda!$C$7,0))+IF(G7="otool + Ghidra",Legenda!$C$8,IF(OR(G7="otool",G7="Ghidra",G7="Outro binário"),Legenda!$C$9,0))+MIN(Legenda!$C$11,MAX(0,J7-1)*Legenda!$C$10))),IF(H7="Parcial",MIN(Legenda!$C$13,MIN(10,IF(E7="Sim",Legenda!$C$4,IF(E7="Parcial",Legenda!$C$5,0))+IF(F7="Sim",Legenda!$C$6,IF(F7="Parcial",Legenda!$C$7,0))+IF(G7="otool + Ghidra",Legenda!$C$8,IF(OR(G7="otool",G7="Ghidra",G7="Outro binário"),Legenda!$C$9,0))+MIN(Legenda!$C$11,MAX(0,J7-1)*Legenda!$C$10))),MIN(10,IF(E7="Sim",Legenda!$C$4,IF(E7="Parcial",Legenda!$C$5,0))+IF(F7="Sim",Legenda!$C$6,IF(F7="Parcial",Legenda!$C$7,0))+IF(G7="otool + Ghidra",Legenda!$C$8,IF(OR(G7="otool",G7="Ghidra",G7="Outro binário"),Legenda!$C$9,0))+MIN(Legenda!$C$11,MAX(0,J7-1)*Legenda!$C$10)))),1) | M7: audiophile-manual-reference.md §1 | N7: — | O7: Fecha no AP-7.1 (power-cycle, ver o nó de bootloader). | P7: =LEFT(A7,FIND(".",A7&".")-1)
A8: AP-0.2.1 | B8: AP-0.2 | C8: Hierarquia Rev1/Rev2 | D8: Audiophile, FW410, Ozonic, Solo, NRV10, Lightbridge derivam de FWRev2AudioDevice; FW1814 (e ProjectMix via 1814) de FWRev1AudioDevice; ambos de m_audio_b_FWAVCAudioDevice. | E8: Sim | F8: Não | G8: otool + Ghidra | H8: Não | I8: construtores de metaclasse (Q16 Correction 2026-10-14); ctor Rev2 0x13574; ctor FWAudiophileDevice 0xbe6c | J8: =IF(TRIM(I8)="",0,LEN(I8)-LEN(SUBSTITUTE(I8,";",""))+1) | K8: Corrigido 2026-10-19 | L8: =ROUND(IF(H8="Sim",MIN(Legenda!$C$12,MIN(10,IF(E8="Sim",Legenda!$C$4,IF(E8="Parcial",Legenda!$C$5,0))+IF(F8="Sim",Legenda!$C$6,IF(F8="Parcial",Legenda!$C$7,0))+IF(G8="otool + Ghidra",Legenda!$C$8,IF(OR(G8="otool",G8="Ghidra",G8="Outro binário"),Legenda!$C$9,0))+MIN(Legenda!$C$11,MAX(0,J8-1)*Legenda!$C$10))),IF(H8="Parcial",MIN(Legenda!$C$13,MIN(10,IF(E8="Sim",Legenda!$C$4,IF(E8="Parcial",Legenda!$C$5,0))+IF(F8="Sim",Legenda!$C$6,IF(F8="Parcial",Legenda!$C$7,0))+IF(G8="otool + Ghidra",Legenda!$C$8,IF(OR(G8="otool",G8="Ghidra",G8="Outro binário"),Legenda!$C$9,0))+MIN(Legenda!$C$11,MAX(0,J8-1)*Legenda!$C$10))),MIN(10,IF(E8="Sim",Legenda!$C$4,IF(E8="Parcial",Legenda!$C$5,0))+IF(F8="Sim",Legenda!$C$6,IF(F8="Parcial",Legenda!$C$7,0))+IF(G8="otool + Ghidra",Legenda!$C$8,IF(OR(G8="otool",G8="Ghidra",G8="Outro binário"),Legenda!$C$9,0))+MIN(Legenda!$C$11,MAX(0,J8-1)*Legenda!$C$10)))),1) | M8: A1-ghidra/Q16-rev1-rev2-deltas.md (Correction 2026-10-14) | N8: AUD-AP-04 | O8: A Correction do topo do Q16 já traz a tabela certa; a linha 80 ainda diz 'Solo = Rev1'. [2026-10-19] Correction no Q16 (R77). | P8: =LEFT(A8,FIND(".",A8&".")-1)
A9: AP-0.2.2 | B9: AP-0.2 | C9: Rev2 AllocateAudioEngine | D9: Rev2 cria um com_m_audio_FWEngine2 (Rev1 devolve 0: a subclasse aloca). | E9: Parcial | F9: Sim | G9: Ghidra | H9: Não | I9: FWRev2AudioDevice::AllocateAudioEngine @0xb66a; FWRev1 @0x136aa; captura 89 (um FWEngine2 'FireWire Audiophile Multichannel') | J9: =IF(TRIM(I9)="",0,LEN(I9)-LEN(SUBSTITUTE(I9,";",""))+1) | K9: Consistente | L9: =ROUND(IF(H9="Sim",MIN(Legenda!$C$12,MIN(10,IF(E9="Sim",Legenda!$C$4,IF(E9="Parcial",Legenda!$C$5,0))+IF(F9="Sim",Legenda!$C$6,IF(F9="Parcial",Legenda!$C$7,0))+IF(G9="otool + Ghidra",Legenda!$C$8,IF(OR(G9="otool",G9="Ghidra",G9="Outro binário"),Legenda!$C$9,0))+MIN(Legenda!$C$11,MAX(0,J9-1)*Legenda!$C$10))),IF(H9="Parcial",MIN(Legenda!$C$13,MIN(10,IF(E9="Sim",Legenda!$C$4,IF(E9="Parcial",Legenda!$C$5,0))+IF(F9="Sim",Legenda!$C$6,IF(F9="Parcial",Legenda!$C$7,0))+IF(G9="otool + Ghidra",Legenda!$C$8,IF(OR(G9="otool",G9="Ghidra",G9="Outro binário"),Legenda!$C$9,0))+MIN(Legenda!$C$11,MAX(0,J9-1)*Legenda!$C$10))),MIN(10,IF(E9="Sim",Legenda!$C$4,IF(E9="Parcial",Legenda!$C$5,0))+IF(F9="Sim",Legenda!$C$6,IF(F9="Parcial",Legenda!$C$7,0))+IF(G9="otool + Ghidra",Legenda!$C$8,IF(OR(G9="otool",G9="Ghidra",G9="Outro binário"),Legenda!$C$9,0))+MIN(Legenda!$C$11,MAX(0,J9-1)*Legenda!$C$10)))),1) | M9: decomp/FWRev2AudioDevice__AllocateAudioEngine.c | N9: — | O9: O clone já tem FWEngine2. | P9: =LEFT(A9,FIND(".",A9&".")-1)
A10: AP-0.2.3 | B10: AP-0.2 | C10: Rev2 AVCControlPlugSignalFormat (0x2F) | D10: EXTENDED STREAM FORMAT: STATUS '01 FF 2F C1 <dir> 00 00 <plug> FF FF <idx>' percorrendo a lista até a resposta[13] = código de taxa; depois CONTROL '00 FF 2F C0 … 90 40 <taxa> …' copiando o bloco de formato da resposta (n×2+1 bytes a partir de resposta[15]). | E10: Sim | F10: Não | G10: otool + Ghidra | H10: Não | I10: asm 0x12e7e-0x1305a; Ghidra; FFADO avc_extended_stream_format.h:35-41,108-109 e .cpp:159-177,340-351; FFADO avc_extended_cmd_generic.cpp:42-48; vtable Audiophile slot 0xb50 | J10: =IF(TRIM(I10)="",0,LEN(I10)-LEN(SUBSTITUTE(I10,";",""))+1) | K10: Consistente | L10: =ROUND(IF(H10="Sim",MIN(Legenda!$C$12,MIN(10,IF(E10="Sim",Legenda!$C$4,IF(E10="Parcial",Legenda!$C$5,0))+IF(F10="Sim",Legenda!$C$6,IF(F10="Parcial",Legenda!$C$7,0))+IF(G10="otool + Ghidra",Legenda!$C$8,IF(OR(G10="otool",G10="Ghidra",G10="Outro binário"),Legenda!$C$9,0))+MIN(Legenda!$C$11,MAX(0,J10-1)*Legenda!$C$10))),IF(H10="Parcial",MIN(Legenda!$C$13,MIN(10,IF(E10="Sim",Legenda!$C$4,IF(E10="Parcial",Legenda!$C$5,0))+IF(F10="Sim",Legenda!$C$6,IF(F10="Parcial",Legenda!$C$7,0))+IF(G10="otool + Ghidra",Legenda!$C$8,IF(OR(G10="otool",G10="Ghidra",G10="Outro binário"),Legenda!$C$9,0))+MIN(Legenda!$C$11,MAX(0,J10-1)*Legenda!$C$10))),MIN(10,IF(E10="Sim",Legenda!$C$4,IF(E10="Parcial",Legenda!$C$5,0))+IF(F10="Sim",Legenda!$C$6,IF(F10="Parcial",Legenda!$C$7,0))+IF(G10="otool + Ghidra",Legenda!$C$8,IF(OR(G10="otool",G10="Ghidra",G10="Outro binário"),Legenda!$C$9,0))+MIN(Legenda!$C$11,MAX(0,J10-1)*Legenda!$C$10)))),1) | M10: A1-ghidra/Q-AP0-nub-and-rev2.md §2.1 | N10: — | O10: Layout dos bytes 10–15 e o comprimento exato precisam do asm 0x12e7e–0x13078 (o decompile mistura pilha). [2026-10-19] Layout fechado no asm e igual ao FFADO. Quadro C1 enviado com 14 bytes (3 sem inicializar). Direção do kext 0 = plug AV/C de saída. | P10: =LEFT(A10,FIND(".",A10&".")-1)
A11: AP-0.2.4 | B11: AP-0.2 | C11: Códigos de taxa do 0x2F | D11: FDF0→0x02, FDF1 e default→0x03, FDF2→0x04, FDF3→0x0A, FDF4→0x05, FDF5→0x06, FDF6→0x07 (32/44.1/48/88.2/96/176.4/192). | E11: Sim | F11: Não | G11: otool + Ghidra | H11: Não | I11: asm 0x12e8f-0x12ecf; Ghidra switch; FFADO avc_definitions.h:115-125 (ESamplingFrequency) | J11: =IF(TRIM(I11)="",0,LEN(I11)-LEN(SUBSTITUTE(I11,";",""))+1) | K11: Consistente | L11: =ROUND(IF(H11="Sim",MIN(Legenda!$C$12,MIN(10,IF(E11="Sim",Legenda!$C$4,IF(E11="Parcial",Legenda!$C$5,0))+IF(F11="Sim",Legenda!$C$6,IF(F11="Parcial",Legenda!$C$7,0))+IF(G11="otool + Ghidra",Legenda!$C$8,IF(OR(G11="otool",G11="Ghidra",G11="Outro binário"),Legenda!$C$9,0))+MIN(Legenda!$C$11,MAX(0,J11-1)*Legenda!$C$10))),IF(H11="Parcial",MIN(Legenda!$C$13,MIN(10,IF(E11="Sim",Legenda!$C$4,IF(E11="Parcial",Legenda!$C$5,0))+IF(F11="Sim",Legenda!$C$6,IF(F11="Parcial",Legenda!$C$7,0))+IF(G11="otool + Ghidra",Legenda!$C$8,IF(OR(G11="otool",G11="Ghidra",G11="Outro binário"),Legenda!$C$9,0))+MIN(Legenda!$C$11,MAX(0,J11-1)*Legenda!$C$10))),MIN(10,IF(E11="Sim",Legenda!$C$4,IF(E11="Parcial",Legenda!$C$5,0))+IF(F11="Sim",Legenda!$C$6,IF(F11="Parcial",Legenda!$C$7,0))+IF(G11="otool + Ghidra",Legenda!$C$8,IF(OR(G11="otool",G11="Ghidra",G11="Outro binário"),Legenda!$C$9,0))+MIN(Legenda!$C$11,MAX(0,J11-1)*Legenda!$C$10)))),1) | M11: A1-ghidra/Q-AP0-nub-and-rev2.md §2.1 | N11: — | O11: Conferir no asm junto com AP-0.2.3. [2026-10-19] Códigos = ESamplingFrequency do FFADO. | P11: =LEFT(A11,FIND(".",A11&".")-1)
A12: AP-0.2.5 | B12: AP-0.2 | C12: AVCSetupSyncStream (0x1A) | D12: 1) STATUS '01 FF 1A 0F FF FE 60 <p>'; 2) vt[0xbc0] = GetAddressAndPlugForSyncType preenche os bytes 4/5 (origem); 3) CONTROL '00 FF 1A 0F <addr> <plug> 60 <p>'. 0x1A = SIGNAL SOURCE (destino = subunidade música 0x60, plug p). | E12: Sim | F12: Não | G12: otool + Ghidra | H12: Não | I12: asm 0x12c60-0x12e1d; Ghidra; vtable Audiophile slot 0xbc0 = GetAddressAndPlugForSyncType; FFADO avc_signal_source.cpp:33 | J12: =IF(TRIM(I12)="",0,LEN(I12)-LEN(SUBSTITUTE(I12,";",""))+1) | K12: Corrigido 2026-10-19 | L12: =ROUND(IF(H12="Sim",MIN(Legenda!$C$12,MIN(10,IF(E12="Sim",Legenda!$C$4,IF(E12="Parcial",Legenda!$C$5,0))+IF(F12="Sim",Legenda!$C$6,IF(F12="Parcial",Legenda!$C$7,0))+IF(G12="otool + Ghidra",Legenda!$C$8,IF(OR(G12="otool",G12="Ghidra",G12="Outro binário"),Legenda!$C$9,0))+MIN(Legenda!$C$11,MAX(0,J12-1)*Legenda!$C$10))),IF(H12="Parcial",MIN(Legenda!$C$13,MIN(10,IF(E12="Sim",Legenda!$C$4,IF(E12="Parcial",Legenda!$C$5,0))+IF(F12="Sim",Legenda!$C$6,IF(F12="Parcial",Legenda!$C$7,0))+IF(G12="otool + Ghidra",Legenda!$C$8,IF(OR(G12="otool",G12="Ghidra",G12="Outro binário"),Legenda!$C$9,0))+MIN(Legenda!$C$11,MAX(0,J12-1)*Legenda!$C$10))),MIN(10,IF(E12="Sim",Legenda!$C$4,IF(E12="Parcial",Legenda!$C$5,0))+IF(F12="Sim",Legenda!$C$6,IF(F12="Parcial",Legenda!$C$7,0))+IF(G12="otool + Ghidra",Legenda!$C$8,IF(OR(G12="otool",G12="Ghidra",G12="Outro binário"),Legenda!$C$9,0))+MIN(Legenda!$C$11,MAX(0,J12-1)*Legenda!$C$10)))),1) | M12: A1-ghidra/Q-AP0-nub-and-rev2.md §2.2 | N12: AUD-AP-01 | O12: Q16:73-74 rotula o 1º quadro como CONTROL e o 2º como GET-STATUS: é o contrário (ctype 0x01 = STATUS, 0x00 = CONTROL). [2026-10-19] Correction no Q16. Peculiaridade: se vt[0xbc0] falha a função devolve 0 sem enviar o CONTROL. | P12: =LEFT(A12,FIND(".",A12&".")-1)
A13: AP-0.2.6 | B13: AP-0.2 | C13: GetAddressAndPlugForSyncType | D13: tipo 0 → 60/(p==1 ? 1 : p+1) (subunidade música); 1 → FF/81; 2 → FF/00; 3 → FF/83; 4 → FF/82 (plugs externos da unidade). Os nomes dos tipos não estão no binário. | E13: Parcial | F13: Não | G13: Ghidra | H13: Não | I13: FWRev2AudioDevice::GetAddressAndPlugForSyncType @0x12ae8 (Ghidra); ctl-services normal.rs:483-495 (Audiophile: interno = música plug 1, S/PDIF = Ext 0x02 → 0x82) | J13: =IF(TRIM(I13)="",0,LEN(I13)-LEN(SUBSTITUTE(I13,";",""))+1) | K13: Corrigido 2026-10-19 | L13: =ROUND(IF(H13="Sim",MIN(Legenda!$C$12,MIN(10,IF(E13="Sim",Legenda!$C$4,IF(E13="Parcial",Legenda!$C$5,0))+IF(F13="Sim",Legenda!$C$6,IF(F13="Parcial",Legenda!$C$7,0))+IF(G13="otool + Ghidra",Legenda!$C$8,IF(OR(G13="otool",G13="Ghidra",G13="Outro binário"),Legenda!$C$9,0))+MIN(Legenda!$C$11,MAX(0,J13-1)*Legenda!$C$10))),IF(H13="Parcial",MIN(Legenda!$C$13,MIN(10,IF(E13="Sim",Legenda!$C$4,IF(E13="Parcial",Legenda!$C$5,0))+IF(F13="Sim",Legenda!$C$6,IF(F13="Parcial",Legenda!$C$7,0))+IF(G13="otool + Ghidra",Legenda!$C$8,IF(OR(G13="otool",G13="Ghidra",G13="Outro binário"),Legenda!$C$9,0))+MIN(Legenda!$C$11,MAX(0,J13-1)*Legenda!$C$10))),MIN(10,IF(E13="Sim",Legenda!$C$4,IF(E13="Parcial",Legenda!$C$5,0))+IF(F13="Sim",Legenda!$C$6,IF(F13="Parcial",Legenda!$C$7,0))+IF(G13="otool + Ghidra",Legenda!$C$8,IF(OR(G13="otool",G13="Ghidra",G13="Outro binário"),Legenda!$C$9,0))+MIN(Legenda!$C$11,MAX(0,J13-1)*Legenda!$C$10)))),1) | M13: A1-ghidra/Q-AP0-nub-and-rev2.md §2.2 | N13: AUD-AP-02 | O13: Q16:44 dá nomes (S/PDIF=0x81, Aux=0x82) sem fonte; no Audiophile o S/PDIF é o tipo 4 (0x82). [2026-10-19] Correction no Q16. | P13: =LEFT(A13,FIND(".",A13&".")-1)
... A18: AP-0.2.11 | B18: AP-0.2 | C18: Pacotes de controle (HSCI) no Rev2 | D18: StartReceptionOfControlPackets: new FWHSCI em [+0x2c8], tamanho = vt[0xba0] (GetControlPacketSize), functor de retorno com tag 0xBB9, Start(workloop). Stop/Pause chamam HSCI e ClearPeakMeters; Resume só HSCI; stop() libera HSCI e a unidade AV/C. | E18: Parcial | F18: Não | G18: Ghidra | H18: Não | I18: FWRev2AudioDevice::{Start,Stop,Pause,Resume}ReceptionOfControlPackets, stop (Ghidra 2026-10-19); Q16 | J18: =IF(TRIM(I18)="",0,LEN(I18)-LEN(SUBSTITUTE(I18,";",""))+1) | K18: Consistente | L18: =ROUND(IF(H18="Sim",MIN(Legenda!$C$12,MIN(10,IF(E18="Sim",Legenda!$C$4,IF(E18="Parcial",Legenda!$C$5,0))+IF(F18="Sim",Legenda!$C$6,IF(F18="Parcial",Legenda!$C$7,0))+IF(G18="otool + Ghidra",Legenda!$C$8,IF(OR(G18="otool",G18="Ghidra",G18="Outro binário"),Legenda!$C$9,0))+MIN(Legenda!$C$11,MAX(0,J18-1)*Legenda!$C$10))),IF(H18="Parcial",MIN(Legenda!$C$13,MIN(10,IF(E18="Sim",Legenda!$C$4,IF(E18="Parcial",Legenda!$C$5,0))+IF(F18="Sim",Legenda!$C$6,IF(F18="Parcial",Legenda!$C$7,0))+IF(G18="otool + Ghidra",Legenda!$C$8,IF(OR(G18="otool",G18="Ghidra",G18="Outro binário"),Legenda!$C$9,0))+MIN(Legenda!$C$11,MAX(0,J18-1)*Legenda!$C$10))),MIN(10,IF(E18="Sim",Legenda!$C$4,IF(E18="Parcial",Legenda!$C$5,0))+IF(F18="Sim",Legenda!$C$6,IF(F18="Parcial",Legenda!$C$7,0))+IF(G18="otool + Ghidra",Legenda!$C$8,IF(OR(G18="otool",G18="Ghidra",G18="Outro binário"),Legenda!$C$9,0))+MIN(Legenda!$C$11,MAX(0,J18-1)*Legenda!$C$10)))),1) | M18: A1-ghidra/Q-AP0-nub-and-rev2.md §2.5 | N18: — | O18: O clone tem o equivalente aberto no FW1814Device: mover para a base Rev2 no AP-2.3. | P18: =LEFT(A18,FIND(".",A18&".")-1)
A19: AP-0.2.12 | B19: AP-0.2 | C19: Métodos vazios do Rev2 | D19: ReadHSCIData e StartExternalSyncUnmuteTimer são corpos vazios na base Rev2; initHardware só repassa ao pai. O Audiophile sobrescreve ReadHSCIData. | E19: Parcial | F19: Não | G19: Ghidra | H19: Não | I19: FWRev2AudioDevice::ReadHSCIData @0x12b6e, StartExternalSyncUnmuteTimer @0x12aa8, initHardware @0x12a3e (Ghidra) | J19: =IF(TRIM(I19)="",0,LEN(I19)-LEN(SUBSTITUTE(I19,";",""))+1) | K19: Consistente | L19: =ROUND(IF(H19="Sim",MIN(Legenda!$C$12,MIN(10,IF(E19="Sim",Legenda!$C$4,IF(E19="Parcial",Legenda!$C$5,0))+IF(F19="Sim",Legenda!$C$6,IF(F19="Parcial",Legenda!$C$7,0))+IF(G19="otool + Ghidra",Legenda!$C$8,IF(OR(G19="otool",G19="Ghidra",G19="Outro binário"),Legenda!$C$9,0))+MIN(Legenda!$C$11,MAX(0,J19-1)*Legenda!$C$10))),IF(H19="Parcial",MIN(Legenda!$C$13,MIN(10,IF(E19="Sim",Legenda!$C$4,IF(E19="Parcial",Legenda!$C$5,0))+IF(F19="Sim",Legenda!$C$6,IF(F19="Parcial",Legenda!$C$7,0))+IF(G19="otool + Ghidra",Legenda!$C$8,IF(OR(G19="otool",G19="Ghidra",G19="Outro binário"),Legenda!$C$9,0))+MIN(Legenda!$C$11,MAX(0,J19-1)*Legenda!$C$10))),MIN(10,IF(E19="Sim",Legenda!$C$4,IF(E19="Parcial",Legenda!$C$5,0))+IF(F19="Sim",Legenda!$C$6,IF(F19="Parcial",Legenda!$C$7,0))+IF(G19="otool + Ghidra",Legenda!$C$8,IF(OR(G19="otool",G19="Ghidra",G19="Outro binário"),Legenda!$C$9,0))+MIN(Legenda!$C$11,MAX(0,J19-1)*Legenda!$C$10)))),1) | M19: A1-ghidra/Q-AP0-nub-and-rev2.md §2.5 | N19: — | P19: =LEFT(A19,FIND(".",A19&".")-1)
A20: AP-0.3.1 | B20: AP-0.3 | C20: Bytes AV/C do mixer (function blocks) | D20: Quatro quadros AV/C (CONTROL, subunidade 0x08, opcode 0xB8, atributo 0x10, fila assíncrona vt[0x8b0], resposta ignorada): feature 00 08 B8 81 fb 10 02 ch sel 02 v16 (sel 2 volume, 3 balanço; v16 = valor<<7, valor em ½ dB, balanço negado); seletor 00 08 B8 80 fb 10 02 in 01 00 00 00; mixer 00 08 B8 82 fb 10 04 plug inCh outCh 03 02 {00|80} 00 00 00; par = dois singles (2n−1, 2n). | E20: Sim | F20: Não | G20: otool + Ghidra | H20: Não | I20: Ghidra FWAVCAudioDevice::AVC* (2026-10-19); ctl-services normal.rs ~474-622; clone FWAvc.cpp:185-210 (mesmos bytes); asm das funções via FWAvc já verificado no 1814 (Q-ME) | J20: =IF(TRIM(I20)="",0,LEN(I20)-LEN(SUBSTITUTE(I20,";",""))+1) | K20: Consistente | L20: =ROUND(IF(H20="Sim",MIN(Legenda!$C$12,MIN(10,IF(E20="Sim",Legenda!$C$4,IF(E20="Parcial",Legenda!$C$5,0))+IF(F20="Sim",Legenda!$C$6,IF(F20="Parcial",Legenda!$C$7,0))+IF(G20="otool + Ghidra",Legenda!$C$8,IF(OR(G20="otool",G20="Ghidra",G20="Outro binário"),Legenda!$C$9,0))+MIN(Legenda!$C$11,MAX(0,J20-1)*Legenda!$C$10))),IF(H20="Parcial",MIN(Legenda!$C$13,MIN(10,IF(E20="Sim",Legenda!$C$4,IF(E20="Parcial",Legenda!$C$5,0))+IF(F20="Sim",Legenda!$C$6,IF(F20="Parcial",Legenda!$C$7,0))+IF(G20="otool + Ghidra",Legenda!$C$8,IF(OR(G20="otool",G20="Ghidra",G20="Outro binário"),Legenda!$C$9,0))+MIN(Legenda!$C$11,MAX(0,J20-1)*Legenda!$C$10))),MIN(10,IF(E20="Sim",Legenda!$C$4,IF(E20="Parcial",Legenda!$C$5,0))+IF(F20="Sim",Legenda!$C$6,IF(F20="Parcial",Legenda!$C$7,0))+IF(G20="otool + Ghidra",Legenda!$C$8,IF(OR(G20="otool",G20="Ghidra",G20="Outro binário"),Legenda!$C$9,0))+MIN(Legenda!$C$11,MAX(0,J20-1)*Legenda!$C$10)))),1) | M20: A1-ghidra/Q-AP0-avc-mixer.md §1 | N20: — | O20: Próximo passo do AP-0.3; o rig SL não captura FCP (B5 §12). [2026-10-19] Fechado (R79). Os construtores já existem no clone 1814, byte a byte. | P20: =LEFT(A20,FIND(".",A20&".")-1)
A21: AP-0.3.2 | B21: AP-0.3 | C21: Enum de MapChannelAndFunctionBlock | D21: Mapa kind → function block: 0 fontes aux (tabela 0x2f750: 9/0A/6/7/8), 1 fones 0F, 2 saídas 0C/0D/0E, 3 retornos SW 1/2/3, 4 não suportado, 5 seletor de saída = par, 6 entradas 4/5, 7 aux out 0B, 8 seletor de fones 4, 9 erro. | E21: Sim | F21: Não | G21: otool + Ghidra | H21: Não | I21: Ghidra MapChannelAndFunctionBlock @0xb0e2; bytes 0x2f750; ctl-services normal.rs (PhysInput 04/05, PhysOutput 0C-0E + seletores 1-3, AuxSource, AuxOutput 0B, Headphone 0F + seletor 4) | J21: =IF(TRIM(I21)="",0,LEN(I21)-LEN(SUBSTITUTE(I21,";",""))+1) | K21: Consistente | L21: =ROUND(IF(H21="Sim",MIN(Legenda!$C$12,MIN(10,IF(E21="Sim",Legenda!$C$4,IF(E21="Parcial",Legenda!$C$5,0))+IF(F21="Sim",Legenda!$C$6,IF(F21="Parcial",Legenda!$C$7,0))+IF(G21="otool + Ghidra",Legenda!$C$8,IF(OR(G21="otool",G21="Ghidra",G21="Outro binário"),Legenda!$C$9,0))+MIN(Legenda!$C$11,MAX(0,J21-1)*Legenda!$C$10))),IF(H21="Parcial",MIN(Legenda!$C$13,MIN(10,IF(E21="Sim",Legenda!$C$4,IF(E21="Parcial",Legenda!$C$5,0))+IF(F21="Sim",Legenda!$C$6,IF(F21="Parcial",Legenda!$C$7,0))+IF(G21="otool + Ghidra",Legenda!$C$8,IF(OR(G21="otool",G21="Ghidra",G21="Outro binário"),Legenda!$C$9,0))+MIN(Legenda!$C$11,MAX(0,J21-1)*Legenda!$C$10))),MIN(10,IF(E21="Sim",Legenda!$C$4,IF(E21="Parcial",Legenda!$C$5,0))+IF(F21="Sim",Legenda!$C$6,IF(F21="Parcial",Legenda!$C$7,0))+IF(G21="otool + Ghidra",Legenda!$C$8,IF(OR(G21="otool",G21="Ghidra",G21="Outro binário"),Legenda!$C$9,0))+MIN(Legenda!$C$11,MAX(0,J21-1)*Legenda!$C$10)))),1) | M21: A1-ghidra/Q-AP0-avc-mixer.md §2 | N21: — | O21: [2026-10-19] Fechado (R79); resolve o item 5 do §8 do reference (linha aux 5/6 = fb 0x08). | P21: =LEFT(A21,FIND(".",A21&".")-1)
A22: AP-0.4.1 | B22: AP-0.4 | C22: Pacote de status de 60 bytes | D22: GetControlPacketSize = 0x3C; NeedsControlPacketsForReadingHardwareControls = 1 (o Audiophile lê os controles do painel frontal pelos pacotes de controle). | E22: Parcial | F22: Não | G22: Ghidra | H22: Não | I22: FWAudiophileDevice::GetControlPacketSize @0xaf7e; NeedsControlPackets… @0xaa20 (Ghidra); snd-bebob bebob_maudio.c:58 METER_SIZE_AUDIOPHILE 60 | J22: =IF(TRIM(I22)="",0,LEN(I22)-LEN(SUBSTITUTE(I22,";",""))+1) | K22: Consistente | L22: =ROUND(IF(H22="Sim",MIN(Legenda!$C$12,MIN(10,IF(E22="Sim",Legenda!$C$4,IF(E22="Parcial",Legenda!$C$5,0))+IF(F22="Sim",Legenda!$C$6,IF(F22="Parcial",Legenda!$C$7,0))+IF(G22="otool + Ghidra",Legenda!$C$8,IF(OR(G22="otool",G22="Ghidra",G22="Outro binário"),Legenda!$C$9,0))+MIN(Legenda!$C$11,MAX(0,J22-1)*Legenda!$C$10))),IF(H22="Parcial",MIN(Legenda!$C$13,MIN(10,IF(E22="Sim",Legenda!$C$4,IF(E22="Parcial",Legenda!$C$5,0))+IF(F22="Sim",Legenda!$C$6,IF(F22="Parcial",Legenda!$C$7,0))+IF(G22="otool + Ghidra",Legenda!$C$8,IF(OR(G22="otool",G22="Ghidra",G22="Outro binário"),Legenda!$C$9,0))+MIN(Legenda!$C$11,MAX(0,J22-1)*Legenda!$C$10))),MIN(10,IF(E22="Sim",Legenda!$C$4,IF(E22="Parcial",Legenda!$C$5,0))+IF(F22="Sim",Legenda!$C$6,IF(F22="Parcial",Legenda!$C$7,0))+IF(G22="otool + Ghidra",Legenda!$C$8,IF(OR(G22="otool",G22="Ghidra",G22="Outro binário"),Legenda!$C$9,0))+MIN(Legenda!$C$11,MAX(0,J22-1)*Legenda!$C$10)))),1) | M22: A1-ghidra/Q-AP0-nub-and-rev2.md §2.5 | N22: — | P22: =LEFT(A22,FIND(".",A22&".")-1)
A23: AP-0.4.2 | B23: AP-0.4 | C23: Picos no pacote de status | D23: Quadlets 0–13 = picos (analog in 1–2, S/PDIF in 1–2, analog out 1–4, S/PDIF out 1–2, fones L/R, aux L/R): pico = 16 bits altos do quadlet big-endian → [+0x108][0..13]; slots 14–19 = retornos SW calculados no host ([+0x110]). | E23: Sim | F23: Não | G23: otool + Ghidra | H23: Não | I23: asm 0xba92-0xbb99; Ghidra UpdatePeakMeters @0x12aae; Apple IOFWReadQuadCommand.cpp:67 (sem swap); snd-bebob bebob_maudio.c:651-655; ctl-services normal.rs read_meter | J23: =IF(TRIM(I23)="",0,LEN(I23)-LEN(SUBSTITUTE(I23,";",""))+1) | K23: Consistente | L23: =ROUND(IF(H23="Sim",MIN(Legenda!$C$12,MIN(10,IF(E23="Sim",Legenda!$C$4,IF(E23="Parcial",Legenda!$C$5,0))+IF(F23="Sim",Legenda!$C$6,IF(F23="Parcial",Legenda!$C$7,0))+IF(G23="otool + Ghidra",Legenda!$C$8,IF(OR(G23="otool",G23="Ghidra",G23="Outro binário"),Legenda!$C$9,0))+MIN(Legenda!$C$11,MAX(0,J23-1)*Legenda!$C$10))),IF(H23="Parcial",MIN(Legenda!$C$13,MIN(10,IF(E23="Sim",Legenda!$C$4,IF(E23="Parcial",Legenda!$C$5,0))+IF(F23="Sim",Legenda!$C$6,IF(F23="Parcial",Legenda!$C$7,0))+IF(G23="otool + Ghidra",Legenda!$C$8,IF(OR(G23="otool",G23="Ghidra",G23="Outro binário"),Legenda!$C$9,0))+MIN(Legenda!$C$11,MAX(0,J23-1)*Legenda!$C$10))),MIN(10,IF(E23="Sim",Legenda!$C$4,IF(E23="Parcial",Legenda!$C$5,0))+IF(F23="Sim",Legenda!$C$6,IF(F23="Parcial",Legenda!$C$7,0))+IF(G23="otool + Ghidra",Legenda!$C$8,IF(OR(G23="otool",G23="Ghidra",G23="Outro binário"),Legenda!$C$9,0))+MIN(Legenda!$C$11,MAX(0,J23-1)*Legenda!$C$10)))),1) | M23: A1-ghidra/Q-AP0-status-packet-front-panel.md §2 | N23: — | O23: '16 bits altos do quadlet BE' supõe buffer cru na ordem do fio (UpdatePeakMeters faz o swap); conferir no asm. [2026-10-19] Fechado (R78): buffer em ordem do fio; ordem dos rótulos igual a snd-bebob e ctl-services. | P23: =LEFT(A23,FIND(".",A23&".")-1)
A24: AP-0.4.3 | B24: AP-0.4 | C24: Quadlet de status (offset 0x38) | D24: Palavra de status (bytes do fio w0..w3): w3≠0 = sync externo; w2 = código de taxa; w1 nibble baixo = encoder 1 (Level Controller), nibble alto = encoder 2 (fones), valores 1 = +1 detente, 2 = −1; w0 bits 4–7 ≠ 0 = botão A/B. | E24: Sim | F24: Não | G24: otool + Ghidra | H24: Não | I24: asm 0xba92-0xbb99; TRotaryControl::RotaryValueChanged @0xc2ba; ctor asm 0xbee0/0xbeea (passo 1); ctl-services normal.rs read_meter (rotaries/switch/sync) | J24: =IF(TRIM(I24)="",0,LEN(I24)-LEN(SUBSTITUTE(I24,";",""))+1) | K24: Consistente | L24: =ROUND(IF(H24="Sim",MIN(Legenda!$C$12,MIN(10,IF(E24="Sim",Legenda!$C$4,IF(E24="Parcial",Legenda!$C$5,0))+IF(F24="Sim",Legenda!$C$6,IF(F24="Parcial",Legenda!$C$7,0))+IF(G24="otool + Ghidra",Legenda!$C$8,IF(OR(G24="otool",G24="Ghidra",G24="Outro binário"),Legenda!$C$9,0))+MIN(Legenda!$C$11,MAX(0,J24-1)*Legenda!$C$10))),IF(H24="Parcial",MIN(Legenda!$C$13,MIN(10,IF(E24="Sim",Legenda!$C$4,IF(E24="Parcial",Legenda!$C$5,0))+IF(F24="Sim",Legenda!$C$6,IF(F24="Parcial",Legenda!$C$7,0))+IF(G24="otool + Ghidra",Legenda!$C$8,IF(OR(G24="otool",G24="Ghidra",G24="Outro binário"),Legenda!$C$9,0))+MIN(Legenda!$C$11,MAX(0,J24-1)*Legenda!$C$10))),MIN(10,IF(E24="Sim",Legenda!$C$4,IF(E24="Parcial",Legenda!$C$5,0))+IF(F24="Sim",Legenda!$C$6,IF(F24="Parcial",Legenda!$C$7,0))+IF(G24="otool + Ghidra",Legenda!$C$8,IF(OR(G24="otool",G24="Ghidra",G24="Outro binário"),Legenda!$C$9,0))+MIN(Legenda!$C$11,MAX(0,J24-1)*Legenda!$C$10)))),1) | M24: A1-ghidra/Q-AP0-status-packet-front-panel.md §2 | N24: — | O24: Ordem de bytes e qual encoder é o Level Controller: asm + ctl-services. [2026-10-19] Fechado (R78). Qual knob físico é o encoder 1: só no hardware (AP-7.7). | P24: =LEFT(A24,FIND(".",A24&".")-1)
A25: AP-0.4.4 | B25: AP-0.4 | C25: Comando vendor dos LEDs (A/B) | D25: LED A/B: CONTROL vendor-dependent de 16 bytes 00 FF 00 | 00 0D 6C | 02 00 01 <v> + zeros; v = 0 desligado, 1 = A, 2 = B (3 = outro estado). | E25: Sim | F25: Não | G25: otool + Ghidra | H25: Não | I25: asm 0xb7d0; asm 0x23970-0x23ad6 (AVCVendorCommand a,b,n,data); FWSettingsABSwitch::UpdateLEDs (Ghidra); ctl-services normal.rs AudiophileLedSwitch | J25: =IF(TRIM(I25)="",0,LEN(I25)-LEN(SUBSTITUTE(I25,";",""))+1) | K25: Consistente | L25: =ROUND(IF(H25="Sim",MIN(Legenda!$C$12,MIN(10,IF(E25="Sim",Legenda!$C$4,IF(E25="Parcial",Legenda!$C$5,0))+IF(F25="Sim",Legenda!$C$6,IF(F25="Parcial",Legenda!$C$7,0))+IF(G25="otool + Ghidra",Legenda!$C$8,IF(OR(G25="otool",G25="Ghidra",G25="Outro binário"),Legenda!$C$9,0))+MIN(Legenda!$C$11,MAX(0,J25-1)*Legenda!$C$10))),IF(H25="Parcial",MIN(Legenda!$C$13,MIN(10,IF(E25="Sim",Legenda!$C$4,IF(E25="Parcial",Legenda!$C$5,0))+IF(F25="Sim",Legenda!$C$6,IF(F25="Parcial",Legenda!$C$7,0))+IF(G25="otool + Ghidra",Legenda!$C$8,IF(OR(G25="otool",G25="Ghidra",G25="Outro binário"),Legenda!$C$9,0))+MIN(Legenda!$C$11,MAX(0,J25-1)*Legenda!$C$10))),MIN(10,IF(E25="Sim",Legenda!$C$4,IF(E25="Parcial",Legenda!$C$5,0))+IF(F25="Sim",Legenda!$C$6,IF(F25="Parcial",Legenda!$C$7,0))+IF(G25="otool + Ghidra",Legenda!$C$8,IF(OR(G25="otool",G25="Ghidra",G25="Outro binário"),Legenda!$C$9,0))+MIN(Legenda!$C$11,MAX(0,J25-1)*Legenda!$C$10)))),1) | M25: A1-ghidra/Q-AP0-status-packet-front-panel.md §4 | N25: — | O25: [2026-10-19] Fechado (R78). ctl-services: mesmos bytes significativos, enchimento FF FF (12 B). | P25: =LEFT(A25,FIND(".",A25&".")-1)
A26: AP-0.4.5 | B26: AP-0.4 | C26: Período de leitura do pacote de status | D26: Leitura de size/4 quadlets em 0xFFC7:0x00600000 a cada 50 ms após cada leitura completa; 1000 ms depois de erro; Pause/Resume contados. | E26: Parcial | F26: Não | G26: Ghidra | H26: Não | I26: FWHSCI::Start, HSCITimerFired, HSCIReadComplete, HSCISafelyComplete, Pause, Resume (Ghidra 2026-10-19) | J26: =IF(TRIM(I26)="",0,LEN(I26)-LEN(SUBSTITUTE(I26,";",""))+1) | K26: Consistente | L26: =ROUND(IF(H26="Sim",MIN(Legenda!$C$12,MIN(10,IF(E26="Sim",Legenda!$C$4,IF(E26="Parcial",Legenda!$C$5,0))+IF(F26="Sim",Legenda!$C$6,IF(F26="Parcial",Legenda!$C$7,0))+IF(G26="otool + Ghidra",Legenda!$C$8,IF(OR(G26="otool",G26="Ghidra",G26="Outro binário"),Legenda!$C$9,0))+MIN(Legenda!$C$11,MAX(0,J26-1)*Legenda!$C$10))),IF(H26="Parcial",MIN(Legenda!$C$13,MIN(10,IF(E26="Sim",Legenda!$C$4,IF(E26="Parcial",Legenda!$C$5,0))+IF(F26="Sim",Legenda!$C$6,IF(F26="Parcial",Legenda!$C$7,0))+IF(G26="otool + Ghidra",Legenda!$C$8,IF(OR(G26="otool",G26="Ghidra",G26="Outro binário"),Legenda!$C$9,0))+MIN(Legenda!$C$11,MAX(0,J26-1)*Legenda!$C$10))),MIN(10,IF(E26="Sim",Legenda!$C$4,IF(E26="Parcial",Legenda!$C$5,0))+IF(F26="Sim",Legenda!$C$6,IF(F26="Parcial",Legenda!$C$7,0))+IF(G26="otool + Ghidra",Legenda!$C$8,IF(OR(G26="otool",G26="Ghidra",G26="Outro binário"),Legenda!$C$9,0))+MIN(Legenda!$C$11,MAX(0,J26-1)*Legenda!$C$10)))),1) | M26: A1-ghidra/Q-AP0-status-packet-front-panel.md §1 | N26: — | O26: Ler FWHSCI::Start/timer com o tamanho 0x3C. [2026-10-19] Fechado (R78): mesma regra de 50 ms do 1814. | P26: =LEFT(A26,FIND(".",A26&".")-1)
A27: AP-0.5.1 | B27: AP-0.5 | C27: Layout do objeto FWAudiophileDevice | D27: Tamanho 0x17E0. 0x000–0x2cf base (0xe8 trava, 0xf8 dict, 0x108 página de picos, 0x110 picos do host, 0x118 MAClockSource, 0x268 unidade AV/C, 0x2c8 HSCI); 0x2d0 ABSwitch; 0x468 RotaryControl; 0x530 AuxSend; 0x808 Levels; 0x1268/0x126c passos; 0x1270 grupos (saídas 6, entradas 4, SW 6, fones 2, envios aux 10, aux out 2). | E27: Sim | F27: Não | G27: otool + Ghidra | H27: Não | I27: asm 0xb6c9 (alloc 0x17e0); ctor @0xc140; $_667 ctor; InitializeUserSettableProperties @0xb7e6; vtable 0x35680 slots 0xbc8/0xb48/0xb40/0xac8; FW32BitNumberProp::CallSetter | J27: =IF(TRIM(I27)="",0,LEN(I27)-LEN(SUBSTITUTE(I27,";",""))+1) | K27: Consistente | L27: =ROUND(IF(H27="Sim",MIN(Legenda!$C$12,MIN(10,IF(E27="Sim",Legenda!$C$4,IF(E27="Parcial",Legenda!$C$5,0))+IF(F27="Sim",Legenda!$C$6,IF(F27="Parcial",Legenda!$C$7,0))+IF(G27="otool + Ghidra",Legenda!$C$8,IF(OR(G27="otool",G27="Ghidra",G27="Outro binário"),Legenda!$C$9,0))+MIN(Legenda!$C$11,MAX(0,J27-1)*Legenda!$C$10))),IF(H27="Parcial",MIN(Legenda!$C$13,MIN(10,IF(E27="Sim",Legenda!$C$4,IF(E27="Parcial",Legenda!$C$5,0))+IF(F27="Sim",Legenda!$C$6,IF(F27="Parcial",Legenda!$C$7,0))+IF(G27="otool + Ghidra",Legenda!$C$8,IF(OR(G27="otool",G27="Ghidra",G27="Outro binário"),Legenda!$C$9,0))+MIN(Legenda!$C$11,MAX(0,J27-1)*Legenda!$C$10))),MIN(10,IF(E27="Sim",Legenda!$C$4,IF(E27="Parcial",Legenda!$C$5,0))+IF(F27="Sim",Legenda!$C$6,IF(F27="Parcial",Legenda!$C$7,0))+IF(G27="otool + Ghidra",Legenda!$C$8,IF(OR(G27="otool",G27="Ghidra",G27="Outro binário"),Legenda!$C$9,0))+MIN(Legenda!$C$11,MAX(0,J27-1)*Legenda!$C$10)))),1) | M27: A1-ghidra/Q-AP0-nub-and-rev2.md §4 | N27: — | O27: [2026-10-19] Fechado (R81); fecha o item 10 do §8 do reference. [2026-10-19] Correção R85: +0xe8 é o engine principal (pause/resumeAudioEngine), não uma trava. | P27: =LEFT(A27,FIND(".",A27&".")-1)
A28: AP-0.6.1 | B28: AP-0.6 | C28: Chaves MA* escritas pelo painel v1.9 | D28: 14 chaves em 266 escritas: MAInputRoutingV2, MAInputPan2, MAAuxSendLevels, MASWReturnLevels, MAHeadphoneSourceV2, MAMomentarySwitchRoutings, MAMomentarySwitchSource, MASWReturnMute, MASWReturnSolo, MASWReturnRoutingV2, MAMonitorAuxOnOutput, MAClockSource, MAGlobalMute, MAGlobalDim. | E28: Sim | F28: Sim | G28: Nenhum | H28: Não | I28: captura 90 (setProperties cru, SL v1.9, decodificada 2026-10-19); grep no kext do clone (MASWReturnMute/Solo sem tratador) | J28: =IF(TRIM(I28)="",0,LEN(I28)-LEN(SUBSTITUTE(I28,";",""))+1) | K28: Consistente | L28: =ROUND(IF(H28="Sim",MIN(Legenda!$C$12,MIN(10,IF(E28="Sim",Legenda!$C$4,IF(E28="Parcial",Legenda!$C$5,0))+IF(F28="Sim",Legenda!$C$6,IF(F28="Parcial",Legenda!$C$7,0))+IF(G28="otool + Ghidra",Legenda!$C$8,IF(OR(G28="otool",G28="Ghidra",G28="Outro binário"),Legenda!$C$9,0))+MIN(Legenda!$C$11,MAX(0,J28-1)*Legenda!$C$10))),IF(H28="Parcial",MIN(Legenda!$C$13,MIN(10,IF(E28="Sim",Legenda!$C$4,IF(E28="Parcial",Legenda!$C$5,0))+IF(F28="Sim",Legenda!$C$6,IF(F28="Parcial",Legenda!$C$7,0))+IF(G28="otool + Ghidra",Legenda!$C$8,IF(OR(G28="otool",G28="Ghidra",G28="Outro binário"),Legenda!$C$9,0))+MIN(Legenda!$C$11,MAX(0,J28-1)*Legenda!$C$10))),MIN(10,IF(E28="Sim",Legenda!$C$4,IF(E28="Parcial",Legenda!$C$5,0))+IF(F28="Sim",Legenda!$C$6,IF(F28="Parcial",Legenda!$C$7,0))+IF(G28="otool + Ghidra",Legenda!$C$8,IF(OR(G28="otool",G28="Ghidra",G28="Outro binário"),Legenda!$C$9,0))+MIN(Legenda!$C$11,MAX(0,J28-1)*Legenda!$C$10)))),1) | M28: captures/90-sl-audiophile-panel-setproperties-raw.txt | N28: AUD-AP-07 | O28: v1.9; cruzar com FWAudiophileDevice::InitializeUserSettableProperties (v1.11.2). [2026-10-19] Todas as 14 chaves aparecem no conjunto de cookies do painel v1.11.2 (R82). | P28: =LEFT(A28,FIND(".",A28&".")-1)
A29: AP-0.6.2 | B29: AP-0.6 | C29: Visão do painel (CXAudiophileDevice) | D29: Tipo do painel = 'FWDJ' (0x4657444A); classes CFWDJ* (settings, mixer, strip, output, fones, hardware, global, medidores) sobre as visões genéricas; 4 abas; contagens 10 saídas / 10 mixer / 4 entradas / 2 fones. | E29: Parcial | F29: Não | G29: Ghidra | H29: Não | I29: Ghidra cfwdj-audiophile-2026-10-19.txt (164 funções); CFWUniDeviceList::CreateNewDevice @0x6a9d6; CX*Device::GetDeviceType | J29: =IF(TRIM(I29)="",0,LEN(I29)-LEN(SUBSTITUTE(I29,";",""))+1) | K29: Consistente | L29: =ROUND(IF(H29="Sim",MIN(Legenda!$C$12,MIN(10,IF(E29="Sim",Legenda!$C$4,IF(E29="Parcial",Legenda!$C$5,0))+IF(F29="Sim",Legenda!$C$6,IF(F29="Parcial",Legenda!$C$7,0))+IF(G29="otool + Ghidra",Legenda!$C$8,IF(OR(G29="otool",G29="Ghidra",G29="Outro binário"),Legenda!$C$9,0))+MIN(Legenda!$C$11,MAX(0,J29-1)*Legenda!$C$10))),IF(H29="Parcial",MIN(Legenda!$C$13,MIN(10,IF(E29="Sim",Legenda!$C$4,IF(E29="Parcial",Legenda!$C$5,0))+IF(F29="Sim",Legenda!$C$6,IF(F29="Parcial",Legenda!$C$7,0))+IF(G29="otool + Ghidra",Legenda!$C$8,IF(OR(G29="otool",G29="Ghidra",G29="Outro binário"),Legenda!$C$9,0))+MIN(Legenda!$C$11,MAX(0,J29-1)*Legenda!$C$10))),MIN(10,IF(E29="Sim",Legenda!$C$4,IF(E29="Parcial",Legenda!$C$5,0))+IF(F29="Sim",Legenda!$C$6,IF(F29="Parcial",Legenda!$C$7,0))+IF(G29="otool + Ghidra",Legenda!$C$8,IF(OR(G29="otool",G29="Ghidra",G29="Outro binário"),Legenda!$C$9,0))+MIN(Legenda!$C$11,MAX(0,J29-1)*Legenda!$C$10)))),1) | M29: A2-panel/PNAP-control-key-map.md §1 | N29: — | O29: Decompilar os getters e quem consome GetDeviceType. [2026-10-19] Fechado (R82). Visual das telas (PPob) não lido: capturas de tela no rig SL (AP-0.9). | P29: =LEFT(A29,FIND(".",A29&".")-1)
A30: AP-0.7.1 | B30: AP-0.7 | C30: SetupAudioEngine do Audiophile | D30: 6 saídas / 4 entradas ([+0x2e0]=6, [+0x2e4]=4, [+0x2ec]=6, [+0x2f0]=4), MIDI 1 entrada/1 saída, [+0x2e8]=1, conversores _ConvertLLRR4SkipMIDI1 (entrada), _RearrangeSampleFrameLLRR6 (saída), _SamplePeaks6. | E30: Parcial | F30: Sim | G30: Ghidra | H30: Não | I30: FWAudiophileDevice::SetupAudioEngine @0xbb9a (Ghidra); captura 89 (6/4 canais, 1 porta MIDI) | J30: =IF(TRIM(I30)="",0,LEN(I30)-LEN(SUBSTITUTE(I30,";",""))+1) | K30: Consistente | L30: =ROUND(IF(H30="Sim",MIN(Legenda!$C$12,MIN(10,IF(E30="Sim",Legenda!$C$4,IF(E30="Parcial",Legenda!$C$5,0))+IF(F30="Sim",Legenda!$C$6,IF(F30="Parcial",Legenda!$C$7,0))+IF(G30="otool + Ghidra",Legenda!$C$8,IF(OR(G30="otool",G30="Ghidra",G30="Outro binário"),Legenda!$C$9,0))+MIN(Legenda!$C$11,MAX(0,J30-1)*Legenda!$C$10))),IF(H30="Parcial",MIN(Legenda!$C$13,MIN(10,IF(E30="Sim",Legenda!$C$4,IF(E30="Parcial",Legenda!$C$5,0))+IF(F30="Sim",Legenda!$C$6,IF(F30="Parcial",Legenda!$C$7,0))+IF(G30="otool + Ghidra",Legenda!$C$8,IF(OR(G30="otool",G30="Ghidra",G30="Outro binário"),Legenda!$C$9,0))+MIN(Legenda!$C$11,MAX(0,J30-1)*Legenda!$C$10))),MIN(10,IF(E30="Sim",Legenda!$C$4,IF(E30="Parcial",Legenda!$C$5,0))+IF(F30="Sim",Legenda!$C$6,IF(F30="Parcial",Legenda!$C$7,0))+IF(G30="otool + Ghidra",Legenda!$C$8,IF(OR(G30="otool",G30="Ghidra",G30="Outro binário"),Legenda!$C$9,0))+MIN(Legenda!$C$11,MAX(0,J30-1)*Legenda!$C$10)))),1) | M30: decomp/FWAudiophileDevice__SetupAudioEngine.c | N30: — | O30: Significado de [+0x2e8]=1: ler no FWBaseEngine. [2026-10-19] [+0x2e8] = m, quadlets MIDI por quadro (= fMidiChannels do clone, R87). | P30: =LEFT(A30,FIND(".",A30&".")-1)
