Workbook

Sheet Dashboard
A1: Broad compatibility plan v4 - OpenAudio BeBoB MAFW, OS X 10.9 to macOS 15 (Legacy 10.6.8-10.8.5 dropped, R130)
A2: 2026-10-21 (R129) - Modern edition works on macOS 14.8.9 Intel (Audiophile); Classic + Modern 0.3.0 packages built; DEC-5, DEC-9, DEC-10 answered. Legacy and Apple Silicon not started. 2026-10-21 - DEC-5 answered: three editions (Legacy / Classic / Modern); Modern Intel in progress on the dev Mac (loads and plays, R126); plan: BROAD_COMPATIBILITY_PLAN_v2.md
A4: Short answer
A5: One package / one version for 10.6.8-15 | B5: Yes, feasible (no checked fact forbids it)
A6: One binary per component | B6: No: kernel symbol generations (E-1, E-2), arm64e kext (E-6), Swift floor 10.9 (E-11)
A7: Kernel-extension builds in the package | B7: 2: Legacy (i386 + x86_64, 10.6 SDK) and Main (x86_64 10.13 SDK + arm64e 15 SDK in one file); 1 if U-12 holds
A8: As separate downloads | B8: Decided (DEC-5, user 2026-10-21): 3 editions - Legacy 10.6.8-10.8.5, Classic 10.9-10.15, Modern 11-15 (Intel, Apple Silicon later); plan v2 §11a
A9: What older OSes lose | B9: No audio / mixer / MIDI function expected; panel cosmetics on 10.6-10.8 (Feature_by_OS), or the whole panel if DEC-4 = c
A10: Recommendation | B10: Stage it: S1 (Intel 10.9-15), then S2 (Apple Silicon, needs hardware), S3 (10.6.8-10.8.5) only if wanted
A12: Effort by band (sessions; refreshes from Tasks)
A13: Band | B13: Meaning | C13: Tasks | D13: Min | E13: Max | F13: Done / partly
A14: C | B14: Common | C14: =COUNTIF(Tasks!$C$2:$C$200,A14) | D14: =SUMIFS(Tasks!$I$2:$I$200,Tasks!$C$2:$C$200,A14) | E14: =SUMIFS(Tasks!$J$2:$J$200,Tasks!$C$2:$C$200,A14) | F14: =COUNTIFS(Tasks!$C$2:$C$200,A14,Tasks!$G$2:$G$200,"Done*")+COUNTIFS(Tasks!$C$2:$C$200,A14,Tasks!$G$2:$G$200,"Partly done")
A15: M | B15: Intel 10.9-15 | C15: =COUNTIF(Tasks!$C$2:$C$200,A15) | D15: =SUMIFS(Tasks!$I$2:$I$200,Tasks!$C$2:$C$200,A15) | E15: =SUMIFS(Tasks!$J$2:$J$200,Tasks!$C$2:$C$200,A15) | F15: =COUNTIFS(Tasks!$C$2:$C$200,A15,Tasks!$G$2:$G$200,"Done*")+COUNTIFS(Tasks!$C$2:$C$200,A15,Tasks!$G$2:$G$200,"Partly done")
A16: AS | B16: Apple Silicon 11-15 | C16: =COUNTIF(Tasks!$C$2:$C$200,A16) | D16: =SUMIFS(Tasks!$I$2:$I$200,Tasks!$C$2:$C$200,A16) | E16: =SUMIFS(Tasks!$J$2:$J$200,Tasks!$C$2:$C$200,A16) | F16: =COUNTIFS(Tasks!$C$2:$C$200,A16,Tasks!$G$2:$G$200,"Done*")+COUNTIFS(Tasks!$C$2:$C$200,A16,Tasks!$G$2:$G$200,"Partly done")
A17: L | B17: 10.6.8-10.8.5 (DROPPED 2026-10-22) | C17: =COUNTIF(Tasks!$C$2:$C$200,A17) | D17: =SUMIFS(Tasks!$I$2:$I$200,Tasks!$C$2:$C$200,A17) | E17: =SUMIFS(Tasks!$J$2:$J$200,Tasks!$C$2:$C$200,A17) | F17: =COUNTIFS(Tasks!$C$2:$C$200,A17,Tasks!$G$2:$G$200,"Done*")+COUNTIFS(Tasks!$C$2:$C$200,A17,Tasks!$G$2:$G$200,"Partly done")
A18: Total | C18: =SUM(C14:C17) | D18: =SUM(D14:D17) | E18: =SUM(E14:E17) | F18: =SUM(F14:F17)
A20: Effort by scenario (sessions)
A21: Scenario | B21: Covers | C21: Bands | D21: Min | E21: Max
A22: S1 | B22: Intel 10.9-15 | C22: C + M | D22: =D14+D15 | E22: =E14+E15
A23: S2 | B23: S1 + Apple Silicon 11-15 | C23: C + M + AS | D23: =D14+D15+D16 | E23: =E14+E15+E16
A24: S3 | B24: WITHDRAWN (Legacy dropped) | C24: C + M + AS + L | D24: =D14+D15+D16+D17 | E24: =E14+E15+E16+E17
A25: S1 + L | B25: All Intel 10.6.8-15, no Apple Silicon | C25: C + M + L | D25: =D14+D15+D17 | E25: =E14+E15+E17
A26: Includes the on-device checks (BC-6), which run only on request: M 2, AS 1-2, L 1-2 sessions.
A28: Status
A29: Decisions open | C29: =COUNTIF(Decisions!$G$2:$G$100,"Open")
A30: Decisions answered | C30: =COUNTIF(Decisions!$G$2:$G$100,"Answered")
A31: Tasks waiting for a decision | C31: =COUNTIF(Tasks!$G$2:$G$200,"Waiting decision")
A32: Tasks done or partly done (static) | C32: =COUNTIF(Tasks!$G$2:$G$200,"Done*")+COUNTIF(Tasks!$G$2:$G$200,"Partly done")
A33: On-device tasks (on request / blocked) | C33: =COUNTIF(Tasks!$G$2:$G$200,"On request")+COUNTIF(Tasks!$G$2:$G$200,"Blocked (hardware)")
A34: Evidence checked (E-n) | C34: =COUNTIF(Evidence!$B$2:$B$200,"Checked")
A35: Claims still unverified (U-n) | C35: =COUNTIF(Evidence!$B$2:$B$200,"Unverified")
A37: Key findings of 2026-10-21
A38: E-1/E-2: the 0.2.2 kext imports _IOLockSleep_darwin14, _IOLockWakeup_darwin14 and IOService::configureReport/updateReport - names old kernels lack, so 10.6-10.8 need an old-SDK build.
A39: E-4: on macOS 14.8.4 Intel, 775 of the 777 imports are defined; the 2 others are reserved IOAudioEngine slots 15/16 (U-11).
A40: E-5: the FireWire and IOAudio kernel families ship for arm64e (Apple Silicon kernel caches, macOS 14.8.4 KDK), including the classic-DCL createLocalIsochPort.
A41: E-6: an arm64e IOAudio driver must implement driverDesiresHiResSampleIntervals().
A42: E-10: the 0.2.2 Swift 4.1 panel starts on Intel macOS 14.8.9 (demo mode).
A43: E-12: the M-Audio MIDI plug-in is x86_64 + i386 with minimum 10.7 - no arm64, and 10.6 is unverified.
A44: E-17 (R125): built with the macOS 15.2 SDK, the kext resolves 778 of 778 imports on the live 14.8.9 kernel (the reserved slots become the HiRes methods).
A45: E-18 (R126): the Modern kext loads on 14.8.9 Intel and plays through the FW Audiophile (TX 46/46 ms, no late callback); one dropout during real use, the adapter's FireWire controller left PCI first (cause open).
...

Sheet Tasks
A1: ID | B1: Phase | C1: Band | D1: Task | E1: Acceptance (how we know it is done) | F1: Depends on | G1: Status | H1: Who | I1: Min sessions | J1: Max sessions | K1: Plan ref | L1: Notes
A2: BC-1.1 | B2: 1 Static evidence | C2: C | D2: Symbol audit per kext build x OS: imports vs the KPI symbol sets and family exports of the oldest and newest OS of each band (SL rig 10.6.8 read-only copy, build PC 10.13.6, KDKs 10.9 / 11 / 15) | E2: A table build x OS with zero unexplained missing symbols | F2: DEC-1; SL rig reachable | G2: Partly done | H2: Claude | I2: 1 | J2: 2 | K2: §7 BC-1 | L2: 2026-10-21: E-1 (28 imports no reference build uses), E-3 (10.13.6 exports both lock names), E-4 (14.8.4 Intel: 2 of 777 missing = reserved slots 15/16). SL rig did not answer SSH.
A3: BC-1.2 | B3: 1 Static evidence | C3: C | D3: Confirm U-1, U-2, U-3, U-6 (K32 defaults, unsigned-kext policy per OS, kext location per OS, Tahoe ceiling) from Apple documentation, man pages and KDKs | E3: Every OS_Matrix cell has a source; U-1/2/3/6 closed or re-labelled | F3: — | G3: Waiting decision | H3: Claude | I3: 0.5 | J3: 1 | K3: §3, §7 BC-1
A4: BC-1.3 | B4: 1 Static evidence | C4: L | D4: i386 (ILP32) audit of the kext: pointer/UInt32 casts, mach_vm sizes, user-client struct layouts for 32- and 64-bit tasks, format strings | E4: List of findings with file:line; none left unclassified | F4: DEC-1 = a; DEC-2 | G4: Cancelled (scope, 2026-10-22: floor 10.9) | H4: Claude | I4: 0 | J4: 0 | K4: §7 BC-1
A5: BC-1.4 | B5: 1 Static evidence | C5: AS | D5: Apple Silicon audit of the kext: 16 KiB pages (TPacketPool 4096 packing, 4 KiB meter page, FWSharedSync 0x1000), AbsoluteTime units, pointer authentication on DCL CallProc / FWFunctor, IOCreateThread, inTaskWithPhysicalMask under DART, driverDesiresHiResSampleIntervals | E5: List of findings with file:line and the fix for each | F5: DEC-3 | G5: Waiting decision | H5: Claude | I5: 1 | J5: 1.5 | K5: §7 BC-1 | L5: Sites already known: TPacketPool.cpp:15-34, FWBaseEngine.cpp:179, FWDCLProgram.cpp:284-477, FWAVCAudioDevice.cpp:212, FWBusReset.cpp:5
A6: BC-1.5 | B6: 1 Static evidence | C6: C | D6: Header compile of the kext per SDK (-fsyntax-only): 10.6 SDK, 10.13 SDK, 15.2 SDK -arch arm64e | E6: Error list per SDK, each mapped to a BC-3 fix | F6: DEC-6 (10.6 SDK) | G6: Waiting decision | H6: Claude | I6: 0.5 | J6: 1 | K6: §7 BC-1
A7: BC-1.6 | B7: 1 Static evidence | C7: M | D7: Panel and Uninstaller API audit (availability per macOS version) | E7: API list with the OS each needs | F7: — | G7: Done (static) | H7: Claude | I7: 0 | J7: 0 | K7: §2 E-11 | L7: 2026-10-21: 5 panel APIs newer than 10.9; Swift floor 10.9
A8: BC-1.7 | B8: 1 Static evidence | C8: C | D8: MIDI plug-in audit (architectures, minimum OS) | E8: Architectures and LC_VERSION_MIN known | F8: — | G8: Done (static) | H8: Claude | I8: 0 | J8: 0 | K8: §2 E-12 | L8: 2026-10-21: x86_64 + i386, min 10.7. Open: U-7 (10.6), U-9 (Apple Silicon)
A9: BC-2.1 | B9: 2 Build system | C9: C | D9: Band-aware build files: kext/Makefile BAND=legacy|main|silicon (SDK, archs, min version, OA_BAND_* defines); helper universal; panel per slice | E9: make BAND=... produces each slice; the 0.2.2 Main build is byte-identical in behaviour (same flags) | F9: DEC-1, DEC-3, DEC-9 | G9: Done (classic, modern; legacy not built) | H9: Claude | I9: 1 | J9: 1 | K9: §7 BC-2 | L9: 2026-10-21: kext/Makefile BAND=classic|modern (R125); panel Makefile BAND -> Info.plist OAEdition, build/<band>/ (R127); legacy not built, no arm64e
A10: BC-2.2 | B10: 2 Build system | C10: L | D10: Legacy toolchain probe (P-2): Xcode 9.4.1 clang/ld + MacOSX10.6.sdk (its i386 libkmod) for an i386 + x86_64 kext; fallback Xcode 4.6.3 on a 10.8 volume | E10: An i386 + x86_64 kext links; kextutil -n -t passes on 10.6.8 | F10: DEC-1 = a; DEC-6 | G10: Cancelled (scope, 2026-10-22: floor 10.9) | H10: Claude | I10: 0 | J10: 0 | K10: §7 BC-2
A11: BC-2.3 | B11: 2 Build system | C11: AS | D11: Silicon toolchain: arm64e kext + arm64 user space with the CLT 15.2 SDK (libkmod arm64e, E-13) or Xcode 12+ on another Mac | E11: An arm64e kext and arm64 helper/panel build | F11: DEC-3; DEC-10 | G11: Waiting decision | H11: Claude | I11: 0.5 | J11: 1 | K11: §7 BC-2
A12: BC-2.4 | B12: 2 Build system | C12: C | D12: Merge and guards: lipo per component; per-slice LC_VERSION_MIN / LC_BUILD_VERSION guard; symbol-audit gate in the build; check-self-contained.sh for universal bundles | E12: A wrong-band symbol or slice fails the build | F12: BC-1.1, BC-2.1 | G12: Waiting decision | H12: Claude | I12: 1 | J12: 1.5 | K12: §7 BC-2
A13: BC-3.1 | B13: 3 Kernel | C13: C | D13: One OS gate in base/ (version_major); re-label each 10.13-forced deviation (VerifyStreamFormats R68 and the others in CLAUDE.md) with the OS range that forces it | E13: Every deviation comment names its OS range; conformance check passes | F13: BC-2.1 | G13: Waiting decision | H13: Claude | I13: 0.5 | J13: 1 | K13: §7 BC-3
A14: BC-3.2 | B14: 3 Kernel | C14: M | D14: Bind IOLockSleep/IOLockWakeup to the plain exported names (__asm label; 10.13.6 exports both, E-3) or use IOCommandGate::commandSleep; -D_FORTIFY_SOURCE=0 if U-5 fails | E14: nm -u of the Main build has no _darwin14 symbol; BC-1.1 clean for 10.9 | F14: BC-1.1 | G14: Not needed on 11-15; only for 10.9-10.12 | H14: Claude | I14: 0.5 | J14: 0.5 | K14: §7 BC-3
A15: BC-3.3 | B15: 3 Kernel | C15: M | D15: Reserved IOAudioEngine slots 15/16 on 11-15 (E-4, U-11): confirm kmutil patches them; otherwise build an 11+ x86_64 slice with a new SDK (third bundle) | E15: kextutil -n -t + a load on one Intel 11+ Mac, or the third bundle exists | F15: BC-6.1 | G15: Done (2026-10-21): 15.x SDK build loads on 14.8.9 (R126) | H15: Claude | I15: 0.5 | J15: 1 | K15: §7 BC-3 | L15: The Modern band is built with the 15.x SDK (BAND=modern): 778/778 resolve (E-17) and it loads (E-18). No kmutil patching needed; the Modern edition is the separate 11+ build
A16: BC-3.4 | B16: 3 Kernel | C16: L | D16: Legacy build: fix what BC-1.5 / BC-1.3 found; Info.plist with KPI library names (per-arch keys only if needed, reference pattern OSBundleLibraries_x86_64) | E16: Legacy kext links for i386 + x86_64; BC-1.1 clean for 10.6.8 | F16: BC-2.2, BC-1.3, BC-1.5 | G16: Cancelled (scope, 2026-10-22: floor 10.9) | H16: Claude | I16: 0 | J16: 0 | K16: §7 BC-3
A17: BC-3.5 | B17: 3 Kernel | C17: AS | D17: Silicon build: implement driverDesiresHiResSampleIntervals (+ useHiResSampleInterval / calculateSampleTimeoutHiRes as documented) and the BC-1.4 fixes; comments say 'forced by the arm64 IOAudioEngine header' | E17: arm64e kext links; BC-1.1 clean against an arm64e KDK | F17: BC-1.4, BC-2.3 | G17: Waiting decision | H17: Claude | I17: 2 | J17: 4 | K17: §7 BC-3
A18: BC-3.6 | B18: 3 Kernel | C18: C | D18: Bundle layout per band: same bundle id and personalities; Main file = x86_64 + arm64e | E18: Both bundles pass plutil and kextutil -n -t on a host of their band | F18: BC-3.2, BC-3.4, BC-3.5 | G18: Not needed (two kext builds, DEC-5 = b) | H18: Claude | I18: 0.5 | J18: 0.5 | K18: §7 BC-3
A19: BC-4.1 | B19: 4 User space | C19: C | D19: Helper universal: i386 + x86_64 (Xcode 9.4.1, min 10.6) + arm64 (min 11), lipo; no API change (E-14) | E19: lipo -archs shows the slices; each slice's min version matches its band | F19: BC-2.1 | G19: Waiting decision | H19: Claude | I19: 0.5 | J19: 0.5 | K19: §7 BC-4
A20: BC-4.2 | B20: 4 User space | C20: M | D20: Swift panel to 10.9: #available fallbacks for the 5 APIs (E-11), deployment target 10.9; Uninstaller likewise | E20: Typecheck at -target x86_64-apple-macosx10.9; --demo --snapshot PNGs unchanged on 10.13 | F20: BC-2.1 | G20: Not needed on 11-15 (panel runs on 14.8.9); only for 10.9-10.12 | H20: Claude | I20: 1 | J20: 2 | K20: §7 BC-4
A21: BC-4.3 | B21: 4 User space | C21: AS | D21: Panel and Uninstaller arm64 slice: same sources with a Swift 5 compiler (-swift-version 4.2 if needed), lipo with the Swift 4.1 x86_64 slice; bundle-swift-runtime.sh universal-aware | E21: Universal app passes check-self-contained; --demo --snapshot on arm64 and x86_64 | F21: BC-2.3, BC-4.2 | G21: Waiting decision | H21: Claude | I21: 0.5 | J21: 1 | K21: §7 BC-4
A22: BC-4.4 | B22: 4 User space | C22: L | D22: Panel port to Objective-C (DEC-4 a), file by file, host tests ported; replaces the Swift panel everywhere (one universal binary, no Swift runtime) | E22: Demo snapshots match the Swift panel's on 10.13; app launches on 10.6.8 | F22: DEC-4 = a | G22: Cancelled (scope, 2026-10-22: floor 10.9) | H22: Claude | I22: 0 | J22: 0 | K22: §7 BC-4 | L22: Largest single item: 5,925 Swift lines (E-16)
A23: BC-4.5 | B23: 4 User space | C23: L | D23: Uninstaller for 10.6-10.8 (Obj-C with BC-4.4, or an AppleScript applet) | E23: Runs on 10.6.8 and removes every listed path | F23: BC-5.3 | G23: Cancelled (scope, 2026-10-22: floor 10.9) | H23: Claude | I23: 0 | J23: 0 | K23: §7 BC-4
A24: BC-4.6 | B24: 4 User space | C24: AS | D24: MIDI clone plug-in mirroring the M-Audio plug-in (A3 decompiles, user-client selectors 500-507), universal | E24: MIDI in/out through the clone on one Intel Mac matches the original (midiprobe) | F24: DEC-8 | G24: Waiting decision | H24: Claude | I24: 4 | J24: 8 | K24: §7 BC-4
A25: BC-4.7 | B25: 4 User space | C25: L | D25: MIDI on 10.6: check the 1.11.2 plug-in's imports against the 10.6.8 frameworks (U-7); otherwise ship the clone there | E25: U-7 closed | F25: BC-1.1 | G25: Cancelled (scope, 2026-10-22: floor 10.9) | H25: Claude | I25: 0 | J25: 0 | K25: §7 BC-4
A26: BC-5.1 | B26: 5 Installer | C26: C | D26: distribution.xml: min 10.6.8 (or the DEC-1 floor), hostArchitectures i386,x86_64,arm64, OS-conditional choices for the kext bundle/location and MIDI plug-in | E26: pkgutil --payload-files per choice; Installer picks the right bundle on each band | F26: DEC-1, DEC-5 | G26: Done for Classic + Modern (per-edition distribution.xml, R128) | H26: Claude | I26: 0.5 | J26: 1 | K26: §7 BC-5 | L26: 2026-10-21 (R128): one package per edition instead of OS-conditional choices (DEC-5 b): Classic min 10.13 before 11.0, Modern min 11.0 before 16.0; checked with installer -volinfo on 14.8.9 and 10.13.6
A27: BC-5.2 | B27: 5 Installer | C27: C | D27: postinstall per band: caches (touch /S/L/E + kextcache on L; -system-caches on M; kmutil flow + approval/restart message on M11/AS); keep the kextutil -t -n gate; MIDIServer restart | E27: Script review per band; the gate runs on all bands | F27: BC-5.1 | G27: Done for Classic + Modern (R128); Modern uninstall unverified | H27: Claude | I27: 1 | J27: 1.5 | K27: §7 BC-5 | L27: 2026-10-21 (R128): postinstall-modern = kmutil import gate (shipped imports.txt) + kmutil load -p + helper + agent + MIDIServer; Classic postinstall unchanged; Legacy not done
A28: BC-5.3 | B28: 5 Installer | C28: C | D28: uninstall.sh: add /System/Library/Extensions/OpenAudioBeBoBMAFW.kext and every new path (all-paths-ever rule kept) | E28: Dry-run listing covers every payload path of every band | F28: BC-5.1 | G28: Done for Classic + Modern (kmutil rebuild branch, unverified) | H28: Claude | I28: 0.5 | J28: 0.5 | K28: §7 BC-5 | L28: 2026-10-21 (R128): uninstall.sh runs kmutil rebuild on 11+ (unverified), kextcache on 10.x
A29: BC-5.4 | B29: 5 Installer | C29: C | D29: Installer pages + README: per-band prerequisites (10.10 boot-arg, 10.11+ SIP, 11+ approval, Apple Silicon Permissive Security) - documentation only | E29: Text reviewed by the user | F29: BC-1.2 | G29: Done for Classic + Modern (Requirements tables, R128) | H29: Claude | I29: 0.5 | J29: 0.5 | K29: §7 BC-5 | L29: 2026-10-21 (R128): Requirements per edition on the installer pages and dmg backgrounds; README pending
A30: BC-6.1 | B30: 6 On-device (on request) | C30: M | D30: P-1: Main kext on one Intel 11-15 Mac (kextutil -n -t, load, CoreAudio, play/record, panel); also U-8, U-11, U-12 with the Legacy build | E30: Results recorded in a dated run log | F30: DEC-7; user request | G30: Partly done (Audiophile plays on 14.8.9; FW1814, record, MIDI, rates open) | H30: User + Claude | I30: 1 | J30: 1 | K30: §7 BC-6, §8 | L30: A panic reboots the host | 2026-10-21 (R126): load + play on 14.8.9 Intel with the FW Audiophile (E-18); one dropout in real use (adapter controller left PCI, cause open). Open: record/RX, panel controls (U-8), MIDI, rates, FW1814, unload, sleep
A31: BC-6.2 | B31: 6 On-device (on request) | C31: M | D31: Main kext on one of 10.9-10.12 | E31: Dated run log | F31: DEC-7; user request | G31: On request | H31: User + Claude | I31: 1 | J31: 1 | K31: §7 BC-6
A32: BC-6.3 | B32: 6 On-device (on request) | C32: L | D32: Legacy kext on 10.6.8, K32 and K64, on a volume other than the SL rig's reference install | E32: Dated run log | F32: DEC-7; user request | G32: Cancelled (scope, 2026-10-22: floor 10.9) | H32: User + Claude | I32: 0 | J32: 0 | K32: §7 BC-6
A33: BC-6.4 | B33: 6 On-device (on request) | C33: AS | D33: Apple Silicon with the TB3->TB2 and TB->FW800 adapters (U-10, U-14) | E33: Dated run log | F33: DEC-3, DEC-7; hardware | G33: Blocked (hardware) | H33: User + Claude | I33: 1 | J33: 2 | K33: §7 BC-6 | L33: No Apple Silicon Mac in the inventory
A34: BC-7.1 | B34: 7 Release | C34: C | D34: README compatibility table (verified / untested per band), NOTICE, CHANGELOG, VERSION (0.3.0 proposed), docs/ARCHITECTURE_MAFW_v2.md, /close-item | E34: README states each band's status honestly | F34: all of the chosen scenario | G34: Waiting decision | H34: Claude | I34: 1 | J34: 1 | K34: §7 BC-7

Sheet Decisions
A1: ID | B1: Question | C1: Options | D1: Recommendation | E1: Why / consequence | F1: Gates | G1: Status | H1: Answer (user, with date)
A2: DEC-1 | B2: Lowest OS to support | C2: a) 10.6.8 (as asked; adds band L) b) 10.9 (no old toolchain; Swift panel kept) c) keep 10.13, extend upward only | D2: b now; a later if wanted | E2: Band L costs 11.5-21.5 sessions, mostly the panel port; official M-Audio drivers already run 10.6.8 (v1.9, SL rig) and, per B3, up to 10.11 | F2: BC-1.3, BC-2.2, BC-3.4, BC-4.4/4.5/4.7, BC-5.1, BC-6.3 | G2: Answered | H2: b) lowest OS 10.9 (user, 2026-10-22: "the older ones work well on official drivers")
A3: DEC-2 | B3: 32-bit kernel (i386 kext slice) for 10.6/10.7 Macs booted K32 | C3: yes / no | D3: yes if DEC-1 = a | E3: Without it, 10.6 Macs must boot the 64-bit kernel; 32-bit-EFI Macs cannot (U-1) | F3: BC-1.3, BC-2.2, BC-3.4 | G3: Answered | H3: Moot (no i386 slice; Legacy dropped, 2026-10-22)
A4: DEC-3 | B4: Apple Silicon in scope | C4: yes (Apple Silicon Mac + TB3->TB2 + TB->FW800 adapters, Permissive Security, MIDI clone) / no | D4: yes as stage S2 once hardware exists | E4: Kernel families exist on arm64e in macOS 14.8.4 (E-5); hardware path unproven (U-10) | F4: BC-1.4, BC-2.3, BC-3.5, BC-4.3, BC-4.6, BC-6.4 | G4: Open
A5: DEC-4 | B5: Control panel on 10.6-10.8 | C5: a) Objective-C port: one panel for every OS b) Swift 10.9+ plus a separate Obj-C legacy panel c) no panel on 10.6-10.8 | D5: a if DEC-1 = a | E5: b doubles the UI code; c loses mixer, routing, clock and firmware-check UI on 10.6-10.8 | F5: BC-4.4, BC-4.5 | G5: Answered | H5: Moot (Swift panel kept; no Obj-C port; 2026-10-22)
A6: DEC-5 | B6: Packaging | C6: a) one package, OS-conditional choices b) three editions (Legacy / Classic / Modern) | D6: a | E6: Same code either way; a = one download and one version per release | F6: BC-5.1 | G6: Answered | H6: b) three editions: Legacy 10.6.8-10.8.5, Classic 10.9-10.15, Modern 11-15 (user, 2026-10-21, R125; plan v2 §11a)
A7: DEC-6 | B7: Source of the 10.6 SDK (band L) | C7: Apple developer downloads (Xcode 3.2.6 / 4.x, the user's Apple ID) | D7: user action | E7: Modern SDKs have no i386 libkmod (E-13) and their x86_64 headers produce symbols 10.6 lacks (E-1, E-2) | F7: BC-1.5, BC-2.2 | G7: Answered | H7: Moot (no 10.6 SDK needed; 2026-10-22)
A8: DEC-7 | B8: Test hosts per band, and whether any BC-6 check happens | C8: SL rig second volume (10.6.8); iMac11,2 extra volume; MacBookAir5,1 (10.14/10.15); dev Mac (11-14); none | D8: the user's call | E8: No formal testing (R123): bands nobody loaded ship labelled untested | F8: BC-6.1 to BC-6.4 | G8: Open | H8: Partly (user, 2026-10-21): the dev Mac (MacBookAir7,2, 14.8.9) for Modern Intel; other bands open
A9: DEC-8 | B9: MIDI on Apple Silicon | C9: a) clone plug-in (Apple Silicon only) b) clone everywhere c) no MIDI on Apple Silicon | D9: a | E9: An arm64e MIDIServer cannot load the x86_64/i386 M-Audio plug-in in-process (U-9); a keeps Intel unchanged | F9: BC-4.6 | G9: Open
A10: DEC-9 | B10: Where the work lives; version numbers | C10: branch of openaudio-mafw-bebob / new folder; package 0.3.0, driver 0.3.0 | D10: branch; 0.3.0 | E10: openaudio-fw1814/ stays frozen; band builds share one tree | F10: BC-2.1, BC-7.1 | G10: Answered | H10: Same tree openaudio-mafw-bebob, BAND=classic|modern; package 0.3.0, driver 0.2.1 (R128, 2026-10-21)
A11: DEC-10 | B11: Build arm64e/arm64 slices on the dev Mac | C11: allow CLT builds there (CLAUDE.md keeps it edit-only) / use another Mac | D11: the user's call | E11: The dev Mac's CLT 15.2 SDK has arm64e libkmod (E-13) | F11: BC-2.3 | G11: Answered | H11: Modern kext is built on the dev Mac (CLT 15.2 SDK, R125-R128); Apple Silicon slices not built

Sheet OS_Matrix
A1: OS | B1: Name | C1: Darwin (version_major) | D1: Band | E1: Kernel arch | F1: Kext build | G1: Kext location | H1: Unsigned-kext prerequisite | I1: Cache / load tool | J1: IOAudioFamily | K1: IOFireWireFamily | L1: AppleFWAudio.kext | M1: Panel | N1: MIDI plug-in | O1: Project host | P1: Facts status | Q1: Source
A2: 10.6.8 | B2: Snow Leopard | C2: 10 | D2: L | E2: i386 (K32, default on most Macs, U-1) or x86_64 | F2: Legacy i386 + x86_64 | G2: /System/Library/Extensions (U-3) | H2: none (U-2) | I2: touch /S/L/E + kextcache | J2: — | K2: — | L2: unverified | M2: Obj-C port or none (DEC-4) | N2: original if U-7 holds, else clone | O2: SL rig (keep v1.9 install: separate volume); iMac11,2 | P2: Unverified except: v1.9 runs here (SL rig) | Q2: U-1, U-2, U-3, U-7
A3: 10.7.5 | B3: Lion | C3: 11 | D3: L | E3: x86_64 (K32 on some Macs, U-1) | F3: Legacy i386 + x86_64 | G3: /System/Library/Extensions (U-3) | H3: none (U-2) | I3: touch /S/L/E + kextcache | J3: — | K3: — | L3: unverified | M3: Obj-C port or none | N3: original (min 10.7, E-12) | O3: iMac11,2; MacBookAir5,1 (recalled ranges) | P3: Unverified | Q3: U-1, U-2, U-3
A4: 10.8.5 | B4: Mountain Lion | C4: 12 | D4: L | E4: x86_64 | F4: Legacy i386 + x86_64 (x86_64 used) | G4: /System/Library/Extensions (U-3) | H4: none (U-2) | I4: touch /S/L/E + kextcache | J4: — | K4: — | L4: unverified | M4: Obj-C port or none | N4: original | O4: iMac11,2; MacBookAir5,1 | P4: Unverified | Q4: U-2, U-3
A5: 10.9.5 | B5: Mavericks | C5: 13 | D5: M | E5: x86_64 | F5: Main x86_64 (after BC-3.2; U-4) | G5: /Library/Extensions | H5: unverified (U-2) | I5: kextcache -system-caches | J5: — | K5: — | L5: unverified | M5: Swift (after BC-4.2) | N5: original | O5: iMac11,2; MacBookAir5,1 | P5: Unverified | Q5: U-2, U-4, U-5
A6: 10.10.5 | B6: Yosemite | C6: 14 | D6: M | E6: x86_64 | F6: Main x86_64 | G6: /Library/Extensions | H6: boot-arg kext-dev-mode=1 (U-2) | I6: kextcache -system-caches | J6: — | K6: — | L6: unverified | M6: Swift (after BC-4.2) | N6: original | O6: iMac11,2; MacBookAir5,1 | P6: Unverified | Q6: U-2, U-5
A7: 10.11.6 | B7: El Capitan | C7: 15 | D7: M | E7: x86_64 | F7: Main x86_64 | G7: /Library/Extensions | H7: SIP off or --without kext (U-2) | I7: kextcache -system-caches | J7: — | K7: — | L7: unverified | M7: Swift (after BC-4.2) | N7: original | O7: iMac11,2; MacBookAir5,1 | P7: Unverified | Q7: U-2, U-5
A8: 10.12.6 | B8: Sierra | C8: 16 | D8: M | E8: x86_64 | F8: Main x86_64 | G8: /Library/Extensions | H8: SIP off (U-2) | I8: kextcache -system-caches | J8: — | K8: — | L8: unverified | M8: Swift (after BC-4.2) | N8: original | O8: iMac11,2; MacBookAir5,1 | P8: Unverified | Q8: U-2, U-5
A9: 10.13.6 | B9: High Sierra | C9: 17 | D9: M | E9: x86_64 | F9: Main x86_64 (= today's build) | G9: /Library/Extensions | H9: SIP off (verified by the project) | I9: kextcache -system-caches | J9: 206.5 (E-8) | K9: 4.7.2 (E-8) | L9: present (E-8) | M9: Swift (today) | N9: original (today) | O9: build PC; MacBook Air (today) | P9: Verified (0.2.2 in use) | Q9: E-3, E-8, E-9
A10: 10.14.6 | B10: Mojave | C10: 18 | D10: M | E10: x86_64 | F10: Main x86_64 | G10: /Library/Extensions | H10: SIP off (U-2) | I10: kextcache -system-caches | J10: — | K10: — | L10: unverified | M10: Swift | N10: original | O10: MacBookAir5,1 | P10: Unverified | Q10: U-2
A11: 10.15.7 | B11: Catalina | C11: 19 | D11: M | E11: x86_64 | F11: Main x86_64 | G11: /Library/Extensions (system volume read-only) | H11: SIP off (U-2) | I11: kextcache -i / | J11: — | K11: — | L11: unverified | M11: Swift | N11: original | O11: MacBookAir5,1 | P11: Unverified | Q11: U-2
A12: 11 (Intel) | B12: Big Sur | C12: 20 | D12: M11 | E12: x86_64 | F12: Modern x86_64 (15.x SDK) | G12: /Library/Extensions -> auxiliary KC | H12: SIP off; approval + restart (U-2) | I12: kmutil (kextutil -n -t for the gate) | J12: — | K12: — | L12: unverified | M12: Swift (E-10 on 14) | N12: original (U-8) | O12: dev Mac (supports up to 12, recalled) | P12: Unverified | Q12: U-2, U-8, U-11
A13: 12 (Intel) | B13: Monterey | C13: 21 | D13: M11 | E13: x86_64 | F13: Modern x86_64 (15.x SDK) | G13: /Library/Extensions -> auxiliary KC | H13: SIP off; approval + restart (U-2) | I13: kmutil | J13: — | K13: — | L13: unverified | M13: Swift | N13: original (U-8) | O13: dev Mac | P13: Unverified | Q13: U-2, U-8, U-11
... A16: 15 (Intel) | B16: Sequoia | C16: 24 | D16: M11 | E16: x86_64 | F16: Modern x86_64 (15.x SDK) | G16: /Library/Extensions -> auxiliary KC | H16: SIP off; approval + restart (U-2) | I16: kmutil | J16: — | K16: — | L16: unverified | M16: Swift | N16: original (U-8) | O16: none | P16: Unverified | Q16: U-2, U-8, U-11
A17: 11-15 (Apple Silicon) | B17: Big Sur ... Sequoia | C17: 20-24 | D17: AS | E17: arm64e | F17: Main arm64e slice (BC-3.5) | G17: /Library/Extensions -> auxiliary KC | H17: Permissive Security + user-managed kexts; approval + restart (U-2) | I17: kmutil | J17: arm64e build exists (E-5) | K17: arm64e build exists (E-5) | L17: absent in kernelcache manifests (E-5 lists no AppleFWAudio) | M17: arm64 slice (BC-4.3) | N17: clone (DEC-8, U-9) | O17: none (needs hardware + 2 adapters) | P17: Families verified present (static); hardware path unverified | Q17: E-5, E-6, U-9, U-10, U-14
A18: 26 | B18: Tahoe | C18: 25 | D18: — | E18: — | F18: out of scope | G18: — | H18: — | I18: — | J18: — | K18: no FireWire stack (U-6) | L18: — | M18: — | N18: — | O18: — | P18: Unverified (macfw statement) | Q18: U-6

Sheet Feature_by_OS
A1: Feature | B1: 10.6.8-10.8.5 (L) | C1: 10.9-10.12 (M) | D1: 10.14-10.15 (M) | E1: 11-15 Intel (M11) | F1: 11-15 Apple Silicon (AS) | G1: Evidence / settle by
A2: Audio I/O, all rates 44.1-192 kHz, S/PDIF / ADAT / S/MUX | B2: Same (v1.9 does it on 10.6.8; ours unverified) | C2: Same (unverified) | D2: Same (unverified) | E2: Same (unverified) | F2: unverified | G2: U-10, U-11, U-13, U-14
A3: 32-bit kernel (K32) Macs | B3: needs the i386 slice (DEC-2) | C3: n/a | D3: n/a | E3: n/a | F3: n/a | G3: U-1
A4: Mixer, routing, levels, encoders, helper settings replay | B4: Same | C4: Same | D4: Same | E4: Same | F4: unverified | G4: E-14
A5: Meters (shared 4 KiB page) | B5: Same | C5: Same | D5: Same | E5: Same | F5: 16 KiB page review | G5: U-14, BC-1.4
A6: MIDI in/out | B6: Same if U-7 holds, else clone | C6: Same | D6: Same | E6: Same (U-8) | F6: LOST unless the clone exists | G6: U-7, U-9, DEC-8
A7: Control panel | B7: LOST if DEC-4 = c; = with the Obj-C port | C7: Same (fallbacks, E-11) | D7: Same | E7: Same (E-10, demo) | F7: Same with arm64 slice | G7: E-10, E-11
A8: Panel: dark vibrant title bar | B8: lost (10.10+) | C8: lost on 10.9 | D8: Same | E8: Same | F8: Same | G8: E-11
A9: Panel: tabular-digit system font | B9: fallback | C9: fallback on 10.9-10.10 | D9: Same | E9: Same | F9: Same | G9: E-11
A10: Panel: GPU-only meter updates | B10: fallback on 10.6-10.7 (CPU drawing) | C10: Same | D10: Same | E10: Same | F10: Same | G10: wantsUpdateLayer 10.8+
A11: Panel: Retina | B11: lost on 10.6 (10.7.3+) | C11: Same | D11: Same | E11: Same | F11: Same | G11: recalled
A12: Panel: Big Meter full screen | B12: lost on 10.6 (10.7+) | C12: Same | D12: Same | E12: Same | F12: Same | G12: recalled
... A14: CoreAudio listeners | B14: fallback on 10.6 (C callbacks) | C14: Same | D14: Same | E14: Same | F14: Same | G14: AudioHardware.h:397 (10.7)
A15: Firmware check window (read-only) | B15: Same with the port | C15: Same | D15: Same | E15: Same | F15: Same
A16: Uninstall app | B16: needs a port | C16: fallbacks | D16: Same | E16: Same | F16: arm64 slice or Rosetta | G16: E-11
A17: Install steps | B17: kext in /System/Library/Extensions; no prerequisite | C17: 10.10 boot-arg; 10.11+ SIP off | D17: SIP off | E17: SIP off + approval + restart | F17: Permissive Security + approval + restart | G17: U-2, U-3

Sheet Components
A1: Component | B1: Today (0.2.2) | C1: Band L (10.6.8-10.8.5) | D1: Band M (10.9-10.15) | E1: Band M11 (11-15 Intel) | F1: Band AS (11-15 Apple Silicon) | G1: Builds needed | H1: Tasks
A2: Kernel extension | B2: x86_64, Xcode 9.4.1, 10.13 SDK, min 10.13 (E-9) | C2: Legacy build: i386 + x86_64, 10.6 SDK | D2: Main x86_64 (10.13 SDK) + BC-3.2 | E2: same Main x86_64 slice (U-11) | F2: arm64e slice in the Main file, 15 SDK, + BC-3.5 | G2: 2 (Legacy, Main); 1 if U-12 holds; 3 if BC-3.3 fails | H2: BC-1.1/1.3/1.4/1.5, BC-2.x, BC-3.x
A3: Helper daemon (C) | B3: x86_64, min 10.13 | C3: i386 + x86_64 slice, min 10.6 | D3: same | E3: same | F3: arm64 slice, min 11 | G3: 1 universal binary | H3: BC-4.1
A4: Control panel | B4: Swift 4.1, x86_64, bundled runtime, min 10.13 | C4: Obj-C port (DEC-4 a) or none | D4: Swift min 10.9 (BC-4.2) or the Obj-C port | E4: same | F4: arm64 slice (Swift 5) or the Obj-C port | G4: 1 (Obj-C port) or 1 Swift universal + nothing on L | H4: BC-4.2, BC-4.3, BC-4.4
A5: Uninstall app | B5: Swift 4.1, x86_64 | C5: Obj-C / AppleScript | D5: Swift min 10.9 | E5: same | F5: arm64 slice | G5: 1-2 | H5: BC-4.2, BC-4.3, BC-4.5
A6: CoreMIDI plug-in | B6: M-Audio 1.11.2 original, x86_64 + i386, min 10.7 (E-12) | C6: original if U-7 holds, else clone | D6: original | E6: original (U-8) | F6: clone (DEC-8) | G6: 1 (original) + 1 (clone) if AS | H6: BC-4.6, BC-4.7
A7: Installer package | B7: min 10.13, hostArchitectures x86_64 (E-9) | C7: choice: Legacy kext -> /System/Library/Extensions | D7: choice: Main kext -> /Library/Extensions | E7: same + kmutil message | F7: same + Permissive Security text | G7: 1 package (Option A) | H7: BC-5.x
A8: Disk image | B8: UDZO + HFS+ (E-15) | C8: opens on 10.6 | D8: same | E8: same | F8: same | G8: 1 | H8: —
A9: Bench tools (not shipped) | B9: C, x86_64 | C9: rebuild per band only when needed | D9: same | E9: same | F9: arm64 if needed | G9: on demand | H9: —

Sheet Evidence
A1: ID | B1: Kind | C1: Statement | D1: How checked / how to settle | E1: File or source | F1: Date | G1: Feeds
A2: E-1 | B2: Checked | C2: 0.2.2 kext imports 777 symbols; 28 imported by no reference build, incl. _IOLockSleep_darwin14, _IOLockWakeup_darwin14, IOService::configureReport/updateReport, ___memmove_chk, ___strlcat_chk | D2: nm -u of the 0.2.2 payload and of v1.9 / v1.10.5 / v1.11.3 | E2: evidence/kext-0.2.2-imports*.txt | F2: 2026-10-21 | G2: §1, BC-1.1, BC-3.2
A3: E-2 | B3: Checked | C3: Modern SDKs alias IOLockSleep / IOLockSleepDeadline / IOLockWakeup to _darwin14 names on x86_64 regardless of deployment target | D3: Read the SDK headers | E3: MacOSX13.3.sdk sys/cdefs.h:514-519; IOKit/IOLocks.h:129,132,134 | F3: 2026-10-21 | G3: BC-3.2
A4: E-3 | B4: Checked | C4: 10.13.6 KPI symbol sets export both plain and _darwin14 lock names, ___memmove_chk, ___strlcat_chk, _version_major, _kernel_thread_start, _thread_call_allocate, _IOCreateThread | D4: read-only nm on the build PC | E4: evidence/buildpc-10.13.6-kpi-exports.txt | F4: 2026-10-21 | G4: BC-3.1, BC-3.2
A5: E-4 | B5: Checked | C5: macOS 14.8.4 Intel: all but 2 of 777 imports defined; missing IOAudioEngine::_RESERVEDIOAudioEngine15/16 (now calculateSampleTimeoutHiRes / useHiResSampleInterval) | D5: KDK 14.8.4 kernel + family dSYMs; 15.2 SDK IOAudioEngine.h:389,403,431-432 | E5: evidence/kext-0.2.2-vs-macos-14.8.4-x86_64.txt | F5: 2026-10-21 | G5: BC-3.3, U-11
A6: E-5 | B6: Checked | C6: IOFireWireFamily, IOFireWireAVC, IOAudioFamily, IOFireWireSBP2 built for arm64e; Apple Silicon kernelcache manifests list them + AppleFWOHCI; arm64e IOFireWireFamily defines createLocalIsochPort (classic DCL) | D6: KDK 14.8.4 dSYM lipo -archs; manifests; nm | E6: evidence/kdk-14.8.4-families-arm64e.txt | F6: 2026-10-21 | G6: DEC-3, BC-3.5
A7: E-6 | B7: Checked | C7: ARM-only pure virtual IOAudioEngine::driverDesiresHiResSampleIntervals() must be implemented by ARM subclasses | D7: Read the SDK header | E7: MacOSX15.2.sdk IOKit/audio/IOAudioEngine.h:928-943 | F7: 2026-10-21 | G7: BC-3.5
A8: E-7 | B8: Checked | C8: macOS 14.8.9: IOFireWireLib / IOFireWireAVCLib / MIDIServer are x86_64 + arm64e; AppleFWAudio.kext absent; IOAudioFamily 540.3, IOFireWireFamily 4.8.3, IOFireWireAVC 4.2.8 | D8: lipo -archs, Info.plist on the dev Mac | E8: dev Mac | F8: 2026-10-21 | G8: OS_Matrix
A9: E-8 | B9: Checked | C9: 10.13.6: IOAudioFamily 206.5, IOFireWireFamily 4.7.2, IOFireWireAVC 4.2.6; AppleFWAudio.kext present | D9: read-only on the build PC | E9: evidence/buildpc-10.13.6-kpi-exports.txt | F9: 2026-10-21 | G9: OS_Matrix
A10: E-9 | B10: Checked | C10: All 0.2.2 binaries x86_64 only; helper/panel LC_VERSION_MIN 10.13; installer min 10.13, hostArchitectures x86_64 | D10: lipo, otool -l; distribution.xml.in:6-7 | E10: dist/OA-BeBoB-MAFW-0.2.2.pkg | F10: 2026-10-21 | G10: BC-2.x, BC-5.1
A11: E-10 | B11: Checked | C11: 0.2.2 panel starts and renders 8 demo snapshots on Intel macOS 14.8.9 (demo mode only) | D11: --demo --snapshot on the dev Mac | E11: evidence/panel-0.2.2-demo-macos-14.8.9.txt | F11: 2026-10-21 | G11: M11 panel
A12: E-11 | B12: Checked | C12: Panel APIs newer than 10.9: labelWithString 10.12, monospacedDigitSystemFont 10.11, vibrantDark 10.10, NSStatusItem.button 10.10, labelColor 10.10; listener blocks 10.7; Swift floor 10.9 | D12: API_AVAILABLE in the 15.2 SDK headers; grep of Sources/ | E12: Widgets.swift:11, Theme.swift:62,173, StatusMenu.swift:35,105,114 | F12: 2026-10-21 | G12: BC-4.2, DEC-4
... A17: E-16 | B17: Checked | C17: Panel 5,925 lines of Swift (+ ~120 Uninstaller); helper 457 lines of C | D17: wc -l | E17: control-panel/Sources, firmware-helper | F17: 2026-10-21 | G17: BC-4.4
A18: U-1 | B18: Unverified | C18: 10.6 boots K32 on most Macs; 10.7 on some; 32-bit-EFI Macs cannot boot K64 | D18: uname -v per target; Apple notes | E18: BC-1.2 | G18: DEC-2
A19: U-2 | B19: Unverified | C19: Unsigned-kext policy per OS (10.10 kext-dev-mode, 10.11+ SIP, 11+ AuxKC approval, Apple Silicon Permissive Security); 10.13.6 row verified by the project | D19: Apple docs, man kmutil/kextutil | E19: BC-1.2 | G19: OS_Matrix, BC-5.4
A20: U-3 | B20: Unverified | C20: /Library/Extensions is scanned only from 10.9 | D20: Apple docs | E20: BC-1.2 | G20: BC-5.1
A21: U-4 | B21: Unverified | C21: IOReporting (configureReport/updateReport) exists from 10.9 - the Main build's floor | D21: 10.9 symbol set / KDK | E21: BC-1.1 | G21: DEC-1
A22: U-5 | B22: Unverified | C22: ___memmove_chk / ___strlcat_chk exported on 10.9-10.12 | D22: symbol sets; or -D_FORTIFY_SOURCE=0 | E22: BC-1.1 | G22: BC-3.2
A23: U-6 | B23: Unverified | C23: macOS 26 Tahoe has no FireWire stack (ceiling = 15) | D23: macfw statement; a Tahoe KDK | E23: docs/MACOS12_PORT_PERSPECTIVE.md §1-2 | G23: scope
A24: U-7 | B24: Unverified | C24: The 1.11.2 MIDI plug-in (min 10.7) runs on 10.6.8 | D24: imports vs 10.6.8 frameworks | E24: BC-4.7 | G24: Band L MIDI
A25: U-8 | B25: Unverified | C25: x86_64 panel works against the real kext on 11-15 | D25: BC-6.1. 2026-10-21: the panel starts and opens the vendor user client against the real kext on 14.8.9 (R126); controls and meters not exercised | E25: BC-6.1 | G25: M11
A26: U-9 | B26: Unverified | C26: CoreMIDI on Apple Silicon can host an x86_64-only driver plug-in | D26: one Apple Silicon run or Apple docs | E26: — | G26: DEC-8
A27: U-10 | B27: Unverified | C27: FireWire works on Apple Silicon through TB3->TB2 + TB->FW800 adapters | D27: BC-6.4 | E27: BC-6.4 | G27: DEC-3
A28: U-11 | B28: Unverified | C28: kxld / kmutil patch the reserved-slot vtable entries 15/16 of a 10.13-SDK kext | D28: Moot for the Modern edition: the 15.x SDK build is used instead (E-17, E-18); patching of a 10.13-SDK build never tried | E28: BC-6.1 | G28: BC-3.3
A29: U-12 | B29: Unverified | C29: An old-SDK x86_64 slice loads and runs on 10.9-15 (would allow one kext bundle) | D29: BC-6.1 with the Legacy build | E29: BC-6.1 | G29: Option A'
... A31: U-14 | B31: Unverified | C31: DCL ring, TPacketPool (4 KiB packing, 32-bit mask) and 4 KiB meter page on Apple Silicon (16 KiB pages, DART, 24 MHz timebase, PAC) | D31: BC-1.4 static, BC-6.4 | E31: BC-1.4 | G31: BC-3.5
A32: E-17 | B32: Checked | C32: 14.8.9 Intel: shipped 0.2.2 kext resolves 775/777 (only _RESERVEDIOAudioEngine15/16 missing); the same sources built with MacOSX15.2.sdk resolve 778/778 | D32: kmutil libraries -p <kext> -a x86_64 -z on the dev Mac | E32: evidence/kext-0.2.2-kmutil-libraries-macos-14.8.9.txt | F32: 2026-10-21 | G32: BC-3.3, U-11
A33: E-18 | B33: Checked | C33: Modern kext (15.2 SDK) loads on 14.8.9 Intel, attaches the FW Audiophile through the TB-FW adapter and plays (user heard it; TX 46/46 ms, no CLIP jump); one dropout in real use, adapter FireWire controller left PCI first, cause open | D33: Dev Mac run: kmutil showloaded, ioreg trace, say -a, maprop MADebugTxStats, log show | E33: evidence/modern-kext-first-run-audiophile-macos-14.8.9.txt; evidence/modern-kext-dropout-macos-14.8.9-1941.txt | F33: 2026-10-21 | G33: BC-6.1, RK-4, RK-6

Sheet Risks
A1: ID | B1: Risk | C1: Bands | D1: Likelihood (estimate) | E1: Impact (estimate) | F1: Mitigation | G1: Task
A2: RK-1 | B2: 10.6 HAL / IOAudioFamily behave differently from 10.13 (U-13) | C2: L | D2: Medium | E2: High | F2: Decompile-and-diff first (standing method lesson); BC-6.3 | G2: BC-6.3
A3: RK-2 | B3: A 10.13-forced deviation misbehaves on another IOAudioFamily version (206.5 vs 540.3) | C3: all | D3: Medium | E3: Medium | F3: BC-3.1 gates each deviation by OS range | G3: BC-3.1
A4: RK-3 | B4: kmutil does not patch reserved slots 15/16 | C4: M11 | D4: Low | E4: Medium | F4: Done: the Modern edition is built with the 15.x SDK (E-17, E-18) | G4: BC-3.3
A5: RK-4 | B5: Classic DCL from the kernel fails on 11-15 (symbol present on x86_64 and arm64e, E-4/E-5) | C5: M11, AS | D5: Low (Intel TX runs on 14.8.9, E-18) | E5: High | F5: BC-6.1 decides it early | G5: BC-6.1
A6: RK-5 | B6: 16 KiB pages / DART / timebase break the DMA ring or meter page | C6: AS | D6: Medium | E6: High | F6: BC-1.4, BC-3.5 | G6: BC-3.5
A7: RK-6 | B7: FireWire through the adapter chain unreliable; bus power short for the Audiophile | C7: AS, M11 | D7: Medium | E7: High | F7: BC-6.4; 2026-10-21: one dropout on Intel 14.8.9 with the adapter, interface bus-powered (R126; user suspects a bad contact) | G7: BC-6.4
A8: RK-7 | B8: A panic reboots the test host; on Apple Silicon recovery needs recoveryOS | C8: all | D8: Medium | E8: Medium | F8: Say so before any load (hardware etiquette); §8 | G8: BC-6.x
A9: RK-8 | B9: Three toolchains per release (Xcode 9.4.1, 10.6 SDK, CLT / Xcode 12+) | C9: all | D9: High | E9: Low | F9: BC-2 scripts; record toolchain versions in CHANGELOG | G9: BC-2.x
A10: RK-9 | B10: Permissive Security lowers the whole Mac's security | C10: AS | D10: High | E10: Medium | F10: User's choice, stated in the installer pages | G10: BC-5.4
A11: RK-10 | B11: Panel port introduces UI regressions | C11: L | D11: Medium | E11: Medium | F11: Port file by file against the --demo --snapshot PNGs | G11: BC-4.4
A12: RK-11 | B12: Original MIDI plug-in fails on 10.6 (min 10.7) | C12: L | D12: Medium | E12: Low | F12: BC-4.7 -> clone | G12: BC-4.7
A13: RK-12 | B13: Most bands ship untested (R123) | C13: all | D13: High | E13: Medium | F13: README marks each band; on-device checks only on request | G13: BC-7.1

Sheet Legend
A1: Legend
A3: Bands
A4: C | B4: Common: needed in every scenario
A5: M | B5: Main: Intel 10.9-15 (M11 = the same build on 11-15)
A6: AS | B6: Apple Silicon 11-15
A7: L | B7: Legacy: 10.6.8-10.8.5
A9: Scenarios
A10: S1 | B10: Intel 10.9-15 = C + M
A11: S2 | B11: S1 + Apple Silicon = C + M + AS
A12: S3 | B12: S2 + 10.6.8-10.8.5 = C + M + AS + L (the full request)
A14: Task status values
A15: Waiting decision | B15: Gated by a DEC-n in the Decisions tab
A16: Partly done / Done (static) | B16: Static work done on 2026-10-21 (nothing loaded)
A17: On request | B17: On-device check; runs only if the user asks (no formal testing, R123)
A18: Blocked (hardware) | B18: Needs hardware the project does not have
A20: Editing
A21: Blue text | B21: Inputs you may change: task status, min/max sessions, risk ratings
A22: Yellow cells | B22: Decision answers (Decisions!H)
A23: Black text | B23: Fixed text or formulas (Dashboard totals refresh from Tasks)
A25: Units
A26: Session | B26: One working session, as in docs/BUILD_AUDIOPHILE_PLAN_v2.md §8. Every effort figure is an estimate.
A27: Evidence ids | B27: E-n checked on 2026-10-21; U-n unverified, with the check that settles it
A28: Plan | B28: BROAD_COMPATIBILITY_PLAN_v1.md (same folder); a new version gets new files (_v2)
